Workbook

Sheet README
A1: COHR — bottom-up transceiver revenue model
A2: Units x ASP x share rebuild of Coherent's data-center revenue. Built 2026-08-17. All figures US$m unless noted.
A4: WHAT THIS IS
B6: A bottom-up rebuild of COHR data-center revenue as: global transceiver units x ASP x COHR share, by speed grade.
B7: It exists because the Jefferies model (Blayne Curtis, file dated 2026-08-13) and the Capstone house model are both
B8: TOP-DOWN — data-center revenue is driven by hand-set q/q growth rates with no unit or share layer underneath.
B10: The model is calibrated to three REPORTED anchors, not fitted to any forecast:
B11: 1. CY2025 reported data-center revenue $2,765.5m
B12: 2. 1H2026 reported data-center revenue $1,971.0m
B13: 3. FQ1 FY27 company revenue guide, midpoint $2,300.0m (Sherri Luther, 2026-08-12)
B15: It is then checked against an observable NOT used in the fit: management's indium-phosphide laser output growth.
A17: HOW TO DRIVE IT
B19: Every assumption lives on the Inputs tab. Change a BLUE cell and the whole workbook recalculates.
B20: Inputs!B4 is the scenario selector — type bear, base or bull. "base" = hold the calibrated Sept-quarter exit-rate share.
B21: Check the Guardrails tab after any change; the checks turn PASS / BINDING / FAIL on their own.
A23: COLOUR LEGEND
B25: Blue | C25: hardcoded input or scenario lever — edit these
B26: Black | C26: formula — do not overwrite
B27: Green | C27: link to another tab
B28: Yellow fill | C28: key assumption / the number the answer hangs on
A30: SOURCES
B32: TAM (units + ASP by speed) | C32: Goldman Sachs global optical-module model, 2026-08-10. Transcribed in _wiki/themes/optical-cpo.md.
C33: CAVEAT: the GS note itself is NOT on disk — it was ingested from a pasted exhibit, broker+date confirmed at ingest.
B34: Reported actuals + segments | C34: Company reported, via the Jefferies/Blayne Curtis model Rev tab (file modified 2026-08-13).
B35: Guide + capacity statements | C35: COHR FQ4 FY26 earnings call, 2026-08-12 (Bloomberg final transcript, 2026-08-13).
B36: Comms & Industrial segments | C36: CARRIED from Jefferies — NOT modelled bottom-up. 32% of CY27E revenue.
B37: Consensus | C37: Bloomberg via _wiki/_data/estimates.json, asof 2026-08-17.
B38: Capstone house model | C38: _wiki/_data/house.json — "Modelo COHR.xlsx, 2026-05-26. Built on Jefferies/Blayne Curtis."
B39: Competitor share marks | C39: Innolight ~27% of DC transceivers (Damnang, 2026-08-04); COHR ranked #2 (Bernstein, 2025-10-27).

Sheet Inputs
A1: Inputs — every assumption in the model
A2: BLUE = edit me. Tags: HARD = sourced exactly · ANCHOR = observable used to calibrate · EST = analyst estimate.
A4: SCENARIO
B6: Scenario (type: bear / base / bull) | C6: base | H6: base = hold the calibrated Sept-quarter exit-rate share flat. No share gain assumed.
B7: Bear — CY27 share of AI pool | C7: 0.122 | H7: share slips back to the 1H26 InP-constrained level
B8: Bear — CY28 share of AI pool | C8: 0.115
B9: Bull — CY27 share of AI pool | C9: 0.165 | H9: 6-inch InP lands + China restrictions hand over share
B10: Bull — CY28 share of AI pool | C10: 0.185
A12: REPORTED ACTUALS [HARD]
B14: Data-center revenue, CY2025 | C14: 2765.5 | H14: sum of four reported quarters: 639.8 + 659.0 + 686.7 + 780.0
B15: Data-center revenue, 1H2026 | C15: 1971 | H15: 878.0 + 1,093.0. Ties to mgmt: DC +24% q/q, +66% y/y in FQ4
B16: Data-center revenue, CQ3-2025 | C16: 686.7 | H16: the y/y base for the September-quarter growth guardrail
B17: Data-center revenue, CY2023 | C17: 1079.2 | H17: pre-800G, so ~100% legacy — the floor anchor for the legacy line
B18: Total revenue, CY2025 | C18: 6294.3
A20: COMPANY GUIDE — FQ1 FY27 (= CQ3-2026) [ANCHOR]
B22: Total revenue guide, midpoint | C22: 2300 | H22: guide range $2.2-2.4bn. CFO Sherri Luther, FQ4 FY26 call 2026-08-12
B23: less: Comms, CQ3-26 | C23: 495 | H23: Jefferies estimate — NOT guidance. See Guardrails check 6
B24: less: Semi Devices, CQ3-26 | C24: 69.8 | H24: RESTORED in v2 - v1 dropped this and mixed the calibration basis
B25: less: Industrial, CQ3-26 | C25: 434.8 | H25: Jefferies estimate — NOT guidance
A27: ANALYST ESTIMATES [EST] — this is the model's exposure
B29: Legacy datacom (400G & below), CY25 | C29: 850 | H29: bracketed below by CY23 actual, above by the InP guardrail ($1,106m max)
B30: Legacy decay, CY26 | C30: 0.75 | H30: y/y factor as 400G rolls over
B31: Legacy decay, CY27 | C31: 0.8
B32: Legacy decay, CY28 | C32: 0.82
B33: Non-module DC, CY25 | C33: 40 | H33: OCS pilot volumes only
B34: Non-module DC, CY26 | C34: 160 | H34: OCS ramping + first CPO revenue in the December quarter
B35: Non-module DC, CY27 | C35: 775 | H35: OCS + CPO scale-up (2H CY27) + multi-rail (1H CY27) + ThermaDyte
B36: Non-module DC, CY28 | C36: 1850 | H36: back-cast from mgmt TAMs: OCS >$4bn by 2030, multi-rail >$2bn by 2030
B37: CQ3-26 share of CY26 non-module | C37: 0.3 | H37: phasing only
B38: pi — COHR ASP / market blended ASP | C38: 1.15 | H38: CANCELS from every growth rate; sets the unit LEVEL only
A40: COHR SPEED MIX — share of its own AI-module dollars [EST]
F41: check
C42: 800G | D42: 1.6T | E42: 3.2T | H42: NOT the market mix. COHR is 1.6T-skewed: "1.6T is ramping incredibly fast" (Anderson, 2026-08-12),
B43: CY2025 | C43: 0.8 | D43: 0.2 | E43: 0 | F43: =SUM(C43:E43) | H43: and 1.6T is EML/InP-led — exactly where COHR's vertical integration sits. This is the BINDING assumption.
B44: CY2026 | C44: 0.35 | D44: 0.65 | E44: 0 | F44: =SUM(C44:E44)
B45: CY2027 | C45: 0.2 | D45: 0.68 | E45: 0.12 | F45: =SUM(C45:E45)
B46: CY2028 | C46: 0.13 | D46: 0.6 | E46: 0.27 | F46: =SUM(C46:E46)
A48: CARRIED FROM JEFFERIES — not modelled here
C50: CY2026E | D50: CY2027E | E50: CY2028E | H50: Jefferies/Blayne Curtis model, Rev tab, file modified 2026-08-13. Together 32% of CY27E revenue.
B51: Comms (DCI/ZR + telecom) | C51: 1896.5 | D51: 2542.8 | E51: 3051.4
...

Sheet TAM
A1: TAM — global optical-module market by speed grade [HARD]
A2: Goldman Sachs, 2026-08-10. Units and ASP are as printed by GS; dollars are as printed. The foot check below is genuine, not circular.
A4: UNITS (k) ASP (US$)
C5: CY2025 | D5: CY2026E | E5: CY2027E | F5: CY2028E | H5: CY2025 | I5: CY2026E | J5: CY2027E | K5: CY2028E
B6: 400G | C6: 18301 | D6: 8295 | E6: 5268 | F6: 2007 | H6: 230 | I6: 210 | J6: 184 | K6: 143
B7: 800G | C7: 21178 | D7: 34183 | E7: 44993 | F7: 44047 | H7: 440 | I7: 396 | J7: 327 | K7: 244
B8: 1.6T | C8: 4591 | D8: 25500 | E8: 45719 | F8: 53525 | H8: 840 | I8: 734 | J8: 599 | K8: 435
B9: 3.2T | C9: 0 | D9: 0 | E9: 13067 | F9: 28162 | H9: 0 | I9: 0 | J9: 1021 | K9: 768
B10: AI pool (800G + 1.6T + 3.2T) | C10: =C7+C8+C9 | D10: =D7+D8+D9 | E10: =E7+E8+E9 | F10: =F7+F8+F9 | M10: This pool EXCLUDES 400G and below-400G. Never compare a share of it to a share of the total module market.
A12: DOLLARS (US$m) — as printed by GS
C13: CY2025 | D13: CY2026E | E13: CY2027E | F13: CY2028E | H13: CHECK: units x ASP vs printed
B14: 400G | C14: 4209 | D14: 1745 | E14: 969 | F14: 287 | H14: =IF(C6=0,"-",C6*H6/1000/C14-1) | I14: =IF(D6=0,"-",D6*I6/1000/D14-1) | J14: =IF(E6=0,"-",E6*J6/1000/E14-1) | K14: =IF(F6=0,"-",F6*K6/1000/F14-1)
B15: 800G | C15: 9318 | D15: 13530 | E15: 14715 | F15: 10761 | H15: =IF(C7=0,"-",C7*H7/1000/C15-1) | I15: =IF(D7=0,"-",D7*I7/1000/D15-1) | J15: =IF(E7=0,"-",E7*J7/1000/E15-1) | K15: =IF(F7=0,"-",F7*K7/1000/F15-1)
B16: 1.6T | C16: 3857 | D16: 18722 | E16: 27403 | F16: 23264 | H16: =IF(C8=0,"-",C8*H8/1000/C16-1) | I16: =IF(D8=0,"-",D8*I8/1000/D16-1) | J16: =IF(E8=0,"-",E8*J8/1000/E16-1) | K16: =IF(F8=0,"-",F8*K8/1000/F16-1)
B17: 3.2T | C17: 0 | D17: 0 | E17: 13340 | F17: 21625 | H17: =IF(C9=0,"-",C9*H9/1000/C17-1) | I17: =IF(D9=0,"-",D9*I9/1000/D17-1) | J17: =IF(E9=0,"-",E9*J9/1000/E17-1) | K17: =IF(F9=0,"-",F9*K9/1000/F17-1)
B18: AI pool (800G + 1.6T + 3.2T) | C18: =C15+C16+C17 | D18: =D15+D16+D17 | E18: =E15+E16+E17 | F18: =F15+F16+F17 | M18: Foot check left: derived (units x ASP) vs GS printed dollars. All within 0.2% — the transcription is sound.
A20: QUARTERLY AI POOL, CY2026 (US$m)
C21: 1Q26 | D21: 2Q26 | E21: 3Q26 | F21: 4Q26 | H21: sum vs annual
B22: 800G | C22: 2706 | D22: 3457 | E22: 3557 | F22: 3810 | H22: =SUM(C22:F22)/D15-1
B23: 1.6T | C23: 3000 | D23: 3736 | E23: 4406 | F23: 7581 | H23: =SUM(C23:F23)/D16-1
B24: AI pool, quarterly | C24: =C22+C23 | D24: =D22+D23 | E24: =E22+E23 | F24: =F22+F23 | H24: =SUM(C24:F24)/D18-1 | M24: Second internal check: the quarterly panel foots to the annual within 0.01%.

Sheet Calibration
A1: Calibration — back-solve COHR's share of the AI-transceiver pool
A2: Three reported anchors. Nothing here is fitted to any forecast. This is the whole model in one page.
A4: ANCHOR 1 — CY2025 actual
B6: Reported data-center revenue, CY25 | C6: =Inputs!$C$14
B7: less: legacy datacom (400G & below) | C7: =-Inputs!$C$29
B8: less: non-module DC (OCS pilot) | C8: =-Inputs!$C$33
B9: = AI-module revenue, CY25 | C9: =SUM(C6:C8)
B10: GS AI-transceiver pool, CY25 | C10: =TAM!C18
B11: = COHR share of the AI pool, CY25 | C11: =C9/C10 | E11: The pool is dollars, so this is a DOLLAR share. Unit share = this / pi (see Units tab).
A13: ANCHOR 2 — 1H2026 actual
B15: Reported data-center revenue, 1H26 | C15: =Inputs!$C$15
B16: less: legacy datacom (half of CY26) | C16: =-Inputs!$C$29*Inputs!$C$30/2
B17: less: non-module DC (half of CY26) | C17: =-Inputs!$C$34/2
B18: = AI-module revenue, 1H26 | C18: =SUM(C15:C17)
B19: GS AI pool, 1H26 (1Q + 2Q) | C19: =TAM!C24+TAM!D24
B20: = COHR share of the AI pool, 1H26 | C20: =C18/C19 | E20: The share FALLS vs CY25 — indium phosphide capacity binding while the pool nearly doubles.
E21: Mgmt: "indium phosphide capacity continues to be our primary constraint" (Anderson, 2026-08-12).
A23: ANCHOR 3 — CQ3-2026 company guide (the exit rate)
B25: FQ1 FY27 total revenue guide, midpoint | C25: =Inputs!$C$22
B26: less: Comms, CQ3-26 | C26: =-Inputs!$C$23
B27: less: Semi Devices, CQ3-26 | C27: =-Inputs!$C$24 | H27: RESTORED v2 - sits inside the Jefferies DC/Comms row; omitting it mixed the basis
B28: less: Industrial, CQ3-26 | C28: =-Inputs!$C$25
B29: = implied data-center revenue, CQ3-26 | C29: =SUM(C25:C28)
B30: y/y growth | C30: =C29/Inputs!$C$16-1 | E30: Mgmt floor: "we would expect our data center growth this quarter y/y to EXCEED 80%".
B31: less: legacy datacom (quarter of CY26) | C31: =-Inputs!$C$29*Inputs!$C$30/4
B32: less: non-module DC | C32: =-Inputs!$C$34*Inputs!$C$37
B33: = AI-module revenue, CQ3-26 | C33: =C29+C31+C32
B34: GS AI pool, 3Q26 | C34: =TAM!E24
B35: = EXIT-RATE SHARE of the AI pool | C35: =C33/C34 | E35: THIS IS THE NUMBER THE WHOLE MODEL TURNS ON. The base case simply holds it flat.
A38: DERIVED — CY2026 blended
B40: AI-module revenue, CY26 | C40: =C18+C33+C35*TAM!F24 | E40: = 1H actual + CQ3 guide-implied + CQ4 at the exit-rate share.
B41: = COHR share of the AI pool, CY26 | C41: =C40/TAM!D18
A43: THE SHARE PATH
B45: CY2025 actual | C45: =C11
B46: 1H2026 actual — InP binds | C46: =C20
B47: CQ3-2026 guide — capacity lands | C47: =C35
B48: CY2026E blended | C48: =C41

Sheet Model
A1: Model — revenue build
A2: Modules are bottom-up (pool x share). Legacy and non-module are estimates. Comms and Industrial are carried from Jefferies.
B4: Active scenario | C4: =Inputs!$C$6 | H4: Change on the Inputs tab (cell C6): bear / base / bull.
A6: US$m | B6: CY2025A | C6: CY2026E | D6: CY2027E | E6: CY2028E
B7: COHR share of AI pool | C7: =Calibration!C11 | D7: =Calibration!C41 | E7: =IF(Inputs!$C$6="bear",Inputs!$C$7,IF(Inputs!$C$6="bull",Inputs!$C$9,Calibration!C35)) | F7: =IF(Inputs!$C$6="bear",Inputs!$C$8,IF(Inputs!$C$6="bull",Inputs!$C$10,Calibration!C35)) | H7: base = the calibrated Sept-quarter exit rate, held flat. No share gain assumed.
B8: AI-module revenue | C8: =Calibration!C9 | D8: =Calibration!C40 | E8: =E7*TAM!E18 | F8: =F7*TAM!F18 | H8: = GS AI-transceiver pool x COHR share. The bottom-up leg.
B9: Legacy datacom (400G & below) | C9: =Inputs!$C$29 | D9: =C9*Inputs!$C$30 | E9: =D9*Inputs!$C$31 | F9: =E9*Inputs!$C$32
B10: OCS · CPO · multi-rail · thermal | C10: =Inputs!$C$33 | D10: =Inputs!$C$34 | E10: =Inputs!$C$35 | F10: =Inputs!$C$36
B11: = Data-center segment | C11: =C8+C9+C10 | D11: =D8+D9+D10 | E11: =E8+E9+E10 | F11: =F8+F9+F10
B12: Comms (carried) | C12: 1222.2 | D12: =Inputs!C51 | E12: =Inputs!D51 | F12: =Inputs!E51
B13: Industrial (carried) | C13: 2009.1 | D13: =Inputs!C53 | E13: =Inputs!D53 | F13: =Inputs!E53
B14: Semi Devices (carried) | C14: 297.5 | D14: =Inputs!C52 | E14: =Inputs!D52 | F14: =Inputs!E52
B15: TOTAL REVENUE | C15: =C11+C12+C14+C13 | D15: =D11+D12+D14+D13 | E15: =E11+E12+E14+E13 | F15: =F11+F12+F14+F13
B16: y/y growth | C16: =C15/5306-1 | D16: =D15/C15-1 | E16: =E15/D15-1 | F16: =F15/E15-1
A18: VERSUS THE STREET
A20: US$m | B20: CY2025A | C20: CY2026E | D20: CY2027E | E20: CY2028E
B21: Jefferies · Curtis 08-13 | D21: =Inputs!C58 | E21: =Inputs!D58 | F21: =Inputs!E58
B22: BBG consensus 08-17 | D22: =Inputs!C59 | E22: =Inputs!D59 | F22: =Inputs!E59
B23: Capstone house 05-26 | D23: =Inputs!C60 | E23: =Inputs!D60 | F23: =Inputs!E60
B24: this model vs Jefferies | D24: =IF(ISNUMBER(Inputs!C58),D15/Inputs!C58-1,"n/a") | E24: =IF(ISNUMBER(Inputs!D58),E15/Inputs!D58-1,"n/a") | F24: =IF(ISNUMBER(Inputs!E58),F15/Inputs!E58-1,"n/a")
B25: this model vs consensus | D25: =IF(ISNUMBER(Inputs!C59),D15/Inputs!C59-1,"n/a") | E25: =IF(ISNUMBER(Inputs!D59),E15/Inputs!D59-1,"n/a") | F25: =IF(ISNUMBER(Inputs!E59),F15/Inputs!E59-1,"n/a")
B26: this model vs house | D26: =IF(ISNUMBER(Inputs!C60),D15/Inputs!C60-1,"n/a") | E26: =IF(ISNUMBER(Inputs!D60),E15/Inputs!D60-1,"n/a") | F26: =IF(ISNUMBER(Inputs!E60),F15/Inputs!E60-1,"n/a")

Sheet Units
A1: Units x ASP — the same model in physical terms
A2: pi cancels from every growth rate, so it does not drive the revenue forecast. The SPEED MIX does: 1.6T carries ~1.9x the ASP of 800G.
B4: CY2025A | C4: CY2026E | D4: CY2027E | E4: CY2028E
A5: 800G
B6: Market units (k) | C6: =TAM!C7 | D6: =TAM!D7 | E6: =TAM!E7 | F6: =TAM!F7
B7: Market ASP ($) | C7: =IF(TAM!C7=0,0,TAM!C15*1000/TAM!C7) | D7: =IF(TAM!D7=0,0,TAM!D15*1000/TAM!D7) | E7: =IF(TAM!E7=0,0,TAM!E15*1000/TAM!E7) | F7: =IF(TAM!F7=0,0,TAM!F15*1000/TAM!F7)
B8: COHR mix (of module $) | C8: =Inputs!C43 | D8: =Inputs!C44 | E8: =Inputs!C45 | F8: =Inputs!C46
B9: COHR revenue ($m) | C9: =C8*Model!C8 | D9: =D8*Model!D8 | E9: =E8*Model!E8 | F9: =F8*Model!F8
B10: COHR ASP ($) = market x pi | C10: =C7*Inputs!$C$38 | D10: =D7*Inputs!$C$38 | E10: =E7*Inputs!$C$38 | F10: =F7*Inputs!$C$38
B11: COHR units (k) | C11: =IF(C10=0,0,C9*1000/C10) | D11: =IF(D10=0,0,D9*1000/D10) | E11: =IF(E10=0,0,E9*1000/E10) | F11: =IF(F10=0,0,F9*1000/F10)
B12: COHR unit share | C12: =IF(TAM!C7=0,"-",C11/TAM!C7) | D12: =IF(TAM!D7=0,"-",D11/TAM!D7) | E12: =IF(TAM!E7=0,"-",E11/TAM!E7) | F12: =IF(TAM!F7=0,"-",F11/TAM!F7)
A14: 1.6T
B15: Market units (k) | C15: =TAM!C8 | D15: =TAM!D8 | E15: =TAM!E8 | F15: =TAM!F8
B16: Market ASP ($) | C16: =IF(TAM!C8=0,0,TAM!C16*1000/TAM!C8) | D16: =IF(TAM!D8=0,0,TAM!D16*1000/TAM!D8) | E16: =IF(TAM!E8=0,0,TAM!E16*1000/TAM!E8) | F16: =IF(TAM!F8=0,0,TAM!F16*1000/TAM!F8)
B17: COHR mix (of module $) | C17: =Inputs!D43 | D17: =Inputs!D44 | E17: =Inputs!D45 | F17: =Inputs!D46
B18: COHR revenue ($m) | C18: =C17*Model!C8 | D18: =D17*Model!D8 | E18: =E17*Model!E8 | F18: =F17*Model!F8
B19: COHR ASP ($) = market x pi | C19: =C16*Inputs!$C$38 | D19: =D16*Inputs!$C$38 | E19: =E16*Inputs!$C$38 | F19: =F16*Inputs!$C$38
B20: COHR units (k) | C20: =IF(C19=0,0,C18*1000/C19) | D20: =IF(D19=0,0,D18*1000/D19) | E20: =IF(E19=0,0,E18*1000/E19) | F20: =IF(F19=0,0,F18*1000/F19)
B21: COHR unit share | C21: =IF(TAM!C8=0,"-",C20/TAM!C8) | D21: =IF(TAM!D8=0,"-",D20/TAM!D8) | E21: =IF(TAM!E8=0,"-",E20/TAM!E8) | F21: =IF(TAM!F8=0,"-",F20/TAM!F8)
A23: 3.2T
B24: Market units (k) | C24: =TAM!C9 | D24: =TAM!D9 | E24: =TAM!E9 | F24: =TAM!F9
B25: Market ASP ($) | C25: =IF(TAM!C9=0,0,TAM!C17*1000/TAM!C9) | D25: =IF(TAM!D9=0,0,TAM!D17*1000/TAM!D9) | E25: =IF(TAM!E9=0,0,TAM!E17*1000/TAM!E9) | F25: =IF(TAM!F9=0,0,TAM!F17*1000/TAM!F9)
B26: COHR mix (of module $) | C26: =Inputs!E43 | D26: =Inputs!E44 | E26: =Inputs!E45 | F26: =Inputs!E46
B27: COHR revenue ($m) | C27: =C26*Model!C8 | D27: =D26*Model!D8 | E27: =E26*Model!E8 | F27: =F26*Model!F8
B28: COHR ASP ($) = market x pi | C28: =C25*Inputs!$C$38 | D28: =D25*Inputs!$C$38 | E28: =E25*Inputs!$C$38 | F28: =F25*Inputs!$C$38
B29: COHR units (k) | C29: =IF(C28=0,0,C27*1000/C28) | D29: =IF(D28=0,0,D27*1000/D28) | E29: =IF(E28=0,0,E27*1000/E28) | F29: =IF(F28=0,0,F27*1000/F28)
B30: COHR unit share | C30: =IF(TAM!C9=0,"-",C29/TAM!C9) | D30: =IF(TAM!D9=0,"-",D29/TAM!D9) | E30: =IF(TAM!E9=0,"-",E29/TAM!E9) | F30: =IF(TAM!F9=0,"-",F29/TAM!F9)
A32: TOTAL
B33: COHR AI-module units (k) | C33: =C11+C20+C29 | D33: =D11+D20+D29 | E33: =E11+E20+E29 | F33: =F11+F20+F29
B34: y/y growth | D34: =D33/C33-1 | E34: =E33/D33-1 | F34: =F33/E33-1 | H34: CY26 growth is the number the InP laser guardrail tests. See Guardrails.
B35: Blended COHR ASP ($) | C35: =IF(C33=0,0,Model!C8*1000/C33) | D35: =IF(D33=0,0,Model!D8*1000/D33) | E35: =IF(E33=0,0,Model!E8*1000/E33) | F35: =IF(F33=0,0,Model!F8*1000/F33)
B36: COHR unit share of AI pool | C36: =C33/TAM!C10 | D36: =D33/TAM!D10 | E36: =E33/TAM!E10 | F36: =F33/TAM!F10
A38: MINIMUM 1.6T MIX for CY26 units to stay inside a 2x laser ceiling
B39: Required 1.6T share of CY26 module $ | C39: =(Model!D8*1000000/(TAM!D15*1000/TAM!D7*Inputs!$C$38)-C33*2*1000)/(Model!D8*1000000/(TAM!D15*1000/TAM!D7*Inputs!$C$38)-Model!D8*1000000/(TAM!D16*1000/TAM!D8*Inputs!$C$38))
B40: Actual setting (Inputs) | C40: =Inputs!D44
B41: Market 1.6T mix, CY26 | C41: =TAM!D16/TAM!D18 | H41: If the required mix exceeds the actual setting, the revenue forecast does not fit the laser capacity.

Sheet Guardrails
A1: Guardrails — checks that use observables NOT used in the calibration
A2: These turn PASS / BINDING / FAIL on their own. If one goes red after you change an input, the model is telling you something.
A4: # | B4: Check | C4: Model | D4: Bound | F4: What it means
A5: 1 | B5: InP laser capacity | C5: =Units!D34 | D5: =1 | F5: Mgmt produced +80% more InP lasers y/y in the June-26 quarter, doubling y/y by end-September, and said those go specifically into 800G and 1.6T transceivers. 800G-DR8 and 1.6T-DR8 both use 8 lasers, so laser growth maps ~1:1 to module units.
B6: =IF(Units!D34<=0.80,"PASS",IF(Units!D34<=1.00,"BINDING - above the +80% internal-laser figure; needs merchant EML growing as fast as internal, which mgmt contradicts","FAIL - units outrun the lasers"))
A8: 2 | B8: September-quarter growth floor | C8: =Calibration!C30 | D8: =0.8 | F8: Mgmt: "we would expect our data center growth this quarter on a year-over-year basis to EXCEED 80% — we've certainly got the lasers this quarter to make that happen" (Anderson, 2026-08-12).
B9: =IF(Calibration!C30>0.8,"PASS","FAIL — below the company's own stated floor")
A11: 3 | B11: Share versus the market leader | C11: =Calibration!C35 | D11: =0.27 | F11: Innolight is ~27% of the DC transceiver market (Damnang, 2026-08-04); Bernstein ranks COHR #2 behind it (2025-10-27).
B12: =IF(Calibration!C35<0.27,"PASS — below Innolight, consistent with #2","FAIL — implies COHR passes Innolight")
A14: 4 | B14: Legacy line vs CY23 actual | C14: =(Inputs!$C$29/Inputs!$C$17)^0.5-1 | D14: =0 | F14: COHR CY23 data-center revenue was $1,079.2m and was essentially all legacy — 800G was barely shipping industry-wide. The legacy setting implies this compound rate over 2023-25 as 400G rolls over.
B15: =IF(AND((Inputs!$C$29/Inputs!$C$17)^0.5-1>-0.3,(Inputs!$C$29/Inputs!$C$17)^0.5-1<0.08),"PASS","CHECK — implied legacy trend is implausible")
A17: 5 | B17: CY28 is not a share problem | C17: =TAM!F18/TAM!E18-1 | D17: =TAM!F10/TAM!E10-1 | F17: GS has the AI dollar pool flat into 2028 while units keep growing: price gives back what volume adds. Holding share does not save 2028 — only a bigger pool or the non-module lines do.
B18: ="INFORMATIONAL — pool dollars vs pool units, CY27 to CY28"
A21: CHECKS THAT COULD NOT BE CLOSED — read these as the model's exposure
B23: BofA "20-30% global transceiver share" | F23: Reconciles on NEITHER dollar basis: COHR is ~14% of the AI pool and ~8% of all optical modules in CY25. Most likely a unit share of a Western/qualified subset, or a forward figure. NOT USED in this model. (BofA, 2026-05-13.)
B24: Comms/Industrial inside the CQ3 anchor | F24: The exit-rate share is calibrated by subtracting JEFFERIES' Comms and Industrial forecasts from the COMPANY's total-revenue guide. Those are estimates, not guidance. A $50m error in either moves the calibrated share ~0.6pt and CY27E revenue ~4%.
B25: The GS note is not on disk | F25: The TAM was ingested from a pasted exhibit with broker and date confirmed at ingest, but the underlying note has never been filed. Pull the PDF into _inbox/ when available. TAM is the single largest sensitivity in this model.
B26: Comms and Industrial are not modelled | F26: Both are carried from Jefferies and together are 32% of CY27E revenue. Only 68% of this model is genuinely bottom-up.
B27: GS 2026 pool growth is aggressive | F27: The AI pool grows +145% y/y in CY26 on GS's numbers. Citi carried "800G+ datacom ~$7bn in 2025" (2025-08-29) against GS's $13.2bn — a ~1.9x conflict. Treated here as a stale forecast vs a with-actuals model, but it is not resolved.

Sheet Benchmark
A1: What every other forecast implies for share
A2: Solve each published CY2027E revenue number backwards through the SAME Comms, Industrial, legacy and non-module lines. Like for like.
A4: CY2027E | B4: Total rev | C4: less C+SD+I | D4: = DC | E4: = modules | G4: Implied AI-pool share
H5: share | I5: vs exit rate
B6: Jefferies · Curtis 08-13 | C6: =Inputs!D58 | D6: =-(Model!E12+Model!E14+Model!E13) | E6: =C6+D6 | F6: =E6-Model!E9-Model!E10 | H6: =F6/TAM!E18 | I6: =H6-Calibration!C35
B7: BBG consensus 08-17 | C7: =Inputs!D59 | D7: =-(Model!E12+Model!E14+Model!E13) | E7: =C7+D7 | F7: =E7-Model!E9-Model!E10 | H7: =F7/TAM!E18 | I7: =H7-Calibration!C35
B8: Capstone house 05-26 | C8: =Inputs!D60 | D8: =-(Model!E12+Model!E14+Model!E13) | E8: =C8+D8 | F8: =E8-Model!E9-Model!E10 | H8: =F8/TAM!E18 | I8: =H8-Calibration!C35
B9: THIS MODEL | C9: =Model!E15 | D9: =-(Model!E12+Model!E14+Model!E13) | E9: =Model!E11 | F9: =Model!E8 | H9: =Model!E7 | I9: =H9-Calibration!C35
B10: Sept-quarter guide exit rate | C10: reference | H10: =Calibration!C35
B12: Read the last two columns. Consensus and Jefferies both implicitly model COHR LOSING share versus the rate its own
B13: September guide implies. The Capstone house model requires a large share GAIN inside about fifteen months — which
B14: would put COHR level with Innolight, the global number one.
A16: SENSITIVITY — CY2027E total revenue
B18: Change one input at a time on the Inputs tab and watch Model!E15.
B19: Ranked by swing (from the build, at base settings):
B20: GS pool +/-15% | C20: $12.5bn / $14.9bn | E20: -9% / +9%
B21: 3.2T pushed to 2029 (650 Group view) | C21: $11.8bn | E21: -14%
B22: AI-pool share +/-1.5pt | C22: $12.9bn / $14.6bn | E22: -6% / +6%
B23: Non-module DC $400m / $1,200m | C23: $13.4bn / $14.2bn | E23: -3% / +3%
B24: Comms +/-15% | C24: $13.3bn / $14.1bn | E24: -3% / +3%
B25: Industrial +/-15% | C25: $13.5bn / $14.0bn | E25: -2% / +2%
B26: Legacy datacom $600m / $1,100m | C26: $13.9bn / $13.6bn | E26: +1% / -1%
B28: The TAM is the exposure, not the share. And the GS note is not on disk.
