Workbook

Sheet DCF Cover - Base
C2: CRWV | Power-driven DCF (IT-load GW x revenue per GW)
C3: US$ millions, except power (MW), revenue/GW, build cost/GW and D&A/GW (US$ billions per GW) and shares (millions). Horizon CY2023–2045; fiscal year = calendar year.
C4: Blue / yellow: assumptions (Assumptions & sources sheet; salmon = no source). Green: internal sources. CY23–25A: reported bases (10-K). 2026: company guide.
D5: CY23A | E5: CY24A | F5: CY25A | G5: CY26E | H5: CY27E | I5: CY28E | J5: CY29E | K5: CY30E | L5: CY31E | M5: CY32E | N5: CY33E | O5: CY34E | P5: CY35E | Q5: CY36E | R5: CY37E | S5: CY38E | T5: CY39E | U5: CY40E | V5: CY41E | W5: CY42E | X5: CY43E | Y5: CY44E | Z5: CY45E
C6: Grid inputs: D6 revenue/GW multiplier 2027+ (1.00 = base) | E6 EBITDA-margin adjustment 2027+ (pp) | F6 replacement life (years) | G6 replacement cost (% of build) | D6: 1 | E6: 0 | F6: 6 | G6: 0.8
C7: Capacity | active power (critical IT load, MW) and billable power
C8: Active power at year-end (MW) | D8: ='Assumptions & sources'!D18 -> 70 | E8: ='Assumptions & sources'!E18 -> 360 | F8: ='Assumptions & sources'!F18 -> 850 | G8: =F8+G9 -> 1900 | H8: =G8+H9 -> 3200 | I8: =H8+I9 -> 4700 | J8: =I8+J9 -> 6300 | K8: =J8+K9 -> 8000 | L8: =K8+L9 -> 9400 | M8: =L8+M9 -> 10600 | N8: =M8+N9 -> 11600 | ... Z8: =Y8+Z9 -> 17874.088
C9: Active power added in the year (MW) | D9: =D8 -> 70 | E9: =E8-D8 -> 290 | F9: =F8-E8 -> 490 | G9: ='Assumptions & sources'!G75 -> 1050 | H9: ='Assumptions & sources'!H75 -> 1300 | I9: ='Assumptions & sources'!I75 -> 1500 | J9: ='Assumptions & sources'!J75 -> 1600 | K9: ='Assumptions & sources'!K75 -> 1700 | L9: ='Assumptions & sources'!L75 -> 1400 | M9: ='Assumptions & sources'!M75 -> 1200 | N9: ='Assumptions & sources'!N75 -> 1000 | ... P9: ='Assumptions & sources'!P75 -> 800 | Q9: =P8*'Assumptions & sources'!$D$71 -> 399 | R9: =Q8*'Assumptions & sources'!$D$71 -> 410.97 | S9: =R8*'Assumptions & sources'!$D$71 -> 423.2991 | T9: =S8*'Assumptions & sources'!$D$71 -> 435.99807 | U9: =T8*'Assumptions & sources'!$D$71 -> 449.07802 | V9: =U8*'Assumptions & sources'!$D$71 -> 462.55036 | W9: =V8*'Assumptions & sources'!$D$71 -> 476.42687 | X9: =W8*'Assumptions & sources'!$D$71 -> 490.71967 | ... Z9: =Y8*'Assumptions & sources'!$D$71 -> 520.6045
C10: Average active power in the year (MW) — D&A basis | E10: =(D8+E8)/2 -> 215 | F10: =(E8+F8)/2 -> 605 | G10: =(F8+G8)/2 -> 1375 | H10: =(G8+H8)/2 -> 2550 | I10: =(H8+I8)/2 -> 3950 | J10: =(I8+J8)/2 -> 5500 | K10: =(J8+K8)/2 -> 7150 | L10: =(K8+L8)/2 -> 8700 | ... Z10: =(Y8+Z8)/2 -> 17613.786
C11: Average billable power (MW) = prior YE + (0.5 − lag) x adds | 2026: quarterly build | E11: =D8+(0.5-'Assumptions & sources'!$D$67)*E9 -> 142.5 | F11: =E8+(0.5-'Assumptions & sources'!$D$67)*F9 -> 482.5 | G11: ='Assumptions & sources'!$D$38 -> 1124 | H11: =G8+(0.5-'Assumptions & sources'!$D$67)*H9 -> 2225 | I11: =H8+(0.5-'Assumptions & sources'!$D$67)*I9 -> 3575 | J11: =I8+(0.5-'Assumptions & sources'!$D$67)*J9 -> 5100 | K11: =J8+(0.5-'Assumptions & sources'!$D$67)*K9 -> 6725 | L11: =K8+(0.5-'Assumptions & sources'!$D$67)*L9 -> 8350 | M11: =L8+(0.5-'Assumptions & sources'!$D$67)*M9 -> 9700 | N11: =M8+(0.5-'Assumptions & sources'!$D$67)*N9 -> 10850 | O11: =N8+(0.5-'Assumptions & sources'!$D$67)*O9 -> 11825 | ... Z11: =Y8+(0.5-'Assumptions & sources'!$D$67)*Z9 -> 17483.634
C12: Revenue per billable GW (US$ bn / GW-year) | CY24-26 implied | E12: =E15/E11 -> 13.438596 | F12: =F15/F11 -> 10.634197 | G12: =G15/G11 -> 11.3879 | H12: ='Assumptions & sources'!H76*$D$6 -> 12 | I12: ='Assumptions & sources'!I76*$D$6 -> 12.5 | J12: ='Assumptions & sources'!J76*$D$6 -> 12.8 | K12: ='Assumptions & sources'!K76*$D$6 -> 13 | L12: ='Assumptions & sources'!L76*$D$6 -> 13.3 | M12: ='Assumptions & sources'!M76*$D$6 -> 13.7 | N12: ='Assumptions & sources'!N76*$D$6 -> 14 | O12: ='Assumptions & sources'!O76*$D$6 -> 14 | ... Z12: ='Assumptions & sources'!Z76*$D$6 -> 14
C13: Memo: revenue per average ACTIVE GW (US$ bn / GW-year) — alternative, lower basis | E13: =E15/E10 -> 8.9069767 | F13: =F15/F10 -> 8.4809917 | G13: =G15/G10 -> 9.3090909 | H13: =H15/H10 -> 10.470588 | I13: =I15/I10 -> 11.313291 | J13: =J15/J10 -> 11.869091 | K13: =K15/K10 -> 12.227273 | L13: =L15/L10 -> 12.764943 | ... Z13: =Z15/Z10 -> 13.896552
C14: Revenue (US$ millions)
C15: Scenario revenue | D15: ='Assumptions & sources'!D9 -> 229 | E15: ='Assumptions & sources'!E9 -> 1915 | F15: ='Assumptions & sources'!F9 -> 5131 | G15: =('Assumptions & sources'!$D$28+'Assumptions & sources'!$D$29)/2 -> 12800 | H15: =H11*H12 -> 26700 | I15: =I11*I12 -> 44687.5 | J15: =J11*J12 -> 65280 | K15: =K11*K12 -> 87425 | L15: =L11*L12 -> 111055 | M15: =M11*M12 -> 132890 | N15: =N11*N12 -> 151900 | O15: =O11*O12 -> 165550 | ... Z15: =Z11*Z12 -> 244770.88
C16: Revenue growth | E16: =E15/D15-1 -> 7.3624454 | F16: =F15/E15-1 -> 1.6793734 | G16: =G15/F15-1 -> 1.4946404 | H16: =H15/G15-1 -> 1.0859375 | I16: =I15/H15-1 -> 0.67368914 | J16: =J15/I15-1 -> 0.46081119 | K16: =K15/J15-1 -> 0.339231 | L16: =L15/K15-1 -> 0.27028882 | ... Z16: =Z15/Y15-1 -> 0.03
C17: Revenue | BBG consensus CY26-28 (memo) | G17: ='Assumptions & sources'!G9 -> 12770.37 | H17: ='Assumptions & sources'!H9 -> 26439.52 | I17: ='Assumptions & sources'!I9 -> 42212.08
C18: Scenario ÷ consensus − 1 | G18: =G15/G17-1 -> 0.0023202147 | H18: =H15/H17-1 -> 0.0098519186 | I18: =I15/I17-1 -> 0.058642455
C19: Memo: 2030 revenue — UBS $84.8bn / Street ~$80bn (UBS 09-22) vs scenario | K19: =K15/84800-1 -> 0.030955189
C21: Operating result and cash (company adjusted basis; SBC deducted below)
C22: Adjusted EBITDA margin | E22: ='Assumptions & sources'!E10/E15 -> 0.64020888 | F22: ='Assumptions & sources'!F10/F15 -> 0.60378094 | G22: ='Assumptions & sources'!G77 -> 0.575 | H22: ='Assumptions & sources'!H77+$E$6 -> 0.62 | I22: ='Assumptions & sources'!I77+$E$6 -> 0.64 | J22: ='Assumptions & sources'!J77+$E$6 -> 0.64 | K22: ='Assumptions & sources'!K77+$E$6 -> 0.63 | L22: ='Assumptions & sources'!L77+$E$6 -> 0.62 | M22: ='Assumptions & sources'!M77+$E$6 -> 0.62 | N22: ='Assumptions & sources'!N77+$E$6 -> 0.62 | O22: ='Assumptions & sources'!O77+$E$6 -> 0.62 | ... Z22: ='Assumptions & sources'!Z77+$E$6 -> 0.62
C23: Adjusted EBITDA | E23: =E15*E22 -> 1226 | F23: =F15*F22 -> 3098 | G23: =G15*G22 -> 7360 | H23: =H15*H22 -> 16554 | I23: =I15*I22 -> 28600 | J23: =J15*J22 -> 41779.2 | K23: =K15*K22 -> 55077.75 | L23: =L15*L22 -> 68854.1 | ... Z23: =Z15*Z22 -> 151757.95
C24: EBITDA | BBG consensus (memo) | G24: ='Assumptions & sources'!G10 -> 7482.66 | H24: ='Assumptions & sources'!H10 -> 16630.37 | I24: ='Assumptions & sources'!I10 -> 27896.76
C25: D&A per average active GW (US$ bn / GW-year) | CY24-25 implied | E25: =E26/E10 -> 4.0139535 | F25: =F26/F10 -> 4.0561983 | G25: ='Assumptions & sources'!G78 -> 4.6 | H25: ='Assumptions & sources'!H78 -> 4.8 | I25: ='Assumptions & sources'!I78 -> 5 | J25: ='Assumptions & sources'!J78 -> 5 | K25: ='Assumptions & sources'!K78 -> 5 | L25: ='Assumptions & sources'!L78 -> 5 | M25: ='Assumptions & sources'!M78 -> 5 | N25: ='Assumptions & sources'!N78 -> 5 | ... Z25: ='Assumptions & sources'!Z78 -> 5
C26: Depreciation and amortization | D26: ='Assumptions & sources'!D14 -> 103 | E26: ='Assumptions & sources'!E14 -> 863 | F26: ='Assumptions & sources'!F14 -> 2454 | G26: =G10*G25 -> 6325 | H26: =H10*H25 -> 12240 | I26: =I10*I25 -> 19750 | J26: =J10*J25 -> 27500 | K26: =K10*K25 -> 35750 | L26: =L10*L25 -> 43500 | M26: =M10*M25 -> 50000 | N26: =N10*N25 -> 55500 | ... Z26: =Z10*Z25 -> 88068.928
C27: Adjusted operating income (AOI = EBITDA − D&A) | E27: =E23-E26 -> 363 | F27: =F23-F26 -> 644 | G27: =G23-G26 -> 1035 | H27: =H23-H26 -> 4314 | I27: =I23-I26 -> 8850 | J27: =J23-J26 -> 14279.2 | K27: =K23-K26 -> 19327.75 | L27: =L23-L26 -> 25354.1 | ... Z27: =Z23-Z26 -> 63689.019
C28: Adjusted operating margin | E28: =E27/E15 -> 0.18955614 | F28: =F27/F15 -> 0.1255116 | G28: =G27/G15 -> 0.080859375 | H28: =H27/H15 -> 0.16157303 | I28: =I27/I15 -> 0.19804196 | J28: =J27/J15 -> 0.21873775 | K28: =K27/K15 -> 0.22107807 | L28: =L27/L15 -> 0.22830219 | ... Z28: =Z27/Z15 -> 0.26019851
C29: AOI | BBG consensus EBIT (memo) / FY26 guide midpoint | G29: =('Assumptions & sources'!$D$30+'Assumptions & sources'!$D$31)/2 -> 1055 | H29: ='Assumptions & sources'!H11 -> 4113.1 | I29: ='Assumptions & sources'!I11 -> 7363.56
C30: Stock-based compensation | D30: =-'Assumptions & sources'!D15 -> -15 | E30: =-'Assumptions & sources'!E15 -> -31 | F30: =-'Assumptions & sources'!F15 -> -630 | G30: =-G15*'Assumptions & sources'!G79 -> -640 | H30: =-H15*'Assumptions & sources'!H79 -> -801 | I30: =-I15*'Assumptions & sources'!I79 -> -1117.1875 | J30: =-J15*'Assumptions & sources'!J79 -> -1305.6 | K30: =-K15*'Assumptions & sources'!K79 -> -1748.5 | L30: =-L15*'Assumptions & sources'!L79 -> -2221.1 | M30: =-M15*'Assumptions & sources'!M79 -> -2657.8 | N30: =-N15*'Assumptions & sources'!N79 -> -3038 | ... Z30: =-Z15*'Assumptions & sources'!Z79 -> -4895.4177
C31: EBIT after SBC | E31: =E27+E30 -> 332 | F31: =F27+F30 -> 14 | G31: =G27+G30 -> 395 | H31: =H27+H30 -> 3513 | I31: =I27+I30 -> 7732.8125 | J31: =J27+J30 -> 12973.6 | K31: =K27+K30 -> 17579.25 | L31: =L27+L30 -> 23133 | ... Z31: =Z27+Z30 -> 58793.602
C32: EBIT margin after SBC | E32: =E31/E15 -> 0.17336815 | F32: =F31/F15 -> 0.002728513 | G32: =G31/G15 -> 0.030859375 | H32: =H31/H15 -> 0.13157303 | I32: =I31/I15 -> 0.17304196 | J32: =J31/J15 -> 0.19873775 | K32: =K31/K15 -> 0.20107807 | L32: =L31/L15 -> 0.20830219 | ... Z32: =Z31/Z15 -> 0.24019851
C33: Cash tax rate | G33: ='Assumptions & sources'!G80 -> 0.05 | H33: ='Assumptions & sources'!H80 -> 0.05 | I33: ='Assumptions & sources'!I80 -> 0.05 | J33: ='Assumptions & sources'!J80 -> 0.1 | K33: ='Assumptions & sources'!K80 -> 0.15 | L33: ='Assumptions & sources'!L80 -> 0.21 | M33: ='Assumptions & sources'!M80 -> 0.21 | N33: ='Assumptions & sources'!N80 -> 0.21 | ... Z33: ='Assumptions & sources'!Z80 -> 0.21
C34: NOPAT | G34: =G31*(1-G33) -> 375.25 | H34: =H31*(1-H33) -> 3337.35 | I34: =I31*(1-I33) -> 7346.1719 | J34: =J31*(1-J33) -> 11676.24 | K34: =K31*(1-K33) -> 14942.362 | L34: =L31*(1-L33) -> 18275.07 | M34: =M31*(1-M33) -> 23489.86 | N34: =N31*(1-N33) -> 28155.6 | ... Z34: =Z31*(1-Z33) -> 46446.945
C35: Build cost per GW added (US$ bn / GW) | G35: ='Assumptions & sources'!G81 -> 33 | H35: ='Assumptions & sources'!H81 -> 38 | I35: ='Assumptions & sources'!I81 -> 40 | J35: ='Assumptions & sources'!J81 -> 40 | K35: ='Assumptions & sources'!K81 -> 40 | L35: ='Assumptions & sources'!L81 -> 40 | M35: ='Assumptions & sources'!M81 -> 40 | N35: ='Assumptions & sources'!N81 -> 40 | ... Z35: ='Assumptions & sources'!Z81 -> 40
C36: Growth capex = build x ((1 − pre-build) x adds t + pre-build x adds t+1) | G36: =-G35*((1-'Assumptions & sources'!$D$68)*G9+'Assumptions & sources'!$D$68*H9) -> -36300 | H36: =-H35*((1-'Assumptions & sources'!$D$68)*H9+'Assumptions & sources'!$D$68*I9) -> -50920 | I36: =-I35*((1-'Assumptions & sources'!$D$68)*I9+'Assumptions & sources'!$D$68*J9) -> -60800 | J36: =-J35*((1-'Assumptions & sources'!$D$68)*J9+'Assumptions & sources'!$D$68*K9) -> -64800 | K36: =-K35*((1-'Assumptions & sources'!$D$68)*K9+'Assumptions & sources'!$D$68*L9) -> -65600 | L36: =-L35*((1-'Assumptions & sources'!$D$68)*L9+'Assumptions & sources'!$D$68*M9) -> -54400 | M36: =-M35*((1-'Assumptions & sources'!$D$68)*M9+'Assumptions & sources'!$D$68*N9) -> -46400 | N36: =-N35*((1-'Assumptions & sources'!$D$68)*N9+'Assumptions & sources'!$D$68*O9) -> -39200 | ... Y36: =-Y35*((1-'Assumptions & sources'!$D$68)*Y9+'Assumptions & sources'!$D$68*Z9) -> -20338.956 | Z36: =-Z35*((1-'Assumptions & sources'!$D$68)*Z9+'Assumptions & sources'!$D$68*Z9) -> -20824.18
C37: Power replaced in the year (MW) = power installed in (t − life), adds and replacements included | D37: =IF(COLUMN(D9)-COLUMN($D$9)+1-$F$6>=1,INDEX($D$38:$Z$38,1,COLUMN(D9)-COLUMN($D$9)+1-$F$6),0) -> 0 | E37: =IF(COLUMN(E9)-COLUMN($D$9)+1-$F$6>=1,INDEX($D$38:$Z$38,1,COLUMN(E9)-COLUMN($D$9)+1-$F$6),0) -> 0 | F37: =IF(COLUMN(F9)-COLUMN($D$9)+1-$F$6>=1,INDEX($D$38:$Z$38,1,COLUMN(F9)-COLUMN($D$9)+1-$F$6),0) -> 0 | G37: =IF(COLUMN(G9)-COLUMN($D$9)+1-$F$6>=1,INDEX($D$38:$Z$38,1,COLUMN(G9)-COLUMN($D$9)+1-$F$6),0) -> 0 | H37: =IF(COLUMN(H9)-COLUMN($D$9)+1-$F$6>=1,INDEX($D$38:$Z$38,1,COLUMN(H9)-COLUMN($D$9)+1-$F$6),0) -> 0 | I37: =IF(COLUMN(I9)-COLUMN($D$9)+1-$F$6>=1,INDEX($D$38:$Z$38,1,COLUMN(I9)-COLUMN($D$9)+1-$F$6),0) -> 0 | J37: =IF(COLUMN(J9)-COLUMN($D$9)+1-$F$6>=1,INDEX($D$38:$Z$38,1,COLUMN(J9)-COLUMN($D$9)+1-$F$6),0) -> 70 | K37: =IF(COLUMN(K9)-COLUMN($D$9)+1-$F$6>=1,INDEX($D$38:$Z$38,1,COLUMN(K9)-COLUMN($D$9)+1-$F$6),0) -> 290 | ... Z37: =IF(COLUMN(Z9)-COLUMN($D$9)+1-$F$6>=1,INDEX($D$38:$Z$38,1,COLUMN(Z9)-COLUMN($D$9)+1-$F$6),0) -> 2735.9981
C38: Power installed in the year (MW) = adds + replacements | D38: =D9+D37 -> 70 | E38: =E9+E37 -> 290 | F38: =F9+F37 -> 490 | G38: =G9+G37 -> 1050 | H38: =H9+H37 -> 1300 | I38: =I9+I37 -> 1500 | J38: =J9+J37 -> 1670 | K38: =K9+K37 -> 1990 | ... Z38: =Z9+Z37 -> 3256.6026
C39: Replacement capex = power replaced x build x replacement % | G39: =-G37*G35*$G$6 -> 0 | H39: =-H37*H35*$G$6 -> 0 | I39: =-I37*I35*$G$6 -> 0 | J39: =-J37*J35*$G$6 -> -2240 | K39: =-K37*K35*$G$6 -> -9280 | L39: =-L37*L35*$G$6 -> -15680 | M39: =-M37*M35*$G$6 -> -33600 | N39: =-N37*N35*$G$6 -> -41600 | ... Z39: =-Z37*Z35*$G$6 -> -87551.938
C40: Total capex | CY23-25 reported cash; 2026 guide (midpoint) | D40: =-'Assumptions & sources'!D16 -> -2943 | E40: =-'Assumptions & sources'!E16 -> -8702 | F40: =-'Assumptions & sources'!F16 -> -10309 | G40: =-('Assumptions & sources'!$D$32+'Assumptions & sources'!$D$33)/2 -> -37000 | H40: =H36+H39 -> -50920 | I40: =I36+I39 -> -60800 | J40: =J36+J39 -> -67040 | K40: =K36+K39 -> -74880 | L40: =L36+L39 -> -70080 | M40: =M36+M39 -> -80000 | N40: =N36+N39 -> -80800 | O40: =O36+O39 -> -83200 | ... Z40: =Z36+Z39 -> -108376.12
C41: Capex | BBG consensus (memo) | G41: =-'Assumptions & sources'!G16 -> -35670.67 | H41: =-'Assumptions & sources'!H16 -> -47897.41 | I41: =-'Assumptions & sources'!I16 -> -50387.97
C42: Memo: 2026 capex by the formula (calibration check) | G42: =G36+G39 -> -36300
...

Sheet Assumptions & sources
C2: CRWV | Assumptions & sources
C3: Data taken from the sources named. US$ millions unless stated; power in MW (critical IT load, the company's basis); revenue per GW and build cost per GW in US$ billions per GW. Fiscal year = calendar year.
C4: Blue = HARD input (filing / consensus); yellow = PARTIAL assumption (sourced range, point is ours); salmon = ESTIMATE (no source). Source in column L (tables) or AB (series).
D5: 2023 | E5: 2024 | F5: 2025 | G5: 2026 | H5: 2027 | I5: 2028
L6: File, sheet and source cells. CY = calendar year (= CoreWeave's fiscal year).
C8: Reported history (10-K FY25, 10-Q 2Q26) and BBG consensus (2026-10-13)
C9: Revenue (US$ m) | 10-K FY23-25 / BBG consensus CY26-28 | D9: 229 | E9: 1915 | F9: 5131 | G9: 12770.37 | H9: 26439.52 | I9: 42212.08 | L9: 10-K FY25 (CRWV/CRWV_10-K_2026-03-02): 229 / 1,915 / 5,131. CY26-28: _wiki/_data/estimates.json CRWV CY2026 / CY2027 / 3FY (BEst 2026-10-13; 47 analysts, 33 buy / 10 hold / 4 sell).
C10: Adjusted EBITDA (US$ m) | company / consensus | E10: 1226 | F10: 3098 | G10: 7482.66 | H10: 16630.37 | I10: 27896.76 | L10: FY24: 64% margin (DB CRWV unit economics 2025-06-16) x 1,915 = 1,226 (PARTIAL). FY25 = sum of quarters: 1Q25 ~609 (1Q26 ~1,164 = 56% x 2,078, '+91% y/y', call 2026-05-07 — PARTIAL) + 2Q 753 + 3Q 838 + 4Q 898 (calls). CY26-28 BEst EBITDA.
C11: Adjusted operating income (AOI, US$ m) | consensus EBIT CY26-28 | G11: 1004.25 | H11: 4113.1 | I11: 7363.56 | L11: BEst EBIT (estimates.json). FY26 guide (call 2026-08-11): AOI $960-1,150m; 3Q26 $200-260m.
C12: GAAP net income (US$ m) | 10-K / consensus | D12: -594 | E12: -863 | F12: -1167 | G12: -2197.83 | H12: -1132.69 | I12: 974.96 | L12: 10-K FY25 (net loss); BEst NI CY26-28.
C13: GAAP diluted EPS (US$) | 10-K / consensus | D13: -3.09 | E13: -4.3 | F13: -2.81 | G13: -3.92 | H13: -2.09 | I13: 1.431 | L13: 10-K FY25 p.1508: net loss per share attributable to common stockholders, diluted: (3.09) / (4.30) / (2.81) (two-class method; post 20:1 split of Mar-25). CY26-28 BEst EPS (ex-SBC).
C14: Depreciation and amortization (US$ m) | D14: 103 | E14: 863 | F14: 2454 | G14: 2540 | L14: 10-K cash flow FY23-25; 1H26 = 2,540 (10-Q 2Q26). 2026 column = 1H26 (memo).
C15: Stock-based compensation (US$ m) | D15: 15 | E15: 31 | F15: 630 | G15: 318 | L15: 10-K cash flow (FY25 includes $177m of RSUs vested at the IPO); 1H26 = 318 (memo).
C16: Cash capex (US$ m) | 10-K / BBG consensus CY26-28 | D16: 2943 | E16: 8702 | F16: 10309 | G16: 35670.67 | H16: 47897.41 | I16: 50387.97 | L16: 10-K 'Purchase of property and equipment' 2,943 / 8,702 / 10,309 (FY25 company basis ~$14bn incl. OEM financing: 3Q25 guide $12-14bn). CY26-28 BEst capex. FY26 guide (company basis): $35-39bn.
C17: Net interest expense (US$ m) | D17: 28 | E17: 361 | F17: 1229 | G17: 1176 | L17: 10-K FY23-25; 1H26 = 1,176 (10-Q 2Q26). 3Q26 guide: $860-940m.
C18: Active power at year-end (MW, IT load) | D18: 70 | E18: 360 | F18: 850 | G18: 1500 | L18: 10-K FY25 p.194: ~70 MW (Dec-23), ~360 MW (Dec-24), >850 MW (Dec-25). 2026 column = Jun-26: 1.5 GW (call 2026-08-11). YE26 guide: >1.85 GW.
C19: Contracted power (MW) | F19: 3100 | G19: 4200 | L19: 10-K FY25: ~3.1 GW (Dec-25). Call 2026-08-11: 3.7 GW at 2Q-end, 4.2 GW as of 11-Aug-26 (2026 column). Target: >=8 GW active by 2030.
C20: Unsatisfied RPO (US$ m) | F20: 60700 | G20: 103700 | L20: 10-K FY25: $60.7bn (43% within 24 months). 10-Q 2Q26: $103.7bn, 41% in the 24 months to Jun-28, 39% months 25-48, balance months 49-78. Backlog (company metric): $66.8bn Dec-25 / $104bn Jun-26.
C21: Total deferred revenue (US$ m) | Dec-24 / Dec-25 / Jun-26 | E21: 4064 | F21: 8185 | G21: 9692 | L21: 10-K FY25 balance sheet (769+3,295; 1,709+6,476); 10-Q 2Q26 (2,686+7,006). Customer prepayments = 15-25% of TCV (UBS 2026-09-22).
C22: Accounts receivable (US$ m) | Dec-24 / Dec-25 / Jun-26 | E22: 417 | F22: 3169 | G22: 2541 | L22: 10-K FY25; 10-Q 2Q26.
C23: Cash and equivalents (US$ m) | Dec-24 / Dec-25 / Jun-26 | E23: 1361 | F23: 3127 | G23: 5524 | L23: 10-K FY25; 10-Q 2Q26. Additional restricted cash: 1,003 (Dec-25: 819 + 184) / 1,380 (Jun-26: 873 + 507) — debt-service coverage, excluded from net cash.
C24: Gross debt, principal (US$ m) | Dec-24 / Dec-25 / Jun-26 | E24: 7926 | F24: 21615 | G24: 35551 | L24: 10-K FY25 note 10 (Dec-24 carrying value 7,926; Dec-25 carrying 21,373 + discount 242 = 21,615). 10-Q 2Q26 note 10: total principal 35,551 (recourse + non-recourse). See Debt sheet.
C25: Operating lease liabilities (US$ m) | Dec-24 / Dec-25 / Jun-26 | E25: 2602 | F25: 8195 | G25: 16319 | L25: 10-K FY25; 10-Q 2Q26 (10% rate, 12-year term). Plus $35.5bn of leases not yet commenced (Jun-26). Rent sits in EBITDA — NOT added to net debt.
C27: FY26 guidance (2Q26 call, 2026-08-11) — company basis
C28: FY26 revenue — low end (US$ m) | D28: 12400 | F28: Call 2026-08-11: $12.4-13.2bn (raised from $12.0-13.0bn in Feb-26).
C29: FY26 revenue — high end (US$ m) | D29: 13200 | F29: Same.
C30: FY26 AOI — low end (US$ m) | D30: 960 | F30: Call 2026-08-11: $960-1,150m (from $900-1,100m).
C31: FY26 AOI — high end (US$ m) | D31: 1150 | F31: Same.
C32: FY26 capex — low end (US$ m, company basis) | D32: 35000 | F32: Call 2026-08-11: $35-39bn (from $31-35bn). 1H26 reported: 6.8 + 9.4 = $16.2bn (cash: 14.1).
C33: FY26 capex — high end (US$ m) | D33: 39000 | F33: Same.
C34: Active power YE26 — guide (MW) | D34: 1850 | F34: Call 2026-08-11: '>1.85 GW' (from >1.7 GW). UBS 09-22: 1,900 MW FY26E, 3,200 FY27E, 4,720 FY28E, 6,320 FY29E, 8,000 FY30E.
C35: 3Q26 revenue — midpoint (US$ m) | D35: 3525 | F35: Call 2026-08-11: $3.45-3.60bn; 3Q AOI $200-260m; 3Q interest $860-940m; 3Q capex $11.5-13.5bn.
C36: 1H26 reported revenue (US$ m) | D36: 4653 | F36: 10-Q 2Q26: 2,078 + 2,575.
C37: 1H26 reported AOI (US$ m) | D37: 149 | F37: Calls: 1Q26 $21m + 2Q26 $128m.
C38: Average billable power 2026 (MW) — quarterly build | D38: 1124 | F38: Average over four quarters of the PRIOR quarter's average active power (UBS 09-22: 'it takes about a quarter for active power to generate revs'): 1Q (590+850)/2=720; 2Q (850+1,000)/2=925; 3Q (1,000+1,500)/2=1,250; 4Q (1,500+1,700)/2=1,600 (3Q26 YE estimated 1,700). Average 1,124. Overrides the annual formula in 2026 (adds were front-loaded in 1H).
C40: Revenue-per-GW marks (US$ bn per IT-load GW per YEAR) — wiki ledger; NEVER net different bases
C41: Realised on the installed book (UBS, 09-22) | D41: 11 | F41: UBS Keirstead 2026-09-22: 2Q26 $2.575bn x4 / 925 MW average active power in 1Q26 = ~$11bn/GW; 'closer to $15bn by end of 2027'. This model: 2026 implied by the guide = ~11.4.
C42: Floor for new long-dated contracts (4-6 years) — management | D42: 15.5 | F42: Nick Robbins (VP Corp Dev) @ BTG Pactual, 2026-09-21: mid-teens $/W/year is 'the absolute floor'; long-dated Vera Rubin 'clearing higher'. Seller of the capacity, not audited.
C43: Nscale's filed book (S-1 2026-09-18) — blended / VR tranche | D43: 13.2 | F43: Nscale S-1: $103.4bn TCV / 5.7 years / 1.37 GW IT = ~$13.2bn/GW-year; Anthropic Vera Rubin tranche ~$16.2bn. Read by the wiki as the CEILING of a contracted book (open conflict with management).
C44: Short-dated contracts (3-6 months) — annualised | D44: 40 | F44: Robbins 09-21: 'about $40 million a megawatt' on short-dated contracts for PRIOR generations (Blackwell / Grace Blackwell), term and time basis not stated; JPM 09-24 repeats the print without a basis; only UBS 09-22 gives the term (3-6 months) and the annualised basis ($40bn/GW). Small slice of the book. Arete 08-21: $20-25m/MW on 2-3-year contracts.
...

Sheet History
C2: CRWV | Reported history (annual and quarterly)
C3: US$ millions unless stated. Source: 10-K FY25, 10-Qs 1Q25-2Q26 (CRWV/), earnings calls (CRWV/transcripts). Blue = reported; derived/PARTIAL noted in the source column.
D5: FY23 | E5: FY24 | F5: FY25 | G5: 1Q25 | H5: 2Q25 | I5: 3Q25 | J5: 4Q25 | K5: 1Q26 | L5: 2Q26 | N5: Source
C7: Income statement and cash flow
C8: Revenue | D8: 229 | E8: 1915 | F8: 5131 | G8: 981.6 | H8: 1212.8 | I8: 1364.7 | J8: 1571.9 | K8: 2078 | L8: 2575 | N8: 10-K FY25; 10-Qs (1Q25-3Q25 in US$ thousands, converted); 4Q25 = FY − 9M.
C9: Cost of revenue | D9: 69 | E9: 493 | F9: 1453 | G9: 262.4 | H9: 312.7 | I9: 368.8 | J9: 509.1 | K9: 716 | L9: 879 | N9: Same.
C10: Technology and infrastructure | D10: 131 | E10: 961 | F10: 2929 | G10: 561.4 | H10: 669.9 | I10: 747.5 | J10: 950.2 | K10: 1273 | L10: 1507 | N10: Same (includes DC rent, power, D&A).
C11: Sales and marketing | D11: 13 | E11: 18 | F11: 144 | G11: 10.5 | H11: 36.8 | I11: 44.6 | J11: 52 | K11: 69 | L11: 60 | N11: Same.
C12: General and administrative | D12: 30 | E12: 119 | F12: 651 | G12: 174.8 | H12: 174.2 | I12: 151.9 | J12: 150.2 | K12: 164 | L12: 178 | N12: Same.
C13: GAAP operating income | D13: -14 | E13: 324 | F13: -46 | G13: -27.5 | H13: 19.2 | I13: 51.9 | J13: -89.6 | K13: -144 | L13: -49 | N13: Same.
C14: Net interest expense | D14: -28 | E14: -361 | F14: -1229 | G14: -263.8 | H14: -267.2 | I14: -311 | J14: -387 | K14: -536 | L14: -640 | N14: Same; 3Q25 call ($311m).
C15: GAAP net income | D15: -594 | E15: -863 | F15: -1167 | G15: -314.6 | H15: -290.5 | I15: -110.1 | J15: -451.8 | K15: -740 | L15: -626 | N15: Same.
C16: Depreciation and amortization | D16: 103 | E16: 863 | F16: 2454 | G16: 443.5 | H16: 559.5 | I16: 630.5 | J16: 820.5 | K16: 1147 | L16: 1393 | N16: Cash-flow YTD figures differenced by quarter.
C17: Stock-based compensation | D17: 15 | E17: 31 | F17: 630 | G17: 184 | H17: 145 | I17: 144.4 | J17: 156.6 | K17: 153 | L17: 165 | N17: Cash-flow YTD differenced (9M25 473.4): 3Q 144.4 / 4Q 156.6 (the statement of equity shows 156.9 in 3Q — different basis).
C18: Cash capex (purchase of PP&E) | D18: 2943 | E18: 8702 | F18: 10309 | G18: 1407 | H18: 2453 | I18: 2389 | J18: 4060 | K18: 7695 | L18: 6422 | N18: Cash-flow YTD differenced.
C19: Capex, company basis (calls) | K19: 6800 | L19: 9400 | N19: Calls 1Q26 (05-07) and 2Q26 (08-11). FY26 guide $35-39bn. Includes OEM financing; differs from cash.
C20: Adjusted EBITDA (company) | E20: 1226 | F20: 3098 | G20: 609 | H20: 753 | I20: 838 | J20: 898 | K20: 1164 | L20: 1510 | N20: Calls; FY24 = 64% (DB 2025-06-16) PARTIAL; 1Q26 = '$1.2bn, ~56%' x 2,078 = 1,164 PARTIAL; 1Q25 = 1,164/1.91 ('+91% y/y') PARTIAL.
C21: Adjusted EBITDA margin | E21: =E20/E8 -> 0.64020888 | F21: =F20/F8 -> 0.60378094 | G21: =G20/G8 -> 0.62041565 | H21: =H20/H8 -> 0.62087731 | I21: =I20/I8 -> 0.61405437 | J21: =J20/J8 -> 0.57128316 | K21: =K20/K8 -> 0.56015399 | L21: =L20/L8 -> 0.58640777 | N21: Calculated.
C22: AOI (adjusted operating income, company) | H22: 200 | I22: 217 | K22: 21 | L22: 128 | N22: Calls: 2Q25 $200m (cited on the 2Q26 call, 08-11), 3Q25 $217m, 1Q26 $21m, 2Q26 $128m. FY25 guide $690-720m (3Q25 call).
C23: Operating and balance sheet
C24: Active power at period-end (MW) | D24: 70 | E24: 360 | F24: 850 | G24: 420 | H24: 470 | I24: 590 | J24: 850 | K24: 1000 | L24: 1500 | N24: 10-K FY25 (70 / 360 / >850); calls (3Q25 590 = +120 q/q → 2Q25 470; 1Q25 ~420 ESTIMATE; 1Q26 '>1 GW'; 2Q26 1.5 GW).
C25: Contracted power at period-end (MW) | F25: 3100 | I25: 2900 | J25: 3100 | K25: 3500 | L25: 3700 | N25: Calls; 4.2 GW as of 11-Aug-26.
C26: Revenue backlog (company, US$ bn) | E26: 15.1 | F26: 66.8 | H26: 30.1 | I26: 55.6 | J26: 66.8 | K26: 99.4 | L26: 104 | N26: Calls (2Q25 'doubled YTD' → Dec-24 ~15.1 PARTIAL). RPO 10-K/10-Q: 60.7 (Dec-25) / 103.7 (Jun-26).
C27: Total deferred revenue (US$ m) | E27: 4064 | F27: 8185 | J27: 8185 | L27: 9692 | N27: Balance sheets.
C28: Unrestricted cash (US$ m) | D28: 217 | E28: 1361 | F28: 3127 | J28: 3127 | L28: 5524 | N28: Balance sheets.
C29: Gross debt, principal (US$ m) | E29: 7926 | F29: 21615 | J29: 21615 | L29: 35551 | N29: Debt notes (Dec-24 carrying value).
C30: Weighted diluted shares (m) | D30: 192 | E30: 218 | F30: 436 | H30: 487 | L30: 551 | N30: 10-K / 10-Q (post 20:1 split).
C32: Calibration | annualised quarterly revenue ÷ average active power of the PRIOR quarter (US$ bn / GW-year)
C33: Average active power of the prior quarter (MW) | H33: =(E24+G24)/2 -> 390 | I33: =(G24+H24)/2 -> 445 | J33: =(H24+I24)/2 -> 530 | K33: =(I24+J24)/2 -> 720 | L33: =(J24+K24)/2 -> 925 | N33: Prior quarter = average of the end of the quarter before last and the end of the prior quarter (2Q25 uses Dec-24 360 and 1Q25 ~420 ESTIMATE). 1Q25 omitted (3Q24 not reported). Basis UBS 09-22 ('about a quarter for active power to generate revs'); 2Q26 = 2,575 x 4 / 925 = 11.1 = UBS.
C34: Revenue per billable GW (US$ bn / GW-year) | H34: =H8*4/H33 -> 12.438974 | I34: =I8*4/I33 -> 12.266966 | J34: =J8*4/J33 -> 11.863396 | K34: =K8*4/K33 -> 11.544444 | L34: =L8*4/L33 -> 11.135135 | N34: Falls from ~12.4 (2Q25) to ~11.1 (2Q26): the fleet scaled faster than the average price (legacy MSFT/OpenAI book). UBS: ~11 → ~15 at the 2027 exit. Anchor of the model (cover row 12).
C35: Annualised D&A ÷ average active power of the quarter (US$ bn / GW-year) | H35: =H16*4/((G24+H24)/2) -> 5.0292135 | I35: =I16*4/((H24+I24)/2) -> 4.7584906 | J35: =J16*4/((I24+J24)/2) -> 4.5583333 | K35: =K16*4/((J24+K24)/2) -> 4.96 | L35: =L16*4/((K24+L24)/2) -> 4.4576 | N35: Anchor of D&A per GW (cover): ~4.5-5.0.
C36: Annualised interest ÷ period-end gross debt (memo) | J36: =-J14*4/J29 -> 0.071616933 | L36: =-L14*4/L29 -> 0.072009226 | N36: 4Q25 ~7.2% and 2Q26 ~7.2% on END-of-period principal (debt grew during the period; capitalised interest excluded) — contractual effective rates 9-11%.

Sheet Debt
C2: CRWV | Debt (10-Q 2Q26, note 10 — principal, US$ millions)
C3: Source: CRWV/CRWV_10-Q_2026-08-12 note 10 (total debt obligations; future principal payments). Rates = 'effective interest rates' from the table.
C5: Type | D5: Instrument | E5: Maturity | F5: Effective rate | G5: 30-Jun-2026 | H5: 31-Dec-2025
C6: Recourse | D6: DDTL 1.0 Facility | E6: Mar-2028 | F6: 0.15 | G6: 1300 | H6: 1553
C7: Recourse | D7: DDTL 2.0 Facility | E7: Aug-2030 | F7: 0.11 | G7: 3190 | H7: 5037
C8: Recourse | D8: DDTL 2.1 Facility | E8: Mar-2031 | F8: 0.09 | G8: 3000 | H8: 2741
C9: Recourse | D9: DDTL 3.0 Facility | E9: Aug-2030 | F9: 0.09 | G9: 2215 | H9: 340
C10: Recourse | D10: DDTL 5.0 Facility (SOFR + 4.50%, May-26) | E10: Nov-2031 | F10: 0.09 | G10: 1101 | H10: 0
C11: Recourse | D11: 2030 Senior Notes (9.25%) | E11: Jun-2030 | F11: 0.1 | G11: 2000 | H11: 2000
C12: Recourse | D12: 2031 9.00% Senior Notes | E12: Feb-2031 | F12: 0.1 | G12: 1750 | H12: 1750
C13: Recourse | D13: 2031 9.75% Senior Notes (Apr-26) | E13: Oct-2031 | F13: 0.1 | G13: 2750 | H13: 0
C14: Recourse | D14: 2032 9.625% Senior Notes (Jun-26) | E14: Jul-2032 | F14: 0.1 | G14: 1250 | H14: 0
C15: Recourse | D15: 2032 EUR Senior Notes (8.50%, EUR 2.0bn, swapped to US$) | E15: Jul-2032 | F15: 0.09 | G15: 2279 | H15: 0
C16: Recourse | D16: 2031 Convertible Senior Notes (1.75%) | E16: Dec-2031 | F16: 0.02 | G16: 2588 | H16: 2588
C17: Recourse | D17: 2032 Convertible Senior Notes (1.75%; conv. $119.60; cap call $230) | E17: Oct-2032 | F17: 0.02 | G17: 4000 | H17: 0
... C23: Non-recourse | D23: OEM and Software License Financing Arrangements | E23: Aug-26 to Aug-28 | F23: 0.09 | G23: 882 | H23: 647
D24: Total principal (recourse + non-recourse) | G24: =SUM(G6:G23) -> 35551 | H24: =SUM(H6:H23) -> 21615
D25: Weighted-average effective rate (Jun-26) | G25: =SUMPRODUCT(F6:F23,G6:G23)/G24 -> 0.084134342
D26: Check: note total = 35,551 (Jun-26) / 21,615 (Dec-25) | G26: =G24-35551 -> 0 | H26: =H24-21615 -> 0
D27: Less: unamortized discount and issuance costs (Jun-26: 427 + 56) | G27: -483
D28: Carrying value (recourse 31,405 + non-recourse 3,663 = 35,068) | G28: =G24+G27 -> 35068
D30: Principal amortization (Jun-26) | G30: US$ m
D31: Remainder of 2026 | G31: 4413
D32: 2027 | G32: 6184
D33: 2028 | G33: 4416
D34: 2029 | G34: 2421
D35: 2030 | G35: 3221
D36: Thereafter | G36: 14896
D37: Total | G37: =SUM(G31:G36) -> 35551
D39: 2Q26 interest: contractual 592 + discount amortization 45 − capitalised 79 = 558 (note 10); 'interest expense, net' on the P&L = 640. 3Q26 guide: $860-940m. 1H26 cash paid 806.
D40: Operating leases (Jun-26): PV 16,319 (10% rate, 12 years); future payments 29,135; not yet commenced 35,500 (a single site = 14,700, 393 MW to be delivered). Rent sits in EBITDA — do not add to debt.
D41: DDTL spreads (Redburn 09-21, Fig 70): S+962 (Jul-23), +425 (Sep-24), +400 (OpenAI, Jul-25), +225 (Meta, Mar-26), +450 (non-IG, May-26), +550 (Aug-26, $2.6bn DDTL 5.5, Sep-31). Term loan S+550 yields 9.15% (MS Credit 08-20).
D42: Capital raised: >$32bn of debt + equity through 2Q26 (call 08-11); WACD −300bp in 12 months (~$1.1bn/year of interest). S&P B+ positive (Apr-26). ATM registered, 'not at these prices' (Robbins 09-21).
D43: 2031 convert: 9.2764 shares per $1,000 (conv. $107.80; capped call strike 107.80 / cap 215.60 — 10-K FY25). 2032 convert: 8.3612 shares per $1,000 (conv. $119.60); capped calls cost 492m, strike 119.60 / cap 230. Management: effective strike ~$200. Both treated as debt in the model (out of the money at $77.81).
D44: Subsequent events (10-Q 2Q26 note 16): Aug-26 $2.6bn DDTL 5.5 (JPMorgan agent; SOFR+550, matures Sep-31) and a $1.2bn draw on the Revolving Credit Facility — NOT in the model's 30-Jun-26 net debt (the draw funds 2H26 capex already discounted in the FCFF).
