Workbook

Sheet Capa DCF - Base
C2: TER | DCF top-down
C3: US$ milhões, salvo ações (milhões) e WFE/TAM (US$ bilhões). Horizonte CY2023–2045; ano fiscal = ano-calendário.
C4: Azul / amarelo: premissas (aba Premissas e fontes). Verde: fontes internas. CY23–25B: bases do cenário (segmentação de 2025 difere da anterior).
D5: CY23B | E5: CY24B | F5: CY25B | G5: CY26E | H5: CY27E | I5: CY28E | J5: CY29E | K5: CY30E | L5: CY31E | M5: CY32E | N5: CY33E | O5: CY34E | P5: CY35E | Q5: CY36E | R5: CY37E | S5: CY38E | T5: CY39E | U5: CY40E | V5: CY41E | W5: CY42E | X5: CY43E | Y5: CY44E | Z5: CY45E
C7: Mercado de teste (ATE) | top-down em US$ bilhões — base Advantest (SoC + memória, ex burn-in), idêntico ao Template DCF ADVANTEST
C8: WFE global (US$ bi) | D8: ='Premissas e fontes'!D50 -> 95.76 | E8: ='Premissas e fontes'!E50 -> 100.34 | F8: ='Premissas e fontes'!F50 -> 116 | G8: ='Premissas e fontes'!G50 -> 158 | H8: ='Premissas e fontes'!H50 -> 205 | I8: ='Premissas e fontes'!I50 -> 240 | J8: =I8*(1+J9) -> 254.4 | K8: =J8*(1+K9) -> 267.12 | L8: =K8*(1+L9) -> 277.8048 | M8: =L8*(1+M9) -> 287.99098 | N8: =M8*(1+N9) -> 297.59068 | O8: =N8*(1+O9) -> 306.5184 | P8: =O8*(1+P9) -> 315.71395 | Q8: =P8*(1+Q9) -> 325.18537 | ... Z8: =Y8*(1+Z9) -> 424.29314
C9: Crescimento WFE | E9: =E8/D8-1 -> 0.047827903 | F9: =F8/E8-1 -> 0.15606936 | G9: =G8/F8-1 -> 0.36206897 | H9: =H8/G8-1 -> 0.29746835 | I9: =I8/H8-1 -> 0.17073171 | J9: ='Premissas e fontes'!J51 -> 0.06 | K9: ='Premissas e fontes'!K51 -> 0.05 | L9: ='Premissas e fontes'!L51 -> 0.04 | M9: ='Premissas e fontes'!M51 -> 0.036666667 | N9: ='Premissas e fontes'!N51 -> 0.033333333 | O9: ='Premissas e fontes'!O51 -> 0.03 | P9: ='Premissas e fontes'!P51 -> 0.03 | Q9: ='Premissas e fontes'!Q51 -> 0.03 | ... Z9: ='Premissas e fontes'!Z51 -> 0.03
C10: ATE / WFE (intensidade de teste) | D10: ='Premissas e fontes'!D52 -> 0.051169591 | E10: ='Premissas e fontes'!E52 -> 0.059796691 | F10: ='Premissas e fontes'!F52 -> 0.077586207 | G10: ='Premissas e fontes'!G52 -> 0.087025316 | H10: ='Premissas e fontes'!H52 -> 0.08 | I10: ='Premissas e fontes'!I52 -> 0.083 | J10: ='Premissas e fontes'!J52 -> 0.083 | K10: ='Premissas e fontes'!K52 -> 0.083 | ... Z10: ='Premissas e fontes'!Z52 -> 0.08
C11: TAM ATE total (US$ bi) | D11: =D8*D10 -> 4.9 | E11: =E8*E10 -> 6 | F11: =F8*F10 -> 9 | G11: =G8*G10 -> 13.75 | H11: =H8*H10 -> 16.4 | I11: =I8*I10 -> 19.92 | J11: =J8*J10 -> 21.1152 | K11: =K8*K10 -> 22.17096 | ... Z11: =Z8*Z10 -> 33.943452
C12: Crescimento TAM ATE | E12: =E11/D11-1 -> 0.2244898 | F12: =F11/E11-1 -> 0.5 | G12: =G11/F11-1 -> 0.52777778 | H12: =H11/G11-1 -> 0.19272727 | I12: =I11/H11-1 -> 0.21463415 | J12: =J11/I11-1 -> 0.06 | K12: =K11/J11-1 -> 0.05 | L12: =L11/K11-1 -> 0.03060241 | ... Z12: =Z11/Y11-1 -> 0.03
C13: TAM ATE | referência Advantest (deck 29-jul-2026; CY23 base Capstone) | D13: ='Premissas e fontes'!D28 -> 4.9 | E13: ='Premissas e fontes'!E28 -> 6 | F13: ='Premissas e fontes'!F28 -> 9 | G13: ='Premissas e fontes'!G28 -> 13.75
C14: Modelo − referência (US$ bi) | D14: =D11-D13 -> 0 | E14: =E11-E13 -> 0 | F14: =F11-F13 -> 0 | G14: =G11-G13 -> 0
C15: TAM ATE na base da iniciação TER (memo: 8,0% / 7,3% / 7,5% × WFE) | G15: =G8*0.08 -> 12.64 | H15: =H8*0.073 -> 14.965 | I15: =I8*0.075 -> 18
C17: Teradyne | share e receita (US$ milhões)
C18: Share Teradyne no TAM ATE (Semi Test ÷ TAM) | D18: =IFERROR(D19/1000/D11,NA()) -> 0.39942857 | E18: =IFERROR(E19/1000/E11,NA()) -> 0.35398333 | F18: =IFERROR(F19/1000/F11,NA()) -> 0.28041111 | G18: ='Premissas e fontes'!G53 -> 0.314 | H18: ='Premissas e fontes'!H53 -> 0.323 | I18: ='Premissas e fontes'!I53 -> 0.333 | J18: ='Premissas e fontes'!J53 -> 0.334 | K18: ='Premissas e fontes'!K53 -> 0.335 | L18: ='Premissas e fontes'!L53 -> 0.335 | M18: ='Premissas e fontes'!M53 -> 0.335 | N18: ='Premissas e fontes'!N53 -> 0.335 | ... Z18: ='Premissas e fontes'!Z53 -> 0.335
C19: Semiconductor Test | D19: ='Premissas e fontes'!D11 -> 1957.2 | E19: ='Premissas e fontes'!E11 -> 2123.9 | F19: ='Premissas e fontes'!F11 -> 2523.7 | G19: =G11*G18*1000 -> 4317.5 | H19: =H11*H18*1000 -> 5297.2 | I19: =I11*I18*1000 -> 6633.36 | J19: =J11*J18*1000 -> 7052.4768 | K19: =K11*K18*1000 -> 7427.2716 | L19: =L11*L18*1000 -> 7654.564 | M19: =M11*M18*1000 -> 7862.8736 | N19: =N11*N18*1000 -> 8050.1998 | ... Z19: =Z11*Z18*1000 -> 11371.056
C20: Product Test | D20: ='Premissas e fontes'!D12 -> 343.9 | E20: ='Premissas e fontes'!E12 -> 331.1 | F20: ='Premissas e fontes'!F12 -> 358 | G20: =F20*(1+'Premissas e fontes'!G54) -> 410 | H20: =G20*(1+'Premissas e fontes'!H54) -> 465 | I20: =H20*(1+'Premissas e fontes'!I54) -> 525 | J20: =I20*(1+'Premissas e fontes'!J54) -> 579.74395 | K20: =J20*(1+'Premissas e fontes'!K54) -> 625.84295 | L20: =K20*(1+'Premissas e fontes'!L54) -> 660.11289 | M20: =L20*(1+'Premissas e fontes'!M54) -> 679.91628 | N20: =M20*(1+'Premissas e fontes'!N54) -> 700.31377 | ... Z20: =Y20*(1+'Premissas e fontes'!Z54) -> 998.47998
C21: Robotics | D21: ='Premissas e fontes'!D13 -> 375.2 | E21: ='Premissas e fontes'!E13 -> 364.8 | F21: ='Premissas e fontes'!F13 -> 308.3 | G21: =F21*(1+'Premissas e fontes'!G55) -> 396 | H21: =G21*(1+'Premissas e fontes'!H55) -> 460 | I21: =H21*(1+'Premissas e fontes'!I55) -> 530 | J21: =I21*(1+'Premissas e fontes'!J55) -> 597.70174 | K21: =J21*(1+'Premissas e fontes'!K55) -> 659.44693 | L21: =K21*(1+'Premissas e fontes'!L55) -> 711.45722 | M21: =L21*(1+'Premissas e fontes'!M55) -> 750.18524 | N21: =M21*(1+'Premissas e fontes'!N55) -> 772.6908 | ... Z21: =Y21*(1+'Premissas e fontes'!Z55) -> 1101.6723
C22: Receita total do cenário | D22: =SUM(D19:D21) -> 2676.3 | E22: =SUM(E19:E21) -> 2819.8 | F22: =SUM(F19:F21) -> 3190 | G22: =SUM(G19:G21) -> 5123.5 | H22: =SUM(H19:H21) -> 6222.2 | I22: =SUM(I19:I21) -> 7688.36 | J22: =SUM(J19:J21) -> 8229.9225 | K22: =SUM(K19:K21) -> 8712.5615 | ... Z22: =SUM(Z19:Z21) -> 13471.209
C23: Crescimento da receita | E23: =E22/D22-1 -> 0.053618802 | F23: =F22/E22-1 -> 0.13128591 | G23: =G22/F22-1 -> 0.60611285 | H23: =H22/G22-1 -> 0.21444325 | I23: =I22/H22-1 -> 0.2356337 | J23: =J22/I22-1 -> 0.070439273 | K23: =K22/J22-1 -> 0.058644414 | L23: =L22/K22-1 -> 0.035990868 | ... Z23: =Z22/Y22-1 -> 0.03
C24: Receita total | referência (CY23-25 10-K; CY26-28 consenso BBG) | D24: ='Premissas e fontes'!D9 -> 2676.3 | E24: ='Premissas e fontes'!E9 -> 2819.9 | F24: ='Premissas e fontes'!F9 -> 3190 | G24: ='Premissas e fontes'!G9 -> 5065.9 | H24: ='Premissas e fontes'!H9 -> 6237.3 | I24: ='Premissas e fontes'!I9 -> 7543.4
C25: Cenário − referência | D25: =D22-D24 -> 0 | E25: =E22-E24 -> -0.1 | F25: =F22-F24 -> 0 | G25: =G22-G24 -> 57.6 | H25: =H22-H24 -> -15.1 | I25: =I22-I24 -> 144.96
C26: Receita total | iniciação Capstone 2026-09-16 | G26: ='Premissas e fontes'!G10 -> 5126.5 | H26: ='Premissas e fontes'!H10 -> 6219.8 | I26: ='Premissas e fontes'!I10 -> 7693.6
C27: Cenário − iniciação (%) | G27: =G22/G26-1 -> -0.00058519458 | H27: =H22/H26-1 -> 0.0003858645 | I27: =I22/I26-1 -> -0.00068108558
C29: Resultado operacional e caixa
C30: Margem bruta | D30: ='Premissas e fontes'!D56 -> 0.574 | E30: ='Premissas e fontes'!E56 -> 0.585 | F30: ='Premissas e fontes'!F56 -> 0.582 | G30: ='Premissas e fontes'!G56 -> 0.5946 | H30: ='Premissas e fontes'!H56 -> 0.5951 | I30: ='Premissas e fontes'!I56 -> 0.602 | J30: ='Premissas e fontes'!J56 -> 0.6 | K30: ='Premissas e fontes'!K56 -> 0.6 | ... Z30: ='Premissas e fontes'!Z56 -> 0.6
C31: Lucro bruto | D31: =D22*D30 -> 1536.1962 | E31: =E22*E30 -> 1649.583 | F31: =F22*F30 -> 1856.58 | G31: =G22*G30 -> 3046.4331 | H31: =H22*H30 -> 3702.8312 | I31: =I22*I30 -> 4628.3927 | J31: =J22*J30 -> 4937.9535 | K31: =K22*K30 -> 5227.5369 | ... Z31: =Z22*Z30 -> 8082.7251
C32: Opex ajustado, ex-SBC | D32: =-D22*D33 -> -943.2362 | E32: =-E22*E33 -> -997.32713 | F32: =-F22*F33 -> -1090.78 | G32: =-G22*G33 -> -1325.9618 | H32: =-H22*H33 -> -1451.6393 | I32: =-I22*I33 -> -1598.41 | J32: =-J22*J33 -> -1773.7129 | K32: =-K22*K33 -> -1944.121 | ... Z32: =-Z22*Z33 -> -3313.9173
C33: Opex ex-SBC / receita | D33: ='Premissas e fontes'!D58 -> 0.35244038 | E33: ='Premissas e fontes'!E58 -> 0.35368719 | F33: ='Premissas e fontes'!F58 -> 0.3419373 | G33: ='Premissas e fontes'!G58 -> 0.2588 | H33: ='Premissas e fontes'!H58 -> 0.2333 | I33: ='Premissas e fontes'!I58 -> 0.2079 | J33: ='Premissas e fontes'!J58 -> 0.21552 | K33: ='Premissas e fontes'!K58 -> 0.22314 | ... Z33: ='Premissas e fontes'!Z58 -> 0.246
C34: Stock-based compensation | D34: =-D22*'Premissas e fontes'!D57 -> -57.7 | E34: =-E22*'Premissas e fontes'!E57 -> -60.097869 | F34: =-F22*'Premissas e fontes'!F57 -> -64 | G34: =-G22*'Premissas e fontes'!G57 -> -71.729 | H34: =-H22*'Premissas e fontes'!H57 -> -87.1108 | I34: =-I22*'Premissas e fontes'!I57 -> -107.63704 | J34: =-J22*'Premissas e fontes'!J57 -> -115.21891 | K34: =-K22*'Premissas e fontes'!K57 -> -121.97586 | ... Z34: =-Z22*'Premissas e fontes'!Z57 -> -188.59692
C35: EBIT após SBC (= resultado operacional non-GAAP) | D35: =SUM(D31:D32,D34) -> 535.26 | E35: =SUM(E31:E32,E34) -> 592.158 | F35: =SUM(F31:F32,F34) -> 701.8 | G35: =SUM(G31:G32,G34) -> 1648.7423 | H35: =SUM(H31:H32,H34) -> 2164.0812 | I35: =SUM(I31:I32,I34) -> 2922.3456 | J35: =SUM(J31:J32,J34) -> 3049.0217 | K35: =SUM(K31:K32,K34) -> 3161.4401 | ... Z35: =SUM(Z31:Z32,Z34) -> 4580.2109
C36: Margem EBIT após SBC | D36: =D35/D22 -> 0.2 | E36: =E35/E22 -> 0.21 | F36: =F35/F22 -> 0.22 | G36: =G35/G22 -> 0.3218 | H36: =H35/H22 -> 0.3478 | I36: =I35/I22 -> 0.3801 | J36: =J35/J22 -> 0.37048 | K36: =K35/K22 -> 0.36286 | ... Z36: =Z35/Z22 -> 0.34
C37: Alíquota de imposto | D37: ='Premissas e fontes'!D59 -> 0.146 | E37: ='Premissas e fontes'!E59 -> 0.098 | F37: ='Premissas e fontes'!F59 -> 0.121 | G37: ='Premissas e fontes'!G59 -> 0.15 | H37: ='Premissas e fontes'!H59 -> 0.15 | I37: ='Premissas e fontes'!I59 -> 0.155 | J37: ='Premissas e fontes'!J59 -> 0.16 | K37: ='Premissas e fontes'!K59 -> 0.16 | ... Z37: ='Premissas e fontes'!Z59 -> 0.16
C38: NOPAT | D38: =D35*(1-D37) -> 457.11204 | E38: =E35*(1-E37) -> 534.12652 | F38: =F35*(1-F37) -> 616.8822 | G38: =G35*(1-G37) -> 1401.431 | H38: =H35*(1-H37) -> 1839.469 | I38: =I35*(1-I37) -> 2469.3821 | J38: =J35*(1-J37) -> 2561.1782 | K38: =K35*(1-K37) -> 2655.6096 | ... Z38: =Z35*(1-Z37) -> 3847.3772
C39: Depreciação operacional | D39: =D22*'Premissas e fontes'!D60 -> 92.1 | E39: =E22*'Premissas e fontes'!E60 -> 100.99642 | F39: =F22*'Premissas e fontes'!F60 -> 111.4 | G39: =G22*'Premissas e fontes'!G60 -> 122.964 | H39: =H22*'Premissas e fontes'!H60 -> 149.3328 | I39: =I22*'Premissas e fontes'!I60 -> 184.52064 | J39: =J22*'Premissas e fontes'!J60 -> 197.51814 | K39: =K22*'Premissas e fontes'!K60 -> 209.10148 | ... Z39: =Z22*'Premissas e fontes'!Z60 -> 323.30901
C40: Capex | D40: =-D22*'Premissas e fontes'!D61 -> -159.6 | E40: =-E22*'Premissas e fontes'!E61 -> -198.09297 | F40: =-F22*'Premissas e fontes'!F61 -> -224 | G40: =-G22*'Premissas e fontes'!G61 -> -353.5215 | H40: =-H22*'Premissas e fontes'!H61 -> -379.5542 | I40: =-I22*'Premissas e fontes'!I61 -> -430.54816 | J40: =-J22*'Premissas e fontes'!J61 -> -411.49612 | K40: =-K22*'Premissas e fontes'!K61 -> -435.62807 | ... Z40: =-Z22*'Premissas e fontes'!Z61 -> -673.56043
C41: Capital de giro operacional (NWC) | F41: =F22*'Premissas e fontes'!F62 -> 897.3 | G41: =G22*'Premissas e fontes'!G62 -> 1280.875 | H41: =H22*'Premissas e fontes'!H62 -> 1555.55 | I41: =I22*'Premissas e fontes'!I62 -> 1922.09 | J41: =J22*'Premissas e fontes'!J62 -> 2057.4806 | K41: =K22*'Premissas e fontes'!K62 -> 2178.1404 | L41: =L22*'Premissas e fontes'!L62 -> 2256.5335 | M41: =M22*'Premissas e fontes'!M62 -> 2323.2438 | ... Z41: =Z22*'Premissas e fontes'!Z62 -> 3367.8021
C42: Variação de NWC | efeito caixa | G42: =-(G41-F41) -> -383.575 | H42: =-(H41-G41) -> -274.675 | I42: =-(I41-H41) -> -366.54 | J42: =-(J41-I41) -> -135.39062 | K42: =-(K41-J41) -> -120.65975 | L42: =-(L41-K41) -> -78.393162 | M42: =-(M41-L41) -> -66.710255 | N42: =-(N41-M41) -> -57.557294 | ... Z42: =-(Z41-Y41) -> -98.091325
C43: Fluxo de caixa livre (FCFF) | G43: =SUM(G38:G40,G42) -> 787.29846 | H43: =SUM(H38:H40,H42) -> 1334.5726 | I43: =SUM(I38:I40,I42) -> 1856.8145 | J43: =SUM(J38:J40,J42) -> 2211.8096 | K43: =SUM(K38:K40,K42) -> 2308.4233 | L43: =SUM(L38:L40,L42) -> 2380.3402 | M43: =SUM(M38:M40,M42) -> 2405.2286 | N43: =SUM(N38:N40,N42) -> 2414.6665 | ... Z43: =SUM(Z38:Z40,Z42) -> 3399.0344
C44: FCFF / receita | G44: =G43/G22 -> 0.15366419 | H44: =H43/H22 -> 0.21448565 | I44: =I43/I22 -> 0.24150983 | J44: =J43/J22 -> 0.26875218 | K44: =K43/K22 -> 0.26495346 | L44: =L43/L22 -> 0.26371647 | M44: =M43/M22 -> 0.25882223 | N44: =N43/N22 -> 0.2535561 | ... Z44: =Z43/Z22 -> 0.25231845
...

Sheet Premissas e fontes
C2: TER | Premissas e fontes
C3: Dados extraídos das fontes indicadas. US$ milhões salvo indicação; TAM/WFE em US$ bilhões. Ano fiscal = ano-calendário (dez).
D5: 2023 | E5: 2024 | F5: 2025 | G5: 2026 | H5: 2027 | I5: 2028
L6: Arquivo, aba e células de origem. CY = ano-calendário.
C8: Histórico reportado (10-K) e referência de consenso / iniciação
C9: Receita total (US$ mi) | 10-K / consenso BBG CY26-28 | D9: 2676.3 | E9: 2819.9 | F9: 3190 | G9: 5065.9 | H9: 6237.3 | I9: 7543.4 | L9: 10-K FY23-FY25 (TER/TER_10-K_2026-02-19: 3.190.024; 2.819.880; 2.676.298). CY26-28: bdp BEST_SALES 1FY/2FY/3FY (2026-09-18).
C10: Receita total | iniciação Capstone 2026-09-16 (base) | G10: 5126.5 | H10: 6219.8 | I10: 7693.6 | L10: _wiki/_data/research/TER_Initiation_2026-09-16_model_out.json → cases.base.periods (ter_model.py). Substituído por este workbook.
C11: Semiconductor Test (US$ mi) | segmento | D11: 1957.2 | E11: 2123.9 | F11: 2523.7 | L11: 10-K FY25 (filed 2026-02-19), segment note restated to the 2025 segmentation: Semiconductor Test 1.957,2 / 2.123,9 / 2.523,7 (inclui IST; 2025 IST 129,2).
C12: Product Test (US$ mi) | System Test + Wireless | D12: 343.9 | E12: 331.1 | F12: 358 | L12: 10-K FY25 restated: Product Test 343,9 / 331,1 / 358,0 (System Test + Wireless Test ex-IST).
C13: Robotics (US$ mi) | D13: 375.2 | E13: 364.8 | F13: 308.3 | L13: 10-K FY25 restated: Robotics 375,2 / 364,8 / 308,3.
C14: Margem bruta (non-GAAP) | D14: 0.574 | E14: 0.585 | F14: 0.582 | L14: 10-K FY24/FY25 (gross profit 57,4% / 58,5% / 58,2%).
C15: Margem operacional non-GAAP | D15: 0.2 | E15: 0.21 | F15: 0.22 | L15: Wiki TER.md tabela de casa (~21% / ~22%); FY23 ~20% (aprox., base do cenário).
C16: Stock-based compensation (US$ mi) | D16: 57.7 | E16: 60.1 | F16: 64 | L16: 10-K cash-flow: 57.682 / 60.122 / 63.999.
C17: Depreciação (US$ mi) | D17: 92.1 | E17: 101 | F17: 111.4 | L17: 10-K cash-flow: 92.118 / 100.977 / 111.445.
C18: Capex (US$ mi) | 10-K / consenso BBG CY26-28 | D18: 159.6 | E18: 198.1 | F18: 224 | G18: 281.9 | H18: 352.6 | I18: 429.4 | L18: 10-K purchases of PP&E: 159.642 / 198.095 / 224.009; CY26-28 bdp BEST_CAPEX.
C19: Contas a receber (US$ mi) | dez-23 / dez-24 / dez-25 / jun-26 | D19: 422.1 | E19: 471.4 | F19: 786.9 | G19: 1109.7 | L19: 10-K FY24/FY25; 10-Q 2Q FY26 (2026-06-28).
C20: Estoques (US$ mi) | D20: 310 | E20: 298.5 | F20: 379.6 | G20: 403.3 | L20: 10-K FY24/FY25; 10-Q 2Q FY26.
C21: Contas a pagar (US$ mi) | D21: 180.1 | E21: 134.8 | F21: 269.2 | G21: 383.4 | L21: 10-K FY24/FY25; 10-Q 2Q FY26.
C22: EPS non-GAAP (US$) | reportado / consenso BBG CY26-28 | D22: 2.93 | E22: 3.22 | F22: 3.97 | G22: 8.838 | H22: 11.453 | I22: 14.769 | L22: FY23-25 releases (wiki TER.md); CY26-28 bdp BEST_EPS 1FY/2FY/3FY (2026-09-18).
C23: EPS non-GAAP | iniciação Capstone 2026-09-16 (base) | G23: 9.03 | H23: 11.92 | I23: 15.99 | L23: model_out.json cases.base.periods.eps: 9,026 / 11,921 / 15,992.
C24: Consenso BBG — EBIT (US$ mi) | G24: 1655.7 | H24: 2143.5 | I24: 2724.3 | L24: bdp BEST_EBIT 1FY/2FY/3FY. 19 analistas (13 buy / 6 hold), rating 4,32, PT médio $450,87.
C25: Consenso BBG — margem bruta | G25: 0.5936 | H25: 0.5951 | I25: 0.5971 | L25: bdp BEST_GROSS_MARGIN.
C26: Advantest test systems SoC + memória (US$ mi) | modelo oficial ADVANTEST — check de shares | D26: 2702.8 | E26: 3450.6 | F26: 5616 | G26: 8855 | H26: 10758.4 | I26: 13023.7 | L26: Template DCF ADVANTEST.xlsx | Capa DCF - Base linhas 24+25 (CY23-25 implícito; CY26-28 cenário base). Valores colados — atualizar se o modelo Advantest mudar.
C27: IST (storage test) dentro de Semi Test (US$ mi) | excluído do check de shares | F27: 129.2 | G27: 230 | H27: 245 | I27: 290 | L27: CY25 10-K FY25 (IST 129,2); CY26-28 sub-segmentação da iniciação (model_out.json subseg). IST não está no TAM SoC+memória da Advantest.
C28: TAM ATE (US$ bi) | referência Advantest (deck 29-jul-2026; CY23 base Capstone) | D28: 4.9 | E28: 6 | F28: 9 | G28: 13.75 | L28: CY24 6,0 / CY25 9,0 / CY26e 13,75 (mid 13,0-14,5) — deck Advantest; validado pelo CEO da TER ('right zip code', call 2026-07-29). Base ex burn-in. CY23 4,9 = Industry Assumptions!K26.
C30: Guidance 3Q FY26 (28-jul-2026) e âncoras da iniciação
C31: 3Q FY26 receita guidance (US$ mi, ponto médio $1.250) | D31: 1250 | F31: Press release 2026-07-28: $1,15-1,25 bi… revisado: $1.250 mi ±; H1 = 50-52% da receita do ano → FY26 $5,02-5,22 bi.
C32: 1H FY26 receita reportada (US$ mi) | D32: 2611.5 | F32: 1Q 1.282,5 + 2Q 1.329,0 (releases 2026-04-29 / 2026-07-28).
C33: 1H FY26 EPS non-GAAP reportado (US$) | D33: 5.02 | F33: Idem (2,56 + 2,47; companhia: $5,02).
C35: Valuation e balanço
C36: Data de valuation | D36: 46261 | F36: Template DCF NVDA.xlsx | Audit & Checks!D5. Mantida a data para comparabilidade com AMD/AVGO.
C37: WACC | D37: 0.1 | F37: Hipótese: 10% do template aplicado como WACC no FCFF (iniciação usou Ke 10% / g 3% com fade de margem a 30% → $212 rolado).
C38: Crescimento terminal | D38: 0.02 | F38: Template DCF NVDA.xlsx | Capa DCF - Base!D91.
C39: ROIC incremental terminal | D39: 0.2 | F39: Hipótese do template: reinvestimento terminal = g / ROIC.
C40: Ações diluídas | referência 2Q FY26 (mi) | D40: 157.7 | F40: 10-Q 2Q FY26: weighted diluted 157.693 mil; em circulação 156,34 mi (27-jul-2026).
C41: Caixa + títulos (US$ mi) | D41: 517.1 | F41: 10-Q 2Q FY26 (28-jun-2026): caixa 349,5 + títulos CP 5,3 + títulos LP 162,3.
C42: Participação Technoprobe (equity method, US$ mi) | D42: 515 | F42: 10-Q 2Q FY26: equity method investment 514.957 (10% da Technoprobe). Ativo não operacional somado ao equity.
C43: Dívida financeira bruta (US$ mi) | D43: 0 | F43: Sem dívida em 28-jun-2026 (revolver $750 mi disponível; $200 mi de dez-25 quitados no 1H).
C44: Data-base do balanço no modelo | D44: 46201 | F44: Anterior à data de valuation; atualização manual disponível.
C45: Preço de referência (US$, informativo) | D45: 363.05 | F45: BBG PX_LAST TER US, 2026-09-18. Não entra no valuation.
...
