Workbook

Sheet Monitor
A1: AI data center credit: live monitor
A2: Layout follows the Barclays IG/HY Data Center Comp Sheets (16-Sep-2026). Blue cells are live Bloomberg formulas. Principal vs par = (live price - 100) / 100 x amount outstanding; negative = below par.
A4: Company / description | B4: Ticker | C4: Tenant | D4: Data center location | E4: Critical IT (MW) | F4: Rating (Moody's / S&P / Fitch) | G4: Amt o/s ($mn) | H4: LIVE price | I4: Chg % 1D | J4: LIVE yield % | K4: Last trade size (TRACE) | L4: Price time | M4: Principal vs par ($mn) | N4: Principal vs par (%) | O4: Today's change in value ($mn) | P4: Since 15-Sep ($mn) | Q4: Δ yield since 15-Sep (bp) | R4: Barclays rec | S4: First issued | T4: LIVE spread (bp, OAS) | U4: Tenant comparable bond | V4: Comp LIVE spread (bp, OAS) | W4: LIVE pickup vs comp (bp) | X4: Pickup 15-Sep (bp, Barclays) | Y4: Δ pickup since 15-Sep (bp) | Z4: Bloomberg ticker (terminal)
A5: Investment Grade HPC Data Center Builders
A6: Hut 8 (Beacon Point DC LLC) 6.129% Sec Notes due 11/30/2042 | B6: HUTBPA | C6: NVIDIA | D6: Nueces County, TX | E6: 352 | F6: Baa2/NR/NR | G6: 4250 | H6: =_xll.BDP($Z6,"LAST_PRICE") -> 92.424 | I6: =_xll.BDP($Z6,"CHG_PCT_1D") -> -0.034323654 | J6: =_xll.BDP($Z6,"YLD_YTM_MID") -> 6.9070348 | K6: =IFERROR(_xll.BDP($Z6,"TRACE_LAST_TRADE_SIZE"),"n/a") -> 11 | L6: =IFERROR(_xll.BDP($Z6,"PRICE_LAST_TIME"),"") -> 16:44:24 | M6: =IF(AND(ISNUMBER(H6),ISNUMBER(G6)),(H6-100)/100*G6,"") -> -321.98 | N6: =IF(ISNUMBER(H6),(H6-100)/100,"") -> -0.07576 | O6: =IFERROR((H6-_xll.BDP($Z6,"PX_CLOSE_1D"))/100*G6,"") -> -4.5475 | P6: =IF(ISNUMBER(H6),(H6-93.65)/100*G6,"") -> -52.105 | Q6: =IF(ISNUMBER(J6),(J6-6.99)*100,"") -> -8.2965174 | S6: 46182 | T6: =_xll.BDP($Z6,"OAS_SPREAD_MID") -> 195.27657 | U6: NVDA 4.95% 2036 | V6: =_xll.BDP("NVDA 4.95 06/15/36 Corp","OAS_SPREAD_MID") -> 80.51352 | W6: =IF(AND(ISNUMBER(T6),ISNUMBER(V6)),T6-V6,"") -> 114.76306 | X6: 125 | Y6: =IF(ISNUMBER(W6),W6-X6,"") -> -10.236945 | Z6: HUTBPA 6.129 11/30/42 144A Corp
A7: Hut 8 (Hut 8 DC LLC) 6.192% Sec Notes due 11/15/2042 | B7: HUTRBA | C7: Fluidstack (Google backstop) | D7: St. Francisville, LA | E7: 245 | F7: NR/BBB-/BBB- | G7: 3250 | H7: =_xll.BDP($Z7,"LAST_PRICE") -> 93.919 | I7: =_xll.BDP($Z7,"CHG_PCT_1D") -> -0.43961784 | J7: =_xll.BDP($Z7,"YLD_YTM_MID") -> 6.8227402 | K7: =IFERROR(_xll.BDP($Z7,"TRACE_LAST_TRADE_SIZE"),"n/a") -> 5MM+ | L7: =IFERROR(_xll.BDP($Z7,"PRICE_LAST_TIME"),"") -> 16:44:24 | M7: =IF(AND(ISNUMBER(H7),ISNUMBER(G7)),(H7-100)/100*G7,"") -> -197.6325 | N7: =IF(ISNUMBER(H7),(H7-100)/100,"") -> -0.06081 | O7: =IFERROR((H7-_xll.BDP($Z7,"PX_CLOSE_1D"))/100*G7,"") -> -12.61 | P7: =IF(ISNUMBER(H7),(H7-96.15)/100*G7,"") -> -72.5075 | Q7: =IF(ISNUMBER(J7),(J7-6.74)*100,"") -> 8.2740175 | S7: 46142 | T7: =_xll.BDP($Z7,"OAS_SPREAD_MID") -> 188.37732 | U7: GOOGL 4.8% 2036 | V7: =_xll.BDP("US02079KBM80 Corp","OAS_SPREAD_MID") -> 68.481578 | W7: =IF(AND(ISNUMBER(T7),ISNUMBER(V7)),T7-V7,"") -> 119.89574 | X7: 110 | Y7: =IF(ISNUMBER(W7),W7-X7,"") -> 9.8957419 | Z7: HUTRBA 6.192 11/15/42 144A Corp
A8: BlueOwl/Meta JV (Beignet Investor LLC) 6.581% Sec Notes due 5/30/2049 | B8: RPLDCI | C8: Meta | D8: Richland Parish, LA | E8: 2064 | F8: NR/A+/NR | G8: 27293.8 | H8: =_xll.BDP($Z8,"LAST_PRICE") -> 91.908 | I8: =_xll.BDP($Z8,"CHG_PCT_1D") -> -0.50901119 | J8: =_xll.BDP($Z8,"YLD_YTM_MID") -> 7.4801614 | K8: =IFERROR(_xll.BDP($Z8,"TRACE_LAST_TRADE_SIZE"),"n/a") -> 5MM+ | L8: =IFERROR(_xll.BDP($Z8,"PRICE_LAST_TIME"),"") -> 16:44:24 | M8: =IF(AND(ISNUMBER(H8),ISNUMBER(G8)),(H8-100)/100*G8,"") -> -2208.6143 | N8: =IF(ISNUMBER(H8),(H8-100)/100,"") -> -0.08092 | O8: =IFERROR((H8-_xll.BDP($Z8,"PX_CLOSE_1D"))/100*G8,"") -> -139.19838 | P8: =IF(ISNUMBER(H8),(H8-94.73)/100*G8,"") -> -770.23104 | Q8: =IF(ISNUMBER(J8),(J8-7.15)*100,"") -> 33.016135 | R8: OW | S8: 45951 | T8: =_xll.BDP($Z8,"OAS_SPREAD_MID") -> 222.60592 | U8: META 5.25% 2036 | V8: =_xll.BDP("US30303MAH51 Corp","OAS_SPREAD_MID") -> 107.58046 | W8: =IF(AND(ISNUMBER(T8),ISNUMBER(V8)),T8-V8,"") -> 115.02546 | X8: 111 | Y8: =IF(ISNUMBER(W8),W8-X8,"") -> 4.0254617 | Z8: RPLDCI 6.581 05/30/49 144A Corp
A9: Blackrock/Meta JV (Sopapilla Investor LLC) 7.534% Sec Notes due 11/30/2048 | B9: TXEDCI | C9: Meta | D9: El Paso, TX | E9: 960 | F9: NR/A+/AA- | G9: 12639.5 | H9: =_xll.BDP($Z9,"LAST_PRICE") -> 98.999 | I9: =_xll.BDP($Z9,"CHG_PCT_1D") -> -0.33711873 | J9: =_xll.BDP($Z9,"YLD_YTM_MID") -> 7.6225604 | K9: =IFERROR(_xll.BDP($Z9,"TRACE_LAST_TRADE_SIZE"),"n/a") -> 175 | L9: =IFERROR(_xll.BDP($Z9,"PRICE_LAST_TIME"),"") -> 16:44:24 | M9: =IF(AND(ISNUMBER(H9),ISNUMBER(G9)),(H9-100)/100*G9,"") -> -126.5214 | N9: =IF(ISNUMBER(H9),(H9-100)/100,"") -> -0.01001 | O9: =IFERROR((H9-_xll.BDP($Z9,"PX_CLOSE_1D"))/100*G9,"") -> -70.27562 | P9: =IF(ISNUMBER(H9),(H9-103.65)/100*G9,"") -> -587.86315 | Q9: =IF(ISNUMBER(J9),(J9-7.22)*100,"") -> 40.256044 | R9: OW | S9: 46233 | T9: =_xll.BDP($Z9,"OAS_SPREAD_MID") -> 238.0114 | U9: META 5.25% 2036 | V9: =_xll.BDP("US30303MAH51 Corp","OAS_SPREAD_MID") -> 107.58046 | W9: =IF(AND(ISNUMBER(T9),ISNUMBER(V9)),T9-V9,"") -> 130.43094 | X9: 128 | Y9: =IF(ISNUMBER(W9),W9-X9,"") -> 2.4309429 | Z9: TXEDCI 7.534 11/30/48 144A Corp
A10: Related Digital (RD Michigan Pro Owner I) 7.50% Sec Notes due 3/30/2045 | B10: RDMICH | C10: Oracle | D10: Saline, MI | E10: 974 | F10: Baa3/NR/BBB | G10: 14000 | H10: =_xll.BDP($Z10,"LAST_PRICE") -> 87.247 | I10: =_xll.BDP($Z10,"CHG_PCT_1D") -> -1.3388337 | J10: =_xll.BDP($Z10,"YLD_YTM_MID") -> 8.9678816 | K10: =IFERROR(_xll.BDP($Z10,"TRACE_LAST_TRADE_SIZE"),"n/a") -> 5000 | L10: =IFERROR(_xll.BDP($Z10,"PRICE_LAST_TIME"),"") -> 16:44:24 | M10: =IF(AND(ISNUMBER(H10),ISNUMBER(G10)),(H10-100)/100*G10,"") -> -1785.42 | N10: =IF(ISNUMBER(H10),(H10-100)/100,"") -> -0.12753 | O10: =IFERROR((H10-_xll.BDP($Z10,"PX_CLOSE_1D"))/100*G10,"") -> -104.58 | P10: =IF(ISNUMBER(H10),(H10-94.25)/100*G10,"") -> -980.42 | Q10: =IF(ISNUMBER(J10),(J10-8.21)*100,"") -> 75.788156 | S10: 46142 | T10: =_xll.BDP($Z10,"OAS_SPREAD_MID") -> 400.12212 | U10: ORCL 3.6% 2040 | V10: =_xll.BDP("US68389XBW48 Corp","OAS_SPREAD_MID") -> 275.0577 | W10: =IF(AND(ISNUMBER(T10),ISNUMBER(V10)),T10-V10,"") -> 125.06442 | X10: 71 | Y10: =IF(ISNUMBER(W10),W10-X10,"") -> 54.064421 | Z10: RDMICH 7.5 03/30/45 144A Corp
A11: QTS (QTS Central Issuer LLC) 6.625% Sec Notes due 9/1/2031 (5NC2) | B11: QTSODY | C11: Microsoft | D11: Atlanta, GA | E11: 204 | F11: Baa3/NR/NR | G11: 3900 | H11: =_xll.BDP($Z11,"LAST_PRICE") -> 97.166 | I11: =_xll.BDP($Z11,"CHG_PCT_1D") -> 0.15399598 | J11: =_xll.BDP($Z11,"YLD_YTM_MID") -> 7.3295727 | K11: =IFERROR(_xll.BDP($Z11,"TRACE_LAST_TRADE_SIZE"),"n/a") -> 400 | L11: =IFERROR(_xll.BDP($Z11,"PRICE_LAST_TIME"),"") -> 16:44:24 | M11: =IF(AND(ISNUMBER(H11),ISNUMBER(G11)),(H11-100)/100*G11,"") -> -110.526 | N11: =IF(ISNUMBER(H11),(H11-100)/100,"") -> -0.02834 | O11: =IFERROR((H11-_xll.BDP($Z11,"PX_CLOSE_1D"))/100*G11,"") -> 6.63 | P11: =IF(ISNUMBER(H11),(H11-98.88)/100*G11,"") -> -66.846 | Q11: =IF(ISNUMBER(J11),(J11-6.9)*100,"") -> 42.957271 | S11: 46261 | T11: =_xll.BDP($Z11,"OAS_SPREAD_MID") -> 222.09584 | U11: MSFT 3.45% 2036 | V11: =_xll.BDP("US594918BS26 Corp","OAS_SPREAD_MID") -> 29.725185 | W11: =IF(AND(ISNUMBER(T11),ISNUMBER(V11)),T11-V11,"") -> 192.37065 | X11: 145 | Y11: =IF(ISNUMBER(W11),W11-X11,"") -> 47.370653 | Z11: QTSODY 6.625 09/01/31 144A Corp
A12: QTS (QTS Fayetteville Dc1-2 LLC) 5.70% Sec Notes due 4/15/2036 | B12: QTSQST | C12: Microsoft | D12: Atlanta, GA | E12: 340 | F12: Baa2/NR/NR | G12: 4600 | H12: =_xll.BDP($Z12,"LAST_PRICE") -> 87.991 | I12: =_xll.BDP($Z12,"CHG_PCT_1D") -> -0.034385601 | J12: =_xll.BDP($Z12,"YLD_YTM_MID") -> 7.5219323 | K12: =IFERROR(_xll.BDP($Z12,"TRACE_LAST_TRADE_SIZE"),"n/a") -> 96 | L12: =IFERROR(_xll.BDP($Z12,"PRICE_LAST_TIME"),"") -> 16:44:24 | M12: =IF(AND(ISNUMBER(H12),ISNUMBER(G12)),(H12-100)/100*G12,"") -> -552.414 | N12: =IF(ISNUMBER(H12),(H12-100)/100,"") -> -0.12009 | O12: =IFERROR((H12-_xll.BDP($Z12,"PX_CLOSE_1D"))/100*G12,"") -> 7.544 | P12: =IF(ISNUMBER(H12),(H12-89.96)/100*G12,"") -> -90.574 | Q12: =IF(ISNUMBER(J12),(J12-7.17)*100,"") -> 35.193235 | S12: 46127 | T12: =_xll.BDP($Z12,"OAS_SPREAD_MID") -> 244.8938 | U12: MSFT 3.45% 2036 | V12: =_xll.BDP("US594918BS26 Corp","OAS_SPREAD_MID") -> 29.725185 | W12: =IF(AND(ISNUMBER(T12),ISNUMBER(V12)),T12-V12,"") -> 215.16862 | X12: 189 | Y12: =IF(ISNUMBER(W12),W12-X12,"") -> 26.168619 | Z12: QTSQST 5.7 04/15/36 144A Corp
A13: IG total | G13: =SUM(G6:G12) -> 69933.3 | H13: =IFERROR(SUMPRODUCT(H6:H12,G6:G12)/SUM(G6:G12),"") -> 92.416906 | M13: =IFERROR(SUM(M6:M12),"") -> -5303.1082 | N13: =IFERROR(M13/G13,"") -> -0.075830944 | O13: =IFERROR(SUM(O6:O12),"") -> -317.0375 | P13: =IFERROR(SUM(P6:P12),"") -> -2620.5467
A14: High Yield HPC Data Center Builders
A15: Applied Digital (APLD ComputeCo LLC) 9 1/4% Sec Notes due 12/15/2030 | B15: APLD | C15: CoreWeave | D15: Ellendale, ND | E15: 250 | F15: NR/BB-/BB- | G15: 2350 | H15: =_xll.BDP($Z15,"LAST_PRICE") -> 102.776 | I15: =_xll.BDP($Z15,"CHG_PCT_1D") -> -0.69392549 | J15: =_xll.BDP($Z15,"YLD_YTM_MID") -> 8.4534708 | K15: =IFERROR(_xll.BDP($Z15,"TRACE_LAST_TRADE_SIZE"),"n/a") -> 1MM+ | L15: =IFERROR(_xll.BDP($Z15,"PRICE_LAST_TIME"),"") -> 16:44:24 | M15: =IF(AND(ISNUMBER(H15),ISNUMBER(G15)),(H15-100)/100*G15,"") -> 65.236 | N15: =IF(ISNUMBER(H15),(H15-100)/100,"") -> 0.02776 | O15: =IFERROR((H15-_xll.BDP($Z15,"PX_CLOSE_1D"))/100*G15,"") -> -15.6275 | P15: =IF(ISNUMBER(H15),(H15-105.29)/100*G15,"") -> -59.079 | Q15: =IF(ISNUMBER(J15),(J15-7.6)*100,"") -> 85.347083 | R15: MW | S15: 45981 | T15: =_xll.BDP($Z15,"OAS_SPREAD_MID") -> 324.69677 | U15: CRWV 9% 2031 | V15: =_xll.BDP("CRWV 9 02/01/2031 144A Corp","OAS_SPREAD_MID") -> 1050.1994 | W15: =IF(AND(ISNUMBER(T15),ISNUMBER(V15)),T15-V15,"") -> -725.50259 | X15: -434 | Y15: =IF(ISNUMBER(W15),W15-X15,"") -> -291.50259 | Z15: APLD 9.25 12/15/30 144A Corp
A16: Applied Digital (APLD ComputeCo 2 LLC) 6 3/4% Sec Notes due 3/15/2031 | B16: PFORGE | C16: Oracle | D16: Harwood, ND | E16: 200 | F16: Ba3/NR/BB- | G16: 2150 | H16: =_xll.BDP($Z16,"LAST_PRICE") -> 95.153 | I16: =_xll.BDP($Z16,"CHG_PCT_1D") -> -0.52129588 | J16: =_xll.BDP($Z16,"YLD_YTM_MID") -> 8.1104983 | K16: =IFERROR(_xll.BDP($Z16,"TRACE_LAST_TRADE_SIZE"),"n/a") -> 50 | L16: =IFERROR(_xll.BDP($Z16,"PRICE_LAST_TIME"),"") -> 16:44:24 | M16: =IF(AND(ISNUMBER(H16),ISNUMBER(G16)),(H16-100)/100*G16,"") -> -104.2105 | N16: =IF(ISNUMBER(H16),(H16-100)/100,"") -> -0.04847 | O16: =IFERROR((H16-_xll.BDP($Z16,"PX_CLOSE_1D"))/100*G16,"") -> -8.127 | P16: =IF(ISNUMBER(H16),(H16-96)/100*G16,"") -> -18.2105 | Q16: =IF(ISNUMBER(J16),(J16-7.93)*100,"") -> 18.049834 | R16: MW | S16: 46091 | T16: =_xll.BDP($Z16,"OAS_SPREAD_MID") -> 339.02994 | U16: ORCL 4.95% 2031 | V16: =_xll.BDP("US68389XDX03 Corp","OAS_SPREAD_MID") -> 225.91147 | W16: =IF(AND(ISNUMBER(T16),ISNUMBER(V16)),T16-V16,"") -> 113.11846 | X16: 167 | Y16: =IF(ISNUMBER(W16),W16-X16,"") -> -53.881536 | Z16: PFORGE 6.75 03/15/31 144A Corp
A17: Applied Digital (APLD ComputeCo 3 LLC) 7% Sec Notes due 6/15/2031 | B17: ELNFOR | C17: CoreWeave | D17: Ellendale, ND | E17: 150 | F17: NR/BB-/BB- | G17: 1590 | H17: =_xll.BDP($Z17,"LAST_PRICE") -> 92.836 | I17: =_xll.BDP($Z17,"CHG_PCT_1D") -> -0.64598564 | J17: =_xll.BDP($Z17,"YLD_YTM_MID") -> 8.831383 | K17: =IFERROR(_xll.BDP($Z17,"TRACE_LAST_TRADE_SIZE"),"n/a") -> 254 | L17: =IFERROR(_xll.BDP($Z17,"PRICE_LAST_TIME"),"") -> 16:44:24 | M17: =IF(AND(ISNUMBER(H17),ISNUMBER(G17)),(H17-100)/100*G17,"") -> -113.9076 | N17: =IF(ISNUMBER(H17),(H17-100)/100,"") -> -0.07164 | O17: =IFERROR((H17-_xll.BDP($Z17,"PX_CLOSE_1D"))/100*G17,"") -> -14.0556 | P17: =IF(ISNUMBER(H17),(H17-95.75)/100*G17,"") -> -46.3326 | Q17: =IF(ISNUMBER(J17),(J17-8.19)*100,"") -> 64.138297 | R17: OW | S17: 46189 | T17: =_xll.BDP($Z17,"OAS_SPREAD_MID") -> 408.84269 | U17: CRWV 9% 2031 | V17: =_xll.BDP("CRWV 9 02/01/2031 144A Corp","OAS_SPREAD_MID") -> 1050.1994 | W17: =IF(AND(ISNUMBER(T17),ISNUMBER(V17)),T17-V17,"") -> -641.35667 | X17: -332 | Y17: =IF(ISNUMBER(W17),W17-X17,"") -> -309.35667 | Z17: ELNFOR 7 06/15/31 144A Corp
A18: Cipher Digital (Cipher Compute LLC) 7 1/8% Sec Notes due 11/15/2030 | B18: CIFR | C18: Fluidstack (Google backstop) | D18: Colorado City, TX | E18: 207 | F18: Ba3/NR/BB- | G18: 1733 | H18: =_xll.BDP($Z18,"LAST_PRICE") -> 99.088 | I18: =_xll.BDP($Z18,"CHG_PCT_1D") -> -0.28045974 | J18: =_xll.BDP($Z18,"YLD_YTM_MID") -> 7.3958154 | K18: =IFERROR(_xll.BDP($Z18,"TRACE_LAST_TRADE_SIZE"),"n/a") -> 535 | L18: =IFERROR(_xll.BDP($Z18,"PRICE_LAST_TIME"),"") -> 16:44:24 | M18: =IF(AND(ISNUMBER(H18),ISNUMBER(G18)),(H18-100)/100*G18,"") -> -15.80496 | N18: =IF(ISNUMBER(H18),(H18-100)/100,"") -> -0.00912 | O18: =IFERROR((H18-_xll.BDP($Z18,"PX_CLOSE_1D"))/100*G18,"") -> -4.24585 | P18: =IF(ISNUMBER(H18),(H18-101.5)/100*G18,"") -> -41.79996 | Q18: =IF(ISNUMBER(J18),(J18-6.72)*100,"") -> 67.581538 | R18: MW | S18: 45974 | T18: =_xll.BDP($Z18,"OAS_SPREAD_MID") -> 238.72623 | U18: GOOGL 4.1% 2031 | V18: =_xll.BDP("US02079KBK25 Corp","OAS_SPREAD_MID") -> 41.152337 | W18: =IF(AND(ISNUMBER(T18),ISNUMBER(V18)),T18-V18,"") -> 197.57389 | X18: 127 | Y18: =IF(ISNUMBER(W18),W18-X18,"") -> 70.57389 | Z18: CIFR 7.125 11/15/30 144A Corp
A19: Cipher Digital (Black Pearl Compute LLC) 6 1/8% Sec Notes due 2/15/2031 | B19: BLKPRL | C19: Amazon | D19: Wink, TX | E19: 216 | F19: Ba2/NR/BB- | G19: 2000 | H19: =_xll.BDP($Z19,"LAST_PRICE") -> 98.352 | I19: =_xll.BDP($Z19,"CHG_PCT_1D") -> -0.29605155 | J19: =_xll.BDP($Z19,"YLD_YTM_MID") -> 6.5859493 | K19: =IFERROR(_xll.BDP($Z19,"TRACE_LAST_TRADE_SIZE"),"n/a") -> 8 | L19: =IFERROR(_xll.BDP($Z19,"PRICE_LAST_TIME"),"") -> 16:44:24 | M19: =IF(AND(ISNUMBER(H19),ISNUMBER(G19)),(H19-100)/100*G19,"") -> -32.96 | N19: =IF(ISNUMBER(H19),(H19-100)/100,"") -> -0.01648 | O19: =IFERROR((H19-_xll.BDP($Z19,"PX_CLOSE_1D"))/100*G19,"") -> -4.38 | P19: =IF(ISNUMBER(H19),(H19-99.75)/100*G19,"") -> -27.96 | Q19: =IF(ISNUMBER(J19),(J19-6.22)*100,"") -> 36.594926 | R19: MW | S19: 46064 | T19: =_xll.BDP($Z19,"OAS_SPREAD_MID") -> 158.72643 | U19: AMZN 4.25% 2031 | V19: =_xll.BDP("US023135DD51 Corp","OAS_SPREAD_MID") -> 52.588859 | W19: =IF(AND(ISNUMBER(T19),ISNUMBER(V19)),T19-V19,"") -> 106.13757 | X19: 77 | Y19: =IF(ISNUMBER(W19),W19-X19,"") -> 29.137574 | Z19: BLKPRL 6.125 02/15/31 144A Corp
A20: Cipher Digital (Stingray Compute LLC) 6% Sec Notes due 6/15/2031 | B20: STNGRY | C20: Amazon | D20: Andrews, TX | E20: 70 | F20: Ba2/NR/BB- | G20: 810 | H20: =_xll.BDP($Z20,"LAST_PRICE") -> 95.265 | I20: =_xll.BDP($Z20,"CHG_PCT_1D") -> -0.26301011 | J20: =_xll.BDP($Z20,"YLD_YTM_MID") -> 7.2172472 | K20: =IFERROR(_xll.BDP($Z20,"TRACE_LAST_TRADE_SIZE"),"n/a") -> 150 | L20: =IFERROR(_xll.BDP($Z20,"PRICE_LAST_TIME"),"") -> 16:44:24 | M20: =IF(AND(ISNUMBER(H20),ISNUMBER(G20)),(H20-100)/100*G20,"") -> -38.3535 | N20: =IF(ISNUMBER(H20),(H20-100)/100,"") -> -0.04735 | O20: =IFERROR((H20-_xll.BDP($Z20,"PX_CLOSE_1D"))/100*G20,"") -> -1.8873 | P20: =IF(ISNUMBER(H20),(H20-97.13)/100*G20,"") -> -15.1065 | Q20: =IF(ISNUMBER(J20),(J20-6.72)*100,"") -> 49.724717 | R20: OW | S20: 46188 | T20: =_xll.BDP($Z20,"OAS_SPREAD_MID") -> 229.4324 | U20: AMZN 4.25% 2031 | V20: =_xll.BDP("US023135DD51 Corp","OAS_SPREAD_MID") -> 52.588859 | W20: =IF(AND(ISNUMBER(T20),ISNUMBER(V20)),T20-V20,"") -> 176.84354 | X20: 136 | Y20: =IF(ISNUMBER(W20),W20-X20,"") -> 40.843543 | Z20: STNGRY 6 06/15/31 144A Corp
A21: Core Scientific (Core Scientific Finance I LLC) 7 3/4% Sec Notes due 5/15/2031 | B21: CORZ | C21: CoreWeave | D21: Various (5 sites: TX, GA, OK, NC) | E21: 590 | F21: NR/BB/BB- | G21: 3300 | H21: =_xll.BDP($Z21,"LAST_PRICE") -> 93.155 | I21: =_xll.BDP($Z21,"CHG_PCT_1D") -> -0.75096229 | J21: =_xll.BDP($Z21,"YLD_YTM_MID") -> 9.6475756 | K21: =IFERROR(_xll.BDP($Z21,"TRACE_LAST_TRADE_SIZE"),"n/a") -> 1MM+ | L21: =IFERROR(_xll.BDP($Z21,"PRICE_LAST_TIME"),"") -> 16:44:24 | M21: =IF(AND(ISNUMBER(H21),ISNUMBER(G21)),(H21-100)/100*G21,"") -> -225.885 | N21: =IF(ISNUMBER(H21),(H21-100)/100,"") -> -0.06845 | O21: =IFERROR((H21-_xll.BDP($Z21,"PX_CLOSE_1D"))/100*G21,"") -> -21.549 | P21: =IF(ISNUMBER(H21),(H21-97.67)/100*G21,"") -> -148.995 | Q21: =IF(ISNUMBER(J21),(J21-8.41)*100,"") -> 123.75756 | R21: OW | S21: 46148 | T21: =_xll.BDP($Z21,"OAS_SPREAD_MID") -> 489.68715 | U21: CRWV 9% 2031 | V21: =_xll.BDP("CRWV 9 02/01/2031 144A Corp","OAS_SPREAD_MID") -> 1050.1994 | W21: =IF(AND(ISNUMBER(T21),ISNUMBER(V21)),T21-V21,"") -> -560.51221 | X21: -313 | Y21: =IF(ISNUMBER(W21),W21-X21,"") -> -247.51221 | Z21: CORZ 7.75 05/15/31 144A Corp
A22: Edged (Edged Compute LLC) 7 1/2% Sec Notes due 4/30/2031 | B22: EDGCOM | C22: CoreWeave (Chicago) / Alibaba (Atlanta) | D22: Chicago, IL (72MW) / Atlanta, GA (42MW) | E22: 114 | F22: NR/BB+/BB- | G22: 1300 | H22: =_xll.BDP($Z22,"LAST_PRICE") -> 87.946 | I22: =_xll.BDP($Z22,"CHG_PCT_1D") -> -1.0217074 | J22: =_xll.BDP($Z22,"YLD_YTM_MID") -> 10.899613 | K22: =IFERROR(_xll.BDP($Z22,"TRACE_LAST_TRADE_SIZE"),"n/a") -> 1MM+ | L22: =IFERROR(_xll.BDP($Z22,"PRICE_LAST_TIME"),"") -> 16:44:24 | M22: =IF(AND(ISNUMBER(H22),ISNUMBER(G22)),(H22-100)/100*G22,"") -> -156.702 | N22: =IF(ISNUMBER(H22),(H22-100)/100,"") -> -0.12054 | O22: =IFERROR((H22-_xll.BDP($Z22,"PX_CLOSE_1D"))/100*G22,"") -> -13.663 | P22: =IF(ISNUMBER(H22),(H22-94.25)/100*G22,"") -> -81.952 | Q22: =IF(ISNUMBER(J22),(J22-9.3)*100,"") -> 159.96128 | R22: UW | S22: 46141 | T22: =_xll.BDP($Z22,"OAS_SPREAD_MID") -> 654.06518 | U22: CRWV 9% 2031 | V22: =_xll.BDP("CRWV 9 02/01/2031 144A Corp","OAS_SPREAD_MID") -> 1050.1994 | W22: =IF(AND(ISNUMBER(T22),ISNUMBER(V22)),T22-V22,"") -> -396.13418 | X22: -217 | Y22: =IF(ISNUMBER(W22),W22-X22,"") -> -179.13418 | Z22: EDGCOM 7.5 04/30/31 144A Corp
A23: Fleet Data Centers/Tract (SV RNO Property Owner 1) 5 7/8% Sec Notes due 3/1/2031 | B23: TRACTC | C23: NVIDIA | D23: Storey County, NV | E23: 200 | F23: Ba1/(P)BB+/BB | G23: 3800 | H23: =_xll.BDP($Z23,"LAST_PRICE") -> 89.109 | I23: =_xll.BDP($Z23,"CHG_PCT_1D") -> -0.57204535 | J23: =_xll.BDP($Z23,"YLD_YTM_MID") -> 8.8175717 | K23: =IFERROR(_xll.BDP($Z23,"TRACE_LAST_TRADE_SIZE"),"n/a") -> 8 | L23: =IFERROR(_xll.BDP($Z23,"PRICE_LAST_TIME"),"") -> 16:44:24 | M23: =IF(AND(ISNUMBER(H23),ISNUMBER(G23)),(H23-100)/100*G23,"") -> -413.858 | N23: =IF(ISNUMBER(H23),(H23-100)/100,"") -> -0.10891 | O23: =IFERROR((H23-_xll.BDP($Z23,"PX_CLOSE_1D"))/100*G23,"") -> -34.846 | P23: =IF(ISNUMBER(H23),(H23-92.63)/100*G23,"") -> -133.798 | Q23: =IF(ISNUMBER(J23),(J23-7.93)*100,"") -> 88.75717 | R23: OW | S23: 46077 | T23: =_xll.BDP($Z23,"OAS_SPREAD_MID") -> 405.1552 | U23: NVDA 2% 2031 | V23: =_xll.BDP("US67066GAN43 Corp","OAS_SPREAD_MID") -> 44.411947 | W23: =IF(AND(ISNUMBER(T23),ISNUMBER(V23)),T23-V23,"") -> 360.74326 | X23: 276 | Y23: =IF(ISNUMBER(W23),W23-X23,"") -> 84.743255 | Z23: TRACTC 5.875 03/01/31 144A Corp
A24: Fleet Data Centers/Tract (PR RNO Property Owner 1) 6 1/2% Sec Notes due 5/1/2031 | B24: TRACTD | C24: NVIDIA | D24: Storey County, NV | E24: 200 | F24: Ba1/(P)BB/BB | G24: 4585 | H24: =_xll.BDP($Z24,"LAST_PRICE") -> 90.215 | I24: =_xll.BDP($Z24,"CHG_PCT_1D") -> -1.054426 | J24: =_xll.BDP($Z24,"YLD_YTM_MID") -> 9.2035095 | K24: =IFERROR(_xll.BDP($Z24,"TRACE_LAST_TRADE_SIZE"),"n/a") -> 500 | L24: =IFERROR(_xll.BDP($Z24,"PRICE_LAST_TIME"),"") -> 16:44:24 | M24: =IF(AND(ISNUMBER(H24),ISNUMBER(G24)),(H24-100)/100*G24,"") -> -448.64225 | N24: =IF(ISNUMBER(H24),(H24-100)/100,"") -> -0.09785 | O24: =IFERROR((H24-_xll.BDP($Z24,"PX_CLOSE_1D"))/100*G24,"") -> -41.3567 | P24: =IF(ISNUMBER(H24),(H24-93.75)/100*G24,"") -> -162.07975 | Q24: =IF(ISNUMBER(J24),(J24-8.2)*100,"") -> 100.35095 | R24: OW | S24: 46143 | T24: =_xll.BDP($Z24,"OAS_SPREAD_MID") -> 439.52395 | U24: NVDA 2% 2031 | V24: =_xll.BDP("US67066GAN43 Corp","OAS_SPREAD_MID") -> 44.411947 | W24: =IF(AND(ISNUMBER(T24),ISNUMBER(V24)),T24-V24,"") -> 395.11201 | X24: 302 | Y24: =IF(ISNUMBER(W24),W24-X24,"") -> 93.112006 | Z24: TRACTD 6.5 05/01/31 144A Corp
A25: Fluidstack-led JV (Flash Compute LLC) 7 1/4% Sec Notes due 12/31/2030 | B25: FLASHC | C25: Fluidstack (Google backstop) | D25: Abernathy, TX | E25: 168 | F25: Ba3/NR/NR | G25: 1300 | H25: =_xll.BDP($Z25,"LAST_PRICE") -> 99.374 | I25: =_xll.BDP($Z25,"CHG_PCT_1D") -> -0.32772999 | J25: =_xll.BDP($Z25,"YLD_YTM_MID") -> 7.4587606 | K25: =IFERROR(_xll.BDP($Z25,"TRACE_LAST_TRADE_SIZE"),"n/a") -> 1MM+ | L25: =IFERROR(_xll.BDP($Z25,"PRICE_LAST_TIME"),"") -> 16:44:24 | M25: =IF(AND(ISNUMBER(H25),ISNUMBER(G25)),(H25-100)/100*G25,"") -> -8.138 | N25: =IF(ISNUMBER(H25),(H25-100)/100,"") -> -0.00626 | O25: =IFERROR((H25-_xll.BDP($Z25,"PX_CLOSE_1D"))/100*G25,"") -> -2.548 | P25: =IF(ISNUMBER(H25),(H25-100.25)/100*G25,"") -> -11.388 | Q25: =IF(ISNUMBER(J25),(J25-7.19)*100,"") -> 26.87606 | R25: MW | S25: 46020 | T25: =_xll.BDP($Z25,"OAS_SPREAD_MID") -> 260.34913 | U25: GOOGL 4.1% 2031 | V25: =_xll.BDP("US02079KBK25 Corp","OAS_SPREAD_MID") -> 41.152337 | W25: =IF(AND(ISNUMBER(T25),ISNUMBER(V25)),T25-V25,"") -> 219.19679 | X25: 192 | Y25: =IF(ISNUMBER(W25),W25-X25,"") -> 27.19679 | Z25: FLASHC 7.25 12/31/30 144A Corp
A26: Fluidstack/Next Frontier JV (Meridian Arc Holdco LLC) 6 1/4% Sec Notes due 4/30/2031 | B26: MERIDI | C26: Fluidstack (Google backstop) | D26: New Lebanon, IN | E26: 430 | F26: Ba2/BB-/BB | G26: 5700 | H26: =_xll.BDP($Z26,"LAST_PRICE") -> 91.868 | I26: =_xll.BDP($Z26,"CHG_PCT_1D") -> -0.31145585 | J26: =_xll.BDP($Z26,"YLD_YTM_MID") -> 8.4501543 | K26: =IFERROR(_xll.BDP($Z26,"TRACE_LAST_TRADE_SIZE"),"n/a") -> 100 | L26: =IFERROR(_xll.BDP($Z26,"PRICE_LAST_TIME"),"") -> 16:44:24 | M26: =IF(AND(ISNUMBER(H26),ISNUMBER(G26)),(H26-100)/100*G26,"") -> -463.524 | N26: =IF(ISNUMBER(H26),(H26-100)/100,"") -> -0.08132 | O26: =IFERROR((H26-_xll.BDP($Z26,"PX_CLOSE_1D"))/100*G26,"") -> -15.561 | P26: =IF(ISNUMBER(H26),(H26-94.63)/100*G26,"") -> -157.434 | Q26: =IF(ISNUMBER(J26),(J26-7.67)*100,"") -> 78.015426 | R26: MW | S26: 46136 | T26: =_xll.BDP($Z26,"OAS_SPREAD_MID") -> 357.71613 | U26: GOOGL 4.1% 2031 | V26: =_xll.BDP("US02079KBK25 Corp","OAS_SPREAD_MID") -> 41.152337 | W26: =IF(AND(ISNUMBER(T26),ISNUMBER(V26)),T26-V26,"") -> 316.56379 | X26: 245 | Y26: =IF(ISNUMBER(W26),W26-X26,"") -> 71.563792 | Z26: MERIDI 6.25 04/30/31 144A Corp
A27: Fluidstack/Next Frontier JV (Zenith Arc LLC) 8 7/8% Sec Notes due 8/31/2031 | B27: ZENARC | C27: Jane Street | D27: Okmulgee, OK | E27: 149 | F27: Ba2/BB/NR | G27: 2250 | H27: =_xll.BDP($Z27,"LAST_PRICE") -> 85.008 | I27: =_xll.BDP($Z27,"CHG_PCT_1D") -> 2.1858097 | J27: =_xll.BDP($Z27,"YLD_YTM_MID") -> 13.095812 | K27: =IFERROR(_xll.BDP($Z27,"TRACE_LAST_TRADE_SIZE"),"n/a") -> 1000 | L27: =IFERROR(_xll.BDP($Z27,"PRICE_LAST_TIME"),"") -> 16:44:24 | M27: =IF(AND(ISNUMBER(H27),ISNUMBER(G27)),(H27-100)/100*G27,"") -> -337.32 | N27: =IF(ISNUMBER(H27),(H27-100)/100,"") -> -0.14992 | O27: =IFERROR((H27-_xll.BDP($Z27,"PX_CLOSE_1D"))/100*G27,"") -> 39.5325 | P27: =IF(ISNUMBER(H27),(H27-92.5)/100*G27,"") -> -168.57 | Q27: =IF(ISNUMBER(J27),(J27-10.86)*100,"") -> 223.58125 | S27: 46252 | T27: =_xll.BDP($Z27,"OAS_SPREAD_MID") -> 822.75219 | U27: Jane Street 7.294% 2031 | V27: =_xll.BDP("USU47015AH24 Corp","OAS_SPREAD_MID") -> 226.43298 | W27: =IF(AND(ISNUMBER(T27),ISNUMBER(V27)),T27-V27,"") -> 596.3192 | X27: 410 | Y27: =IF(ISNUMBER(W27),W27-X27,"") -> 186.3192 | Z27: ZENARC 8.875 08/31/31 144A Corp
A28: Galaxy Digital (Galaxy Helios Data Centers II LLC) 9 7/8% Sec Notes due 8/1/2031 | B28: GALAXY | C28: CoreWeave | D28: Dickens County, TX | E28: 260 | F28: NR/BB-/BB- | G28: 3507 | H28: =_xll.BDP($Z28,"LAST_PRICE") -> 91.064 | I28: =_xll.BDP($Z28,"CHG_PCT_1D") -> -1.0446242 | J28: =_xll.BDP($Z28,"YLD_YTM_MID") -> 12.517412 | K28: =IFERROR(_xll.BDP($Z28,"TRACE_LAST_TRADE_SIZE"),"n/a") -> 1000 | L28: =IFERROR(_xll.BDP($Z28,"PRICE_LAST_TIME"),"") -> 16:44:24 | M28: =IF(AND(ISNUMBER(H28),ISNUMBER(G28)),(H28-100)/100*G28,"") -> -313.38552 | N28: =IF(ISNUMBER(H28),(H28-100)/100,"") -> -0.08936 | O28: =IFERROR((H28-_xll.BDP($Z28,"PX_CLOSE_1D"))/100*G28,"") -> -19.42878 | P28: =IF(ISNUMBER(H28),(H28-99.25)/100*G28,"") -> -287.08302 | Q28: =IF(ISNUMBER(J28),(J28-10.1)*100,"") -> 241.74116 | R28: OW | S28: 46231 | T28: =_xll.BDP($Z28,"OAS_SPREAD_MID") -> 764.7852 | U28: CRWV 9% 2031 | V28: =_xll.BDP("CRWV 9 02/01/2031 144A Corp","OAS_SPREAD_MID") -> 1050.1994 | W28: =IF(AND(ISNUMBER(T28),ISNUMBER(V28)),T28-V28,"") -> -285.41417 | X28: -150 | Y28: =IF(ISNUMBER(W28),W28-X28,"") -> -135.41417 | Z28: GALAXY 9.875 08/01/31 144A Corp
A29: Prime Data Centers (Elk Grove Village Property LLC) 7 1/2% Sec Notes due 6/15/2031 | B29: ELKGVP | C29: CoreWeave | D29: Chicago, IL | E29: 72 | F29: Ba3/BB-/BB- | G29: 900 | H29: =_xll.BDP($Z29,"LAST_PRICE") -> 93.622 | I29: =_xll.BDP($Z29,"CHG_PCT_1D") -> -0.32418555 | J29: =_xll.BDP($Z29,"YLD_YTM_MID") -> 9.2615243 | K29: =IFERROR(_xll.BDP($Z29,"TRACE_LAST_TRADE_SIZE"),"n/a") -> 1MM+ | L29: =IFERROR(_xll.BDP($Z29,"PRICE_LAST_TIME"),"") -> 16:44:24 | M29: =IF(AND(ISNUMBER(H29),ISNUMBER(G29)),(H29-100)/100*G29,"") -> -57.402 | N29: =IF(ISNUMBER(H29),(H29-100)/100,"") -> -0.06378 | O29: =IFERROR((H29-_xll.BDP($Z29,"PX_CLOSE_1D"))/100*G29,"") -> -1.089 | P29: =IF(ISNUMBER(H29),(H29-95.63)/100*G29,"") -> -18.072 | Q29: =IF(ISNUMBER(J29),(J29-8.79)*100,"") -> 47.15243 | R29: OW | S29: 46182 | T29: =_xll.BDP($Z29,"OAS_SPREAD_MID") -> 460.50215 | U29: CRWV 9% 2031 | V29: =_xll.BDP("CRWV 9 02/01/2031 144A Corp","OAS_SPREAD_MID") -> 1050.1994 | W29: =IF(AND(ISNUMBER(T29),ISNUMBER(V29)),T29-V29,"") -> -589.69722 | X29: -271 | Y29: =IF(ISNUMBER(W29),W29-X29,"") -> -318.69722 | Z29: ELKGVP 7.5 06/15/31 144A Corp
A30: SB Energy (SE Cosmos, LLC) 8 7/8% Sec Notes due 5/1/2031 | B30: SECMOS | C30: SoftBank | D30: Austin, TX | E30: 50 | F30: NR/(P)BB/BB- | G30: 999 | H30: =_xll.BDP($Z30,"LAST_PRICE") -> 95.294 | I30: =_xll.BDP($Z30,"CHG_PCT_1D") -> -1.2367635 | J30: =_xll.BDP($Z30,"YLD_YTM_MID") -> 10.262203 | K30: =IFERROR(_xll.BDP($Z30,"TRACE_LAST_TRADE_SIZE"),"n/a") -> 1MM+ | L30: =IFERROR(_xll.BDP($Z30,"PRICE_LAST_TIME"),"") -> 16:44:24 | M30: =IF(AND(ISNUMBER(H30),ISNUMBER(G30)),(H30-100)/100*G30,"") -> -47.01294 | N30: =IF(ISNUMBER(H30),(H30-100)/100,"") -> -0.04706 | O30: =IFERROR((H30-_xll.BDP($Z30,"PX_CLOSE_1D"))/100*G30,"") -> -9.5904 | P30: =IF(ISNUMBER(H30),(H30-97.13)/100*G30,"") -> -18.34164 | Q30: =IF(ISNUMBER(J30),(J30-9.66)*100,"") -> 60.220277 | R30: MW | S30: 46149 | T30: =_xll.BDP($Z30,"OAS_SPREAD_MID") -> 536.33904 | U30: SoftBank 8.25% 2031 | V30: =_xll.BDP("XS3344488864 Corp","OAS_SPREAD_MID") -> 392.92231 | W30: =IF(AND(ISNUMBER(T30),ISNUMBER(V30)),T30-V30,"") -> 143.41673 | X30: 106 | Y30: =IF(ISNUMBER(W30),W30-X30,"") -> 37.41673 | Z30: SECMOS 8.875 05/01/31 144A Corp
A31: TeraWulf (WULF Compute LLC) 7 3/4% Sec Notes due 10/15/2030 | B31: WULF | C31: Fluidstack (Google backstop) 366MW / Core42 60MW | D31: Barker, NY | E31: 366 | F31: Ba2/BB/BB | G31: 3200 | H31: =_xll.BDP($Z31,"LAST_PRICE") -> 102.417 | I31: =_xll.BDP($Z31,"CHG_PCT_1D") -> -0.078565559 | J31: =_xll.BDP($Z31,"YLD_YTM_MID") -> 7.0540663 | K31: =IFERROR(_xll.BDP($Z31,"TRACE_LAST_TRADE_SIZE"),"n/a") -> 1MM+ | L31: =IFERROR(_xll.BDP($Z31,"PRICE_LAST_TIME"),"") -> 16:44:24 | M31: =IF(AND(ISNUMBER(H31),ISNUMBER(G31)),(H31-100)/100*G31,"") -> 77.344 | N31: =IF(ISNUMBER(H31),(H31-100)/100,"") -> 0.02417 | O31: =IFERROR((H31-_xll.BDP($Z31,"PX_CLOSE_1D"))/100*G31,"") -> -1.44 | P31: =IF(ISNUMBER(H31),(H31-103.9)/100*G31,"") -> -47.456 | Q31: =IF(ISNUMBER(J31),(J31-6.34)*100,"") -> 71.406627 | R31: MW | S31: 45953 | T31: =_xll.BDP($Z31,"OAS_SPREAD_MID") -> 183.86387 | U31: GOOGL 4.1% 2031 | V31: =_xll.BDP("US02079KBK25 Corp","OAS_SPREAD_MID") -> 41.152337 | W31: =IF(AND(ISNUMBER(T31),ISNUMBER(V31)),T31-V31,"") -> 142.71153 | X31: 90 | Y31: =IF(ISNUMBER(W31),W31-X31,"") -> 52.711534 | Z31: WULF 7.75 10/15/30 144A Corp
A32: Yondr Group/JK Land Holdings JV (Yondr JK 1, LLC) 6 7/8% Sec Notes due 6/30/2031 | B32: YNDRDC | C32: Oracle | D32: Loudoun County, VA | E32: 48 | F32: Ba3/NR/BB | G32: 715 | H32: =_xll.BDP($Z32,"LAST_PRICE") -> 89.657 | I32: =_xll.BDP($Z32,"CHG_PCT_1D") -> -2.0872717 | J32: =_xll.BDP($Z32,"YLD_YTM_MID") -> 9.6972191 | K32: =IFERROR(_xll.BDP($Z32,"TRACE_LAST_TRADE_SIZE"),"n/a") -> 1000 | L32: =IFERROR(_xll.BDP($Z32,"PRICE_LAST_TIME"),"") -> 16:44:24 | M32: =IF(AND(ISNUMBER(H32),ISNUMBER(G32)),(H32-100)/100*G32,"") -> -73.95245 | N32: =IF(ISNUMBER(H32),(H32-100)/100,"") -> -0.10343 | O32: =IFERROR((H32-_xll.BDP($Z32,"PX_CLOSE_1D"))/100*G32,"") -> -12.7413 | P32: =IF(ISNUMBER(H32),(H32-92.75)/100*G32,"") -> -22.11495 | Q32: =IF(ISNUMBER(J32),(J32-8.92)*100,"") -> 77.721914 | R32: OW | S32: 46203 | T32: =_xll.BDP($Z32,"OAS_SPREAD_MID") -> 508.10483 | U32: ORCL 4.95% 2031 | V32: =_xll.BDP("US68389XDX03 Corp","OAS_SPREAD_MID") -> 225.91147 | W32: =IF(AND(ISNUMBER(T32),ISNUMBER(V32)),T32-V32,"") -> 282.19336 | X32: 267 | Y32: =IF(ISNUMBER(W32),W32-X32,"") -> 15.193357 | Z32: YNDRDC 6.875 06/30/31 144A Corp
A33: HY total | G33: =SUM(G15:G32) -> 42189 | H33: =IFERROR(SUMPRODUCT(H15:H32,G15:G32)/SUM(G15:G32),"") -> 93.580131 | M33: =IFERROR(SUM(M15:M32),"") -> -2708.4787 | N33: =IFERROR(M33/G33,"") -> -0.064198694 | O33: =IFERROR(SUM(O15:O32),"") -> -182.60393 | P33: =IFERROR(SUM(P15:P32),"") -> -1465.7729
A34: Tenant / parent comparables
A35: CoreWeave 9 3/4% Sr Notes due 10/1/2031 | B35: CRWV | C35: CoreWeave | D35: HPC cloud provider | G35: 2750 | H35: =_xll.BDP($Z35,"LAST_PRICE") -> 81.122 | I35: =_xll.BDP($Z35,"CHG_PCT_1D") -> -2.6888331 | J35: =_xll.BDP($Z35,"YLD_YTM_MID") -> 15.566073 | K35: =IFERROR(_xll.BDP($Z35,"TRACE_LAST_TRADE_SIZE"),"n/a") -> 1000 | L35: =IFERROR(_xll.BDP($Z35,"PRICE_LAST_TIME"),"") -> 16:44:24 | M35: =IF(AND(ISNUMBER(H35),ISNUMBER(G35)),(H35-100)/100*G35,"") -> -519.145 | N35: =IF(ISNUMBER(H35),(H35-100)/100,"") -> -0.18878 | O35: =IFERROR((H35-_xll.BDP($Z35,"PX_CLOSE_1D"))/100*G35,"") -> -41.5525 | P35: =IF(ISNUMBER(H35),(H35-90.25)/100*G35,"") -> -251.02 | Q35: =IF(ISNUMBER(J35),(J35-12.46)*100,"") -> 310.60726 | S35: 46126 | T35: =_xll.BDP($Z35,"OAS_SPREAD_MID") -> 1070.0762 | Z35: CRWV 9.75 10/01/2031 144A Corp
A36: Oracle 4.95% Sr Notes due 2/4/2031 | B36: ORCL | C36: Oracle | D36: Tenant parent | G36: 3500 | H36: =_xll.BDP($Z36,"LAST_PRICE") -> 91.99 | I36: =_xll.BDP($Z36,"CHG_PCT_1D") -> 0.066211329 | J36: =_xll.BDP($Z36,"YLD_YTM_MID") -> 7.128663 | K36: =IFERROR(_xll.BDP($Z36,"TRACE_LAST_TRADE_SIZE"),"n/a") -> 48 | L36: =IFERROR(_xll.BDP($Z36,"PRICE_LAST_TIME"),"") -> 16:44:24 | M36: =IF(AND(ISNUMBER(H36),ISNUMBER(G36)),(H36-100)/100*G36,"") -> -280.35 | N36: =IF(ISNUMBER(H36),(H36-100)/100,"") -> -0.0801 | O36: =IFERROR((H36-_xll.BDP($Z36,"PX_CLOSE_1D"))/100*G36,"") -> -0.105 | P36: =IF(ISNUMBER(H36),(H36-94.96)/100*G36,"") -> -103.95 | Q36: =IF(ISNUMBER(J36),(J36-6.28)*100,"") -> 84.866299 | S36: 46057 | T36: =_xll.BDP($Z36,"OAS_SPREAD_MID") -> 225.91147 | Z36: ORCL 4.95 02/04/31 Corp
A38: Notes: composite quotes refresh about every 15 seconds and are not individual trades. 'Last trade size' is the latest TRACE print (e.g. 5MM+ = $5mm or more); cumulative daily bond volume is not available from Bloomberg fields. Principal vs par excludes accrued interest. Amber yield = 10% or more (MS: HY datacenter deals get pulled near ~10%). Pink = yield up 25bp or more since 15-Sep (Barclays YTW vs live YTM, approximate). Pickup = bond OAS minus the tenant comparable bond's OAS (both live, Bloomberg OAS_SPREAD_MID); Barclays used G-spread on IG non-callables, so IG pickups differ slightly in basis. A negative pickup means the project bond trades tighter than the tenant's own unsecured bond (the CoreWeave comparable is now at about 1,050bp OAS). EDGCOM is measured against CoreWeave 9% 2031 (Chicago, about 60% of the credit); the Alibaba leg (BABA 2.125% 2031) is not blended. First issued = Bloomberg ISSUE_DT (issue / settlement date of the original issue; later taps are not separated).

Sheet Deal Index
A1: Deal dossiers: one tab per bond on the Monitor sheet
A2: Built from official documents where available (SEC filings, indentures, company releases, rating agency releases). Each dossier lists its sources and what could not be verified. Click a ticker to open its tab.
A4: Ticker | B4: Bond | C4: Section | D4: Sources | E4: of which official-type | F4: Open gaps | G4: Headline
A5: HUTBPA | B5: Beacon Point DC LLC 6.129% Senior Secured Notes due 30-Nov-2042 | C5: IG | D5: 15 | E5: 11 | F5: 11 | G5: $4.25bn fully amortizing, non-recourse 144A notes issued 9 Jun 2026 by a Hut 8 SPV to build the 352 MW first phase of the Beacon Point campus in Nueces County, Texas, secured by the project and a 15-year triple-net take-or-pay lease to an unnamed tenant rated AA- or better (reported by the FT to be NVIDIA). Moody's rates the notes Baa2 and they priced at T+165bp. Credit rests on one tenant and on energization and delivery in Q1-Q3 2027; Phase 2 (a second 352 MW lease), NVIDIA's disclosure that it expects to reassign leases to third parties, and the reported Lambda/Anthropic usage raise assignment and end-user questions, with indenture limits on assignment to Qualifying Tenants or Creditworthy Transferees the main protection.
A6: HUTRBA | B6: Hut 8 DC LLC 6.192% Senior Secured Notes due 15-Nov-2042 | C6: IG | D6: 16 | E6: 11 | F6: 9 | G6: $3.25bn fully amortizing, non-recourse 144A notes issued 30 Apr 2026 by a Hut 8 SPV to build the 245 MW River Bend campus in West Feliciana Parish, Louisiana, secured by the project and a 15-year triple-net lease to Fluidstack (unrated) whose rent and certain other obligations are backstopped by Google LLC. Rated BBB- by S&P and Fitch (per press). The credit is effectively Google's for rent, but the backstop's cap and conditions are not public; no warrants to Google are disclosed (the company said none were issued). Execution risk remains until the first hall energizes in Q2 2027 at about 95% loan-to-cost.
A7: RPLDCI | B7: Beignet Investor LLC 6.581% Senior Secured Notes due 30-May-2049 | C7: IG | D7: 12 | E7: 7 | F7: 9 | G7: A single-tranche, fully amortising 144A project bond (about $27.3bn) issued in Oct 2025 to fund the Hyperion data centre campus in Richland Parish, Louisiana, owned by a joint venture in which Blue Owl funds hold 80% and Meta 20%. Debt service is meant to come from Meta's lease rent plus a Meta residual value guarantee (RVG), so the credit is essentially Meta's; S&P rates it A+ (one notch below Meta), per press reports. Meta consolidates nothing: it treats the JV as an unconsolidated VIE, but discloses $46.0bn of maximum exposure to loss as of 30-Jun-2026. Main watch items are construction and power delivery (the campus was announced in Jul 2026 to scale to 5 GW) and what happens at the end of each four-year lease block.
A8: TXEDCI | B8: Sopaipilla Investor LLC 7.534% Senior Secured Notes due 30-Nov-2048 | C8: IG | D8: 8 | E8: 2 | F8: 8 | G8: A roughly $12.3-12.6bn 144A senior secured bond issued in late Jul 2026 to fund Meta's El Paso, Texas data centre campus (about 1 GW, about $14bn total cost), owned by a JV in which BlackRock-managed funds (GIP and HPS) hold 80% and Meta 20%. Meta is sole tenant, developer and operator, pays rent from Dec 2028 whether or not the campus is complete, and provides a residual value guarantee (up to about $13bn per its 10-Q). Ratings reported at A+ (S&P, preliminary) and AA- (Fitch, expected); the one-notch gap reflects the absence of an asset mortgage. Seed 7.534% coupon, ISIN and maturity are confirmed by a fund holdings filing, but almost everything else rests on press and newsletter coverage because the offering memorandum is private and Meta has not yet filed its post-closing 10-Q.
A9: RDMICH | B9: RD Michigan Property Owner I LLC 7.50% Senior Secured Notes due 2045 (Related Digital / Blackstone, Oracle campus, Saline Township, MI) | C9: IG | D9: 18 | E9: 9 | F9: 9 | G9: $14bn 7.500% senior secured notes due 2045 issued in spring 2026 by a Related Digital/Blackstone SPV to fund a 974MW Oracle data center campus in Saline Township, Michigan, anchored by PIMCO. Cash flows come from four triple-net leases to Oracle America Cloud Services guaranteed by Oracle Corporation, so the credit is essentially Oracle (S&P BBB-, Moody's Baa2 negative per Feb-2026 data) plus construction risk; KBRA rates it BBB Stable. The spread over Oracle's own bonds reflects project, construction, power-approval litigation and 144A illiquidity.
A10: QTSODY | B10: QTS Central Issuer LLC 6.625% Senior Secured Notes due 1-Sep-2031 (5NC2) | C10: IG | D10: 18 | E10: 5 | F10: 9 | G10: QTSODY is a $3.9bn five-year non-call-2 non-recourse project bond sold by Blackstone's QTS in Aug 2026 (closed 27-Aug) to finance part of the Microsoft-leased Fayetteville, Georgia campus (Project Odyssey). It was reshaped from a larger bond-and-loan package into an investment-grade deal reportedly rated Baa3/BBB-, yet priced at a 7.228% yield. Support is the Microsoft lease and the project; there is little official disclosure because it is a 144A deal with no SEC filings.
A11: QTSQST | B11: QTS Fayetteville I DC1-2 LLC 5.70% Senior Secured Notes due 15-Apr-2036 | C11: IG | D11: 18 | E11: 5 | F11: 7 | G11: QTSQST is a $4.6bn 10-year non-amortising, non-recourse single-asset project bond issued in April 2026 by QualityTech (Blackstone) subsidiaries, refinancing construction credit facilities for two Microsoft-leased data centers on the Fayetteville, Georgia campus. Moody's reportedly assigned Baa2. Support is the Microsoft lease and the project; it moved from a 5.70% issue yield to about 7.2% by Aug-Sep 2026 as AI-infrastructure credit repriced.
A12: APLD | B12: APLD ComputeCo LLC 9 1/4% Senior Secured Notes due 15-Dec-2030 | C12: HY | D12: 17 | E12: 15 | F12: 11 | G12: APLD ComputeCo LLC's $2.35bn 9.25% senior secured notes due December 2030 are a ring-fenced, project-style financing of two CoreWeave-leased buildings (100 MW and 150 MW, now both live) at the Polaris Forge 1 campus in Ellendale, North Dakota. Applied Digital provides only a completion guarantee, not a payment guarantee; credit rests on CoreWeave rent (now partly owed by a CoreWeave SPV with springing parent guaranty), a DSRA, and a sculpted amortization that leaves roughly 70-75% to refinance at maturity. The sponsor's own model shows coverage near 1.0x in 2028-2029, which together with CoreWeave credit concerns and a heavy parent funding pipeline explains why the notes carry a high-yield spread despite full delivery of the assets.
A13: PFORGE | B13: APLD ComputeCo 2 LLC 6 3/4% Senior Secured Notes due 15-Mar-2031 | C13: HY | D13: 14 | E13: 12 | F13: 9 | G13: APLD ComputeCo 2 LLC's $2.15bn 6.75% senior secured notes due March 2031 finance the 200 MW Oracle-leased Polaris Forge 2 campus in Harwood, North Dakota, through a ring-fenced chain of lessor SPVs with an Applied Digital completion guarantee. The 15-year take-or-pay lease and sculpted amortization (about 81% balloon, about 1.0x modelled coverage, $148mm DSRA) put the bond between investment-grade-tenant and high-yield sponsor risk; the campus is still under construction, with first ready-for-service now guided to 2H CY2026 after a model date of 1-Oct-2026, and the notes marked in the mid-90s at 31-Aug-2026 after a sell-side downgrade on supply overhang.
A14: ELNFOR | B14: APLD ComputeCo 3 LLC 7% Senior Secured Notes due 15-Jun-2031 | C14: HY | D14: 17 | E14: 14 | F14: 9 | G14: APLD ComputeCo 3 LLC's $1.59bn 7.00% senior secured notes due June 2031 fund the third 150 MW building (ELN-04) at Applied Digital's Polaris Forge 1 campus in Ellendale, North Dakota, leased to CoreWeave. The building is still under construction, so the credit combines construction and delivery risk (backstopped by a parent completion guarantee), single-tenant CoreWeave exposure with a possible upgrade path through an unconsummated June-2026 MoU to an investment-grade CoreWeave subsidiary, and an amortization profile that leaves about 85% to refinance in 2031. Sponsor model coverage is 1.2x from 2028, and the bond traded down to about 94 by Oct 2026 amid supply-overhang concerns.
A15: CIFR | B15: Cipher Compute LLC 7.125% Senior Secured Notes due 15-Nov-2030 | C15: HY | D15: 19 | E15: 16 | F15: 9 | G15: Project-finance notes of Cipher Compute LLC ($1.733bn outstanding) that fund the 207 MW critical IT Barber Lake data center in Colorado City, Texas, leased to Fluidstack with a Google backstop equal to the debt and a Cipher completion guarantee. Credit hinges on on-time delivery (now Q4 2026-Q1 2027 after change orders), Google's backstop, and the parent's ability to fund a cost increase of roughly $0.5bn while its equity has been hit by a heavy 2032 convertible and 2030 exchange. The notes amortize but leave a large balloon at Nov-2030.
A16: BLKPRL | B16: Black Pearl Compute LLC 6.125% Senior Secured Notes due 15-Feb-2031 | C16: HY | D16: 13 | E16: 11 | F16: 9 | G16: $2.0bn project notes of Black Pearl Compute LLC funding the retrofit and build-out of a 300 MW gross / 216 MW critical IT campus in Wink, Texas, leased to Amazon Data Services under a 15-year triple-net sublease with an Amazon.com parent guaranty and a $9.5mm per MW tenant cost cap. First capacity was delivered two months early (Aug-2026) and rent has started, but later halls are being re-phased, the notes amortize only 7% a year leaving roughly a 70% balloon at Feb-2031, and loss of the lease or guaranty is an immediate default. Tight pricing reflects Amazon credit and tenant protections against overruns.
... A31: ORCL | B31: Oracle Corporation 4.950% Senior Notes due 4-Feb-2031 | C31: Parent | D31: 12 | E31: 9 | F31: 7 | G31: $3.5bn of Oracle's 4.950% unsecured senior notes due 4-Feb-2031, one of eight series in a $25bn offering priced on 2-Feb-2026 (alongside a $5bn mandatory convertible and a $20bn ATM that Oracle has since fully used). It is the parent/tenant comparable for Oracle-leased project bonds: priced at T+115bp, now rated BBB- at S&P (cut 9-Jul-2026), Baa2 negative at Moody's and BBB at Fitch as last confirmed. Credit story is heavy AI capex (Q1 FY27 capex $28.5bn, FCF -$5.4bn), $125bn of debt and $288bn of not-yet-commenced data center leases against a $664bn backlog.

Sheet Terms & Lease
A1: Terms, call schedule and lease structure
A2: From Barclays Figures 7 and 8 (15-Sep). Live price links to the Monitor sheet.
A4: Company / description | B4: Ticker | C4: Tenant | D4: LIVE price | E4: Next call | F4: Call price | G4: Live price to call (pts) | H4: Amort. start | I4: Est. amortization before maturity (% of original) | J4: Tenant comp bond | K4: Tenant comp spread (bp) | L4: Lease type | M4: Lease tenor | N4: Construction start | O4: Lease commencement | P4: Barclays spread 15-Sep (bp)
A5: Investment Grade HPC Data Center Builders
A6: Hut 8 (Beacon Point DC LLC) 6.129% Sec Notes due 11/30/2042 | B6: HUTBPA | C6: NVIDIA | D6: =Monitor!H6 -> 92.424 | E6: 5/30/42 | F6: 100 | G6: =IF(ISNUMBER(D6),F6-D6,"") -> 7.576 | H6: Mid 2030 | I6: 1 | J6: NVDA 4.95% 2036 | K6: 75 | L6: Triple Net | M6: 15yrs, three 5-yr ext. | N6: Early 2026 | O6: Aug 2027 - Apr 2028 | P6: 200
A7: Hut 8 (Hut 8 DC LLC) 6.192% Sec Notes due 11/15/2042 | B7: HUTRBA | C7: Fluidstack (Google backstop) | D7: =Monitor!H7 -> 93.919 | E7: 5/15/42 | F7: 100 | G7: =IF(ISNUMBER(D7),F7-D7,"") -> 6.081 | H7: Mid 2028 | I7: 1 | J7: GOOGL 4.8% 2036 | K7: 68 | L7: Triple Net | M7: 15yrs, three 5-yr ext. | N7: Dec 2025 | O7: Apr 2027 - Oct 2027 | P7: 178
A8: BlueOwl/Meta JV (Beignet Investor LLC) 6.581% Sec Notes due 5/30/2049 | B8: RPLDCI | C8: Meta | D8: =Monitor!H8 -> 91.908 | E8: 11/30/48 | F8: 100 | G8: =IF(ISNUMBER(D8),F8-D8,"") -> 8.092 | H8: Mid 2029 | I8: 1 | J8: META 5.25% 2036 | K8: 94 | L8: Triple Net | M8: 20yrs (4yr initial + 4 x 4yr ext.) | N8: Late 2024 | O8: June 2029 | P8: 205
A9: Blackrock/Meta JV (Sopapilla Investor LLC) 7.534% Sec Notes due 11/30/2048 | B9: TXEDCI | C9: Meta | D9: =Monitor!H9 -> 98.999 | E9: 5/30/48 | F9: 100 | G9: =IF(ISNUMBER(D9),F9-D9,"") -> 1.001 | H9: Late 2028 | I9: 1 | J9: META 5.25% 2036 | K9: 94 | L9: Triple Net | M9: 20yrs (4yr initial + 4 x 4yr ext.) | N9: Oct 2025 | O9: Dec 2028 | P9: 222
A10: Related Digital (RD Michigan Pro Owner I) 7.50% Sec Notes due 3/30/2045 | B10: RDMICH | C10: Oracle | D10: =Monitor!H10 -> 87.247 | E10: 4/30/29 | F10: 100 | G10: =IF(ISNUMBER(D10),F10-D10,"") -> 12.753 | H10: Mid 2032 | I10: 1 | J10: ORCL 3.6% 2040 | K10: 208 | L10: Triple Net | M10: 17.5yrs, two 10-yr renewals | N10: Early 2026 | O10: Feb 2027 - Mar 2028 | P10: 279
A11: QTS (QTS Central Issuer LLC) 6.625% Sec Notes due 9/1/2031 (5NC2) | B11: QTSODY | C11: Microsoft | D11: =Monitor!H11 -> 97.166 | E11: 9/1/28 | F11: 100 | G11: =IF(ISNUMBER(D11),F11-D11,"") -> 2.834 | H11: Mid 2029 | I11: 0.055 | J11: MSFT 3.45% 2036 | K11: 31 | L11: Triple Net | M11: 15yrs, 15-yr renewal | N11: Early 2026 | O11: Nov 2027 - Feb 2028 | P11: 176
A12: QTS (QTS Fayetteville Dc1-2 LLC) 5.70% Sec Notes due 4/15/2036 | B12: QTSQST | C12: Microsoft | D12: =Monitor!H12 -> 87.991 | E12: 10/15/35 | F12: 100 | G12: =IF(ISNUMBER(D12),F12-D12,"") -> 12.009 | H12: N/A | I12: 0 | J12: MSFT 3.45% 2036 | K12: 33 | L12: Triple Net | M12: 20yrs, 15-yr renewal | N12: 2023 | O12: Apr 2025 - Apr 2026 | P12: 222
A14: High Yield HPC Data Center Builders
A15: Applied Digital (APLD ComputeCo LLC) 9 1/4% Sec Notes due 12/15/2030 | B15: APLD | C15: CoreWeave | D15: =Monitor!H15 -> 102.776 | E15: 12/15/27 | F15: 104.63 | G15: =IF(ISNUMBER(D15),F15-D15,"") -> 1.854 | H15: Late 2027 | I15: 0.304 | J15: CRWV 9% 2031 | K15: 670 | L15: Modified Gross | M15: 15yrs, three 5-yr ext. | N15: Early 2024 | O15: 4Q25 - 2Q26 | P15: 236
A16: Applied Digital (APLD ComputeCo 2 LLC) 6 3/4% Sec Notes due 3/15/2031 | B16: PFORGE | C16: Oracle | D16: =Monitor!H16 -> 95.153 | E16: 3/15/28 | F16: 103.38 | G16: =IF(ISNUMBER(D16),F16-D16,"") -> 8.227 | H16: Mid 2027 | I16: 0.191 | J16: ORCL 4.95% 2031 | K16: 147 | L16: Modified Gross | M16: 15yrs, two 5-yr ext. | N16: Sept 2025 | O16: Nov 2026 - June 2027 | P16: 314
A17: Applied Digital (APLD ComputeCo 3 LLC) 7% Sec Notes due 6/15/2031 | B17: ELNFOR | C17: CoreWeave | D17: =Monitor!H17 -> 92.836 | E17: 6/15/28 | F17: 103.5 | G17: =IF(ISNUMBER(D17),F17-D17,"") -> 10.664 | H17: Mid 2027 | I17: 0.147 | J17: CRWV 9% 2031 | K17: 670 | L17: Modified Gross | M17: 15yrs, three 5-yr ext. | N17: Aug 2025 | O17: Jan 2027 - June 2027 | P17: 338
A18: Cipher Digital (Cipher Compute LLC) 7 1/8% Sec Notes due 11/15/2030 | B18: CIFR | C18: Fluidstack (Google backstop) | D18: =Monitor!H18 -> 99.088 | E18: 11/15/27 | F18: 103.56 | G18: =IF(ISNUMBER(D18),F18-D18,"") -> 4.472 | H18: Late 2026 | I18: 0.441 | J18: GOOGL 4.1% 2031 | K18: 42 | L18: Modified Gross | M18: 10yrs, two 5-yr ext. | N18: Mid 2025 | O18: Sept 2026 - Jan 2027 | P18: 169
A19: Cipher Digital (Black Pearl Compute LLC) 6 1/8% Sec Notes due 2/15/2031 | B19: BLKPRL | C19: Amazon | D19: =Monitor!H19 -> 98.352 | E19: 2/15/28 | F19: 103.06 | G19: =IF(ISNUMBER(D19),F19-D19,"") -> 4.708 | H19: Early 2027 | I19: 0.277 | J19: AMZN 4.25% 2031 | K19: 50 | L19: Triple Net | M19: 15yrs, three 5-yr ext. | N19: Feb 2026 | O19: Oct 2026 - Mar 2027 | P19: 127
A20: Cipher Digital (Stingray Compute LLC) 6% Sec Notes due 6/15/2031 | B20: STNGRY | C20: Amazon | D20: =Monitor!H20 -> 95.265 | E20: 6/15/28 | F20: 103 | G20: =IF(ISNUMBER(D20),F20-D20,"") -> 7.735 | H20: Mid 2027 | I20: 0.258 | J20: AMZN 4.25% 2031 | K20: 50 | L20: Triple Net | M20: 15yrs, three 5-yr ext. | N20: May 2026 | O20: Apr 2027 | P20: 186
A21: Core Scientific (Core Scientific Finance I LLC) 7 3/4% Sec Notes due 5/15/2031 | B21: CORZ | C21: CoreWeave | D21: =Monitor!H21 -> 93.155 | E21: 5/15/28 | F21: 103.88 | G21: =IF(ISNUMBER(D21),F21-D21,"") -> 10.725 | H21: Early 2029 | I21: 0.236 | J21: CRWV 9% 2031 | K21: 670 | L21: Modified Gross | M21: 12yrs, two 5-yr ext. | N21: Mid 2024 | O21: Late 2024 - Early 2027 | P21: 357
A22: Edged (Edged Compute LLC) 7 1/2% Sec Notes due 4/30/2031 | B22: EDGCOM | C22: CoreWeave (Chicago) / Alibaba (Atlanta) | D22: =Monitor!H22 -> 87.946 | E22: 4/30/28 | F22: 103.75 | G22: =IF(ISNUMBER(D22),F22-D22,"") -> 15.804 | H22: Late 2029 | I22: 0.066 | J22: CRWV 9% 2031 / BABA 2.125% 2031 | L22: Triple Net (Chi) / Mod. Gross (Atl) | M22: 16yrs Chicago / 15yrs Atlanta, two 5-yr ext. | N22: 3Q25 | O22: Chicago May-Dec 2027; Atlanta Jan-Jun 2027 | P22: 453
A23: Fleet Data Centers/Tract (SV RNO Property Owner 1) 5 7/8% Sec Notes due 3/1/2031 | B23: TRACTC | C23: NVIDIA | D23: =Monitor!H23 -> 89.109 | E23: 3/1/28 | F23: 102.94 | G23: =IF(ISNUMBER(D23),F23-D23,"") -> 13.831 | H23: Mid 2028 | I23: 0.082 | J23: NVDA 2% 2031 | K23: 39 | L23: Triple Net | M23: 16.4yrs, two 10-yr ext. | N23: June 2026 | O23: Oct 2027 - June 2028 | P23: 315
A24: Fleet Data Centers/Tract (PR RNO Property Owner 1) 6 1/2% Sec Notes due 5/1/2031 | B24: TRACTD | C24: NVIDIA | D24: =Monitor!H24 -> 90.215 | E24: 5/1/28 | F24: 103.25 | G24: =IF(ISNUMBER(D24),F24-D24,"") -> 13.035 | H24: Mid 2028 | I24: 0.075 | J24: NVDA 2% 2031 | K24: 39 | L24: Triple Net | M24: 16.4yrs, two 10-yr ext. | N24: Summer 2026 | O24: Oct 2027 - Apr 2028 | P24: 341
A25: Fluidstack-led JV (Flash Compute LLC) 7 1/4% Sec Notes due 12/31/2030 | B25: FLASHC | C25: Fluidstack (Google backstop) | D25: =Monitor!H25 -> 99.374 | E25: 12/31/27 | F25: 103.63 | G25: =IF(ISNUMBER(D25),F25-D25,"") -> 4.256 | H25: Late 2026 | I25: 0.325 | J25: GOOGL 4.1% 2031 | K25: 42 | L25: Modified Gross | M25: 25yrs, two 5-yr shortening options | N25: Sept 2025 | O25: Late 4Q26 | P25: 234
A26: Fluidstack/Next Frontier JV (Meridian Arc Holdco LLC) 6 1/4% Sec Notes due 4/30/2031 | B26: MERIDI | C26: Fluidstack (Google backstop) | D26: =Monitor!H26 -> 91.868 | E26: 4/30/28 | F26: 103.13 | G26: =IF(ISNUMBER(D26),F26-D26,"") -> 11.262 | H26: Mid 2027 | I26: 0.13 | J26: GOOGL 4.1% 2031 | K26: 42 | L26: Triple Net | M26: 15yrs, three 5-yr ext. | N26: May 2026 | O26: Aug 2027 - Feb 2028 | P26: 287
A27: Fluidstack/Next Frontier JV (Zenith Arc LLC) 8 7/8% Sec Notes due 8/31/2031 | B27: ZENARC | C27: Jane Street | D27: =Monitor!H27 -> 85.008 | E27: 8/31/28 | F27: 104.44 | G27: =IF(ISNUMBER(D27),F27-D27,"") -> 19.432 | H27: Late 2027 | I27: 0.089 | J27: JANEST 7.294% 2031 | K27: 196 | L27: Triple Net | M27: 15yrs, two 5-yr ext. | N27: July 2026 | O27: Oct 2027 - Nov 2028 | P27: 606
A28: Galaxy Digital (Galaxy Helios Data Centers II LLC) 9 7/8% Sec Notes due 8/1/2031 | B28: GALAXY | C28: CoreWeave | D28: =Monitor!H28 -> 91.064 | E28: 8/1/28 | F28: 104.94 | G28: =IF(ISNUMBER(D28),F28-D28,"") -> 13.876 | H28: Late 2028 | I28: 0.099 | J28: CRWV 9% 2031 | K28: 670 | L28: Modified Gross | M28: 15yrs, two 5-yr ext. | N28: 4Q25 | O28: 2Q27 - 1Q28 | P28: 520
A29: Prime Data Centers (Elk Grove Village Property LLC) 7 1/2% Sec Notes due 6/15/2031 | B29: ELKGVP | C29: CoreWeave | D29: =Monitor!H29 -> 93.622 | E29: 6/15/28 | F29: 103.75 | G29: =IF(ISNUMBER(D29),F29-D29,"") -> 10.128 | H29: Mid 2027 | I29: 0.195 | J29: CRWV 9% 2031 | K29: 670 | L29: Triple Net | M29: 15yrs, two 7-yr ext. | N29: Mid 2024 | O29: Oct 2025 - Early 2027 | P29: 399
A30: SB Energy (SE Cosmos, LLC) 8 7/8% Sec Notes due 5/1/2031 | B30: SECMOS | C30: SoftBank | D30: =Monitor!H30 -> 95.294 | E30: 5/1/28 | F30: 104.44 | G30: =IF(ISNUMBER(D30),F30-D30,"") -> 9.146 | H30: N/A | I30: 0 | J30: SOFTBK 8.25% 2031 | K30: 376 | L30: Triple Net | M30: 15yrs, one 10-yr ext. | N30: Feb 2026 | O30: Dec 2026 - June 2027 | P30: 482
A31: TeraWulf (WULF Compute LLC) 7 3/4% Sec Notes due 10/15/2030 | B31: WULF | C31: Fluidstack (Google backstop) 366MW / Core42 60MW | D31: =Monitor!H31 -> 102.417 | E31: 10/15/27 | F31: 103.88 | G31: =IF(ISNUMBER(D31),F31-D31,"") -> 1.463 | H31: Late 2026 | I31: 0.45 | J31: GOOGL 4.1% 2031 | K31: 42 | L31: Modified Gross | M31: 10yrs, two 5-yr ext. | N31: Apr 2025 (Core42: late 2024) | O31: May - Dec 2026 (Core42: 3Q25-4Q25) | P31: 132
A32: Yondr Group/JK Land Holdings JV (Yondr JK 1, LLC) 6 7/8% Sec Notes due 6/30/2031 | B32: YNDRDC | C32: Oracle | D32: =Monitor!H32 -> 89.657 | E32: 6/30/28 | F32: 103.44 | G32: =IF(ISNUMBER(D32),F32-D32,"") -> 13.783 | H32: Late 2028 | I32: 0.088 | J32: ORCL 4.95% 2031 | K32: 147 | L32: Modified Gross | M32: 15yrs, two 5-yr ext. | N32: Feb 2026 | O32: Jan 2028 - Oct 2028 | P32: 414
A34: Tenant / parent comparables
A35: CoreWeave 9 3/4% Sr Notes due 10/1/2031 | B35: CRWV | C35: CoreWeave | D35: =Monitor!H35 -> 81.122 | P35: 768
A36: Oracle 4.95% Sr Notes due 2/4/2031 | B36: ORCL | C36: Oracle | D36: =Monitor!H36 -> 91.99 | P36: 149

Sheet Financials
A1: Project financial metrics
A2: From Barclays Figure 9 (15-Sep). Rent yield on cost and debt per MW are calculated here. Estimates are Barclays': base rent is estimated where not disclosed; leverage at issuance = pre-amortization debt / run-rate NOI.
A4: Company / description | B4: Ticker | C4: Tenant | D4: LIVE price | E4: LIVE yield % | F4: Amt o/s ($mn) | G4: Facility cost ($mn) | H4: Cost per MW ($mn) | I4: Est. base rent per MW ($mn) | J4: Annual rent escalator | K4: % of funding debt financed | L4: Gross leverage at issuance (x) | M4: Gross leverage at maturity (x) | N4: Rent yield on cost | O4: Debt per MW ($mn) | P4: Critical IT (MW)
A5: Investment Grade HPC Data Center Builders
A6: Hut 8 (Beacon Point DC LLC) 6.129% Sec Notes due 11/30/2042 | B6: HUTBPA | C6: NVIDIA | D6: =Monitor!H6 -> 92.424 | E6: =Monitor!J6 -> 6.9070348 | F6: =Monitor!G6 -> 4250 | G6: 3871 | H6: 11 | I6: 1.57 | J6: 3.0% | K6: 0.97 | L6: 7.7 | M6: 0 | N6: =IF(AND(ISNUMBER(I6),ISNUMBER(H6)),I6/H6,"") -> 0.14272727 | O6: =IF(AND(ISNUMBER(F6),ISNUMBER(P6),P6>0),F6/P6,"") -> 12.073864 | P6: 352
A7: Hut 8 (Hut 8 DC LLC) 6.192% Sec Notes due 11/15/2042 | B7: HUTRBA | C7: Fluidstack (Google backstop) | D7: =Monitor!H7 -> 93.919 | E7: =Monitor!J7 -> 6.8227402 | F7: =Monitor!G7 -> 3250 | G7: 3057 | H7: 12.5 | I7: 1.5 | J7: 3.0% | K7: 0.97 | L7: 8.8 | M7: 0 | N7: =IF(AND(ISNUMBER(I7),ISNUMBER(H7)),I7/H7,"") -> 0.12 | O7: =IF(AND(ISNUMBER(F7),ISNUMBER(P7),P7>0),F7/P7,"") -> 13.265306 | P7: 245
A8: BlueOwl/Meta JV (Beignet Investor LLC) 6.581% Sec Notes due 5/30/2049 | B8: RPLDCI | C8: Meta | D8: =Monitor!H8 -> 91.908 | E8: =Monitor!J8 -> 7.4801614 | F8: =Monitor!G8 -> 27293.8 | G8: 28800 | H8: 14 | I8: 1.23 | J8: 2.0% | K8: 0.9 | L8: 9.1 | M8: 0 | N8: =IF(AND(ISNUMBER(I8),ISNUMBER(H8)),I8/H8,"") -> 0.087857143 | O8: =IF(AND(ISNUMBER(F8),ISNUMBER(P8),P8>0),F8/P8,"") -> 13.22374 | P8: 2064
A9: Blackrock/Meta JV (Sopapilla Investor LLC) 7.534% Sec Notes due 11/30/2048 | B9: TXEDCI | C9: Meta | D9: =Monitor!H9 -> 98.999 | E9: =Monitor!J9 -> 7.6225604 | F9: =Monitor!G9 -> 12639.5 | G9: 13700 | H9: 14.3 | I9: 1.38 | J9: 2.0% | K9: 0.9 | L9: 9.3 | M9: 0 | N9: =IF(AND(ISNUMBER(I9),ISNUMBER(H9)),I9/H9,"") -> 0.096503497 | O9: =IF(AND(ISNUMBER(F9),ISNUMBER(P9),P9>0),F9/P9,"") -> 13.166146 | P9: 960
A10: Related Digital (RD Michigan Pro Owner I) 7.50% Sec Notes due 3/30/2045 | B10: RDMICH | C10: Oracle | D10: =Monitor!H10 -> 87.247 | E10: =Monitor!J10 -> 8.9678816 | F10: =Monitor!G10 -> 14000 | G10: 15543 | H10: 16 | I10: 1.43 | J10: 3.0% | K10: 0.9 | L10: 10.1 | M10: 0 | N10: =IF(AND(ISNUMBER(I10),ISNUMBER(H10)),I10/H10,"") -> 0.089375 | O10: =IF(AND(ISNUMBER(F10),ISNUMBER(P10),P10>0),F10/P10,"") -> 14.373717 | P10: 974
A11: QTS (QTS Central Issuer LLC) 6.625% Sec Notes due 9/1/2031 (5NC2) | B11: QTSODY | C11: Microsoft | D11: =Monitor!H11 -> 97.166 | E11: =Monitor!J11 -> 7.3295727 | F11: =Monitor!G11 -> 3900 | I11: 1.74 | J11: 3.0% | L11: 11 | M11: 9.8 | N11: =IF(AND(ISNUMBER(I11),ISNUMBER(H11)),I11/H11,"") | O11: =IF(AND(ISNUMBER(F11),ISNUMBER(P11),P11>0),F11/P11,"") -> 19.117647 | P11: 204
A12: QTS (QTS Fayetteville Dc1-2 LLC) 5.70% Sec Notes due 4/15/2036 | B12: QTSQST | C12: Microsoft | D12: =Monitor!H12 -> 87.991 | E12: =Monitor!J12 -> 7.5219323 | F12: =Monitor!G12 -> 4600 | I12: 0.9 | J12: 3.0% | L12: 15 | M12: 11.3 | N12: =IF(AND(ISNUMBER(I12),ISNUMBER(H12)),I12/H12,"") | O12: =IF(AND(ISNUMBER(F12),ISNUMBER(P12),P12>0),F12/P12,"") -> 13.529412 | P12: 340
A14: High Yield HPC Data Center Builders
A15: Applied Digital (APLD ComputeCo LLC) 9 1/4% Sec Notes due 12/15/2030 | B15: APLD | C15: CoreWeave | D15: =Monitor!H15 -> 102.776 | E15: =Monitor!J15 -> 8.4534708 | F15: =Monitor!G15 -> 2350 | G15: 3100 | H15: 12.4 | I15: 1.39 | J15: 3.0% | K15: 0.66 | L15: 7.2 | M15: 4.5 | N15: =IF(AND(ISNUMBER(I15),ISNUMBER(H15)),I15/H15,"") -> 0.11209677 | O15: =IF(AND(ISNUMBER(F15),ISNUMBER(P15),P15>0),F15/P15,"") -> 9.4 | P15: 250
A16: Applied Digital (APLD ComputeCo 2 LLC) 6 3/4% Sec Notes due 3/15/2031 | B16: PFORGE | C16: Oracle | D16: =Monitor!H16 -> 95.153 | E16: =Monitor!J16 -> 8.1104983 | F16: =Monitor!G16 -> 2150 | G16: 2391 | H16: 12 | I16: 1.34 | J16: 2.5% | K16: 0.8 | L16: 9.1 | M16: 6.6 | N16: =IF(AND(ISNUMBER(I16),ISNUMBER(H16)),I16/H16,"") -> 0.11166667 | O16: =IF(AND(ISNUMBER(F16),ISNUMBER(P16),P16>0),F16/P16,"") -> 10.75 | P16: 200
A17: Applied Digital (APLD ComputeCo 3 LLC) 7% Sec Notes due 6/15/2031 | B17: ELNFOR | C17: CoreWeave | D17: =Monitor!H17 -> 92.836 | E17: =Monitor!J17 -> 8.831383 | F17: =Monitor!G17 -> 1590 | G17: 1923 | H17: 12.8 | I17: 1.43 | J17: 3.0% | K17: 0.74 | L17: 8.2 | M17: 6.3 | N17: =IF(AND(ISNUMBER(I17),ISNUMBER(H17)),I17/H17,"") -> 0.11171875 | O17: =IF(AND(ISNUMBER(F17),ISNUMBER(P17),P17>0),F17/P17,"") -> 10.6 | P17: 150
A18: Cipher Digital (Cipher Compute LLC) 7 1/8% Sec Notes due 11/15/2030 | B18: CIFR | C18: Fluidstack (Google backstop) | D18: =Monitor!H18 -> 99.088 | E18: =Monitor!J18 -> 7.3958154 | F18: =Monitor!G18 -> 1733 | G18: 2443 | H18: 11.8 | I18: 1.59 | J18: 3.0% | K18: 0.7 | L18: 6.1 | M18: 3 | N18: =IF(AND(ISNUMBER(I18),ISNUMBER(H18)),I18/H18,"") -> 0.13474576 | O18: =IF(AND(ISNUMBER(F18),ISNUMBER(P18),P18>0),F18/P18,"") -> 8.3719807 | P18: 207
A19: Cipher Digital (Black Pearl Compute LLC) 6 1/8% Sec Notes due 2/15/2031 | B19: BLKPRL | C19: Amazon | D19: =Monitor!H19 -> 98.352 | E19: =Monitor!J19 -> 6.5859493 | F19: =Monitor!G19 -> 2000 | G19: 2100 | H19: 9.7 | I19: 1.38 | J19: 3.0% | K19: 0.85 | L19: 6.7 | M19: 4.3 | N19: =IF(AND(ISNUMBER(I19),ISNUMBER(H19)),I19/H19,"") -> 0.14226804 | O19: =IF(AND(ISNUMBER(F19),ISNUMBER(P19),P19>0),F19/P19,"") -> 9.2592593 | P19: 216
A20: Cipher Digital (Stingray Compute LLC) 6% Sec Notes due 6/15/2031 | B20: STNGRY | C20: Amazon | D20: =Monitor!H20 -> 95.265 | E20: =Monitor!J20 -> 7.2172472 | F20: =Monitor!G20 -> 810 | G20: 735 | H20: 10.5 | I20: 1.58 | J20: 3.0% | K20: 0.98 | L20: 7.3 | M20: 4.9 | N20: =IF(AND(ISNUMBER(I20),ISNUMBER(H20)),I20/H20,"") -> 0.15047619 | O20: =IF(AND(ISNUMBER(F20),ISNUMBER(P20),P20>0),F20/P20,"") -> 11.571429 | P20: 70
A21: Core Scientific (Core Scientific Finance I LLC) 7 3/4% Sec Notes due 5/15/2031 | B21: CORZ | C21: CoreWeave | D21: =Monitor!H21 -> 93.155 | E21: =Monitor!J21 -> 9.6475756 | F21: =Monitor!G21 -> 3300 | G21: 5500 | H21: 9.3 | I21: 1.2 | J21: 3.0% | K21: 0.56 | L21: 5.7 | M21: 3.8 | N21: =IF(AND(ISNUMBER(I21),ISNUMBER(H21)),I21/H21,"") -> 0.12903226 | O21: =IF(AND(ISNUMBER(F21),ISNUMBER(P21),P21>0),F21/P21,"") -> 5.5932203 | P21: 590
A22: Edged (Edged Compute LLC) 7 1/2% Sec Notes due 4/30/2031 | B22: EDGCOM | C22: CoreWeave (Chicago) / Alibaba (Atlanta) | D22: =Monitor!H22 -> 87.946 | E22: =Monitor!J22 -> 10.899613 | F22: =Monitor!G22 -> 1300 | G22: 1633 | H22: 14.3 | I22: 1.71 | J22: 3.0% | K22: 0.71 | L22: 7.4 | M22: 6 | N22: =IF(AND(ISNUMBER(I22),ISNUMBER(H22)),I22/H22,"") -> 0.11958042 | O22: =IF(AND(ISNUMBER(F22),ISNUMBER(P22),P22>0),F22/P22,"") -> 11.403509 | P22: 114
