Workbook
Name DDR_Sufficiency: Model!$D$43
Name Required_Total_DRAM_WPM: Model!$D$45

Sheet Scenarios
A1: Scenario library — feeds the Model sheet
A3: Scenario | B3: ASML Low-NA capacity plan / ceiling, 2028 | C3: TSMC Low-NA allocation | D3: Intel Low-NA allocation | E3: Other logic allocation | F3: Total DRAM wafer capacity, 2028 | G3: Gross adds qualified by YE | H3: HBM bit demand, 2028 | I3: HBM demand served | J3: HBM output per wafer, 2028 | K3: DDR node-migration uplift | L3: DDR ex-HBM demand, 2028 | M3: Memory tools residual | N3: HBM wafer burden | O3: DDR supply | P3: DDR sufficiency
A4: Updated base | B4: 110 | C4: 50 | D4: 15 | E4: 5 | F4: 2480 | G4: 1 | H4: 109 | I4: 1 | J4: 8 | K4: 0.082 | L4: 528.5 | M4: =MAX(0,B4-C4-D4-E4) -> 40 | N4: =(H4*I4)/(J4*0.012) -> 1135.4167 | O4: =MAX(0,(2176+(F4-2176)*G4)-N4)*(22.72*(1+K4))*0.012 -> 396.64735 | P4: =O4/L4-1 -> -0.24948467
A5: Prior house | B5: 112 | C5: 45 | D5: 11 | E5: 5 | F5: 2480 | G5: 1 | H5: 80 | I5: 0.833 | J5: 8 | K5: 0.082 | L5: 528.5 | M5: =MAX(0,B5-C5-D5-E5) -> 51 | N5: =(H5*I5)/(J5*0.012) -> 694.16667 | O5: =MAX(0,(2176+(F5-2176)*G5)-N5)*(22.72*(1+K5))*0.012 -> 526.81455 | P5: =O5/L5-1 -> -0.0031891254
A6: HBM rationed | B6: 110 | C6: 50 | D6: 15 | E6: 5 | F6: 2480 | G6: 1 | H6: 109 | I6: 0.6 | J6: 8 | K6: 0.082 | L6: 528.5 | M6: =MAX(0,B6-C6-D6-E6) -> 40 | N6: =(H6*I6)/(J6*0.012) -> 681.25 | O6: =MAX(0,(2176+(F6-2176)*G6)-N6)*(22.72*(1+K6))*0.012 -> 530.62492 | P6: =O6/L6-1 -> 0.0040206592
A7: Supply bull | B7: 120 | C7: 45 | D7: 12 | E7: 5 | F7: 2700 | G7: 1 | H7: 109 | I7: 1 | J7: 10 | K7: 0.12 | L7: 510 | M7: =MAX(0,B7-C7-D7-E7) -> 58 | N7: =(H7*I7)/(J7*0.012) -> 908.33333 | O7: =MAX(0,(2176+(F7-2176)*G7)-N7)*(22.72*(1+K7))*0.012 -> 547.0976 | P7: =O7/L7-1 -> 0.072740392
A8: Custom

Sheet Model
A1: Memory supply / demand — DDR balance through 2028
A2: ASML allocation is a feasibility constraint; wafer capacity is modeled independently to avoid the circular wafers-per-tool conversion. | I2: 2028 DDR sufficiency | K2: HBM wafer burden | M2: HBM coverage at DDR balance
A3: =IF($D$43>=0,"YES — selected case: "&TEXT($D$43,"0.0%")&" DDR sufficiency.","NO — selected case: "&TEXT($D$43,"0.0%")&" DDR sufficiency.") -> NO — selected case: -25% DDR sufficiency. | I3: =D43 -> -0.24948467 | K3: =D38/D35 -> 0.4578293 | M3: =D48 -> 0.6063441
A5: Selected scenario | B5: Updated base | D5: Enter an Override; leave blank to use the selected scenario.
A7: Input | B7: Scenario value | C7: Override | D7: Active | E7: Unit | F7: Grounding | G7: Source / date
A8: ASML Low-NA capacity plan / ceiling, 2028 | B8: =IF($B$5="Custom","",INDEX(Scenarios!$B$4:$L$8,MATCH($B$5,Scenarios!$A$4:$A$8,0),1)) -> 110 | D8: =IF(ISNUMBER(C8),C8,B8) -> 110 | E8: tools | F8: HARD | G8: ASML Q2 call · 15 Jul 2026; capacity plan, realization PARTIAL
A9: TSMC Low-NA allocation | B9: =IF($B$5="Custom","",INDEX(Scenarios!$B$4:$L$8,MATCH($B$5,Scenarios!$A$4:$A$8,0),2)) -> 50 | D9: =IF(ISNUMBER(C9),C9,B9) -> 50 | E9: tools | F9: ESTIMATE | G9: 2027 40–45 booked: Redburn / Conor O’Mara · 23 Jun 2026
A10: Intel Low-NA allocation | B10: =IF($B$5="Custom","",INDEX(Scenarios!$B$4:$L$8,MATCH($B$5,Scenarios!$A$4:$A$8,0),3)) -> 15 | D10: =IF(ISNUMBER(C10),C10,B10) -> 15 | E10: tools | F10: ESTIMATE | G10: Orders +30–40%: KeyBanc / John Vinh · 24 Jul 2026; not EUV-specific
A11: Other Low-NA logic allocation | B11: =IF($B$5="Custom","",INDEX(Scenarios!$B$4:$L$8,MATCH($B$5,Scenarios!$A$4:$A$8,0),4)) -> 5 | D11: =IF(ISNUMBER(C11),C11,B11) -> 5 | E11: tools | F11: PARTIAL | G11: Bristlemoon · Jun 2026
A12: Total DRAM wafer capacity, 2028 | B12: =IF($B$5="Custom","",INDEX(Scenarios!$B$4:$L$8,MATCH($B$5,Scenarios!$A$4:$A$8,0),5)) -> 2480 | D12: =IF(ISNUMBER(C12),C12,B12) -> 2480 | E12: k wpm | F12: ESTIMATE | G12: Capstone prior-house default · 27 Jul 2026; no independent 2028 anchor
A13: Gross adds qualified by YE | B13: =IF($B$5="Custom","",INDEX(Scenarios!$B$4:$L$8,MATCH($B$5,Scenarios!$A$4:$A$8,0),6)) -> 1 | D13: =IF(ISNUMBER(C13),C13,B13) -> 1 | E13: % | F13: ESTIMATE | G13: Shipment → install → qualification; 100% supply-friendly
A14: HBM bit demand, 2028 | B14: =IF($B$5="Custom","",INDEX(Scenarios!$B$4:$L$8,MATCH($B$5,Scenarios!$A$4:$A$8,0),7)) -> 109 | D14: =IF(ISNUMBER(C14),C14,B14) -> 109 | E14: bn Gb | F14: PARTIAL | G14: Bernstein ≈109bn via Capstone · 27 Jul 2026; Bristlemoon 78.3bn · Jun 2026
A15: HBM demand served | B15: =IF($B$5="Custom","",INDEX(Scenarios!$B$4:$L$8,MATCH($B$5,Scenarios!$A$4:$A$8,0),8)) -> 1 | D15: =IF(ISNUMBER(C15),C15,B15) -> 1 | E15: % | F15: ESTIMATE | G15: Below 100% explicitly rations HBM
A16: HBM output per wafer, 2028 | B16: =IF($B$5="Custom","",INDEX(Scenarios!$B$4:$L$8,MATCH($B$5,Scenarios!$A$4:$A$8,0),9)) -> 8 | D16: =IF(ISNUMBER(C16),C16,B16) -> 8 | E16: kGb / wafer | F16: ESTIMATE | G16: Capstone physical engine · 27 Jul 2026
A17: DDR node-migration uplift | B17: =IF($B$5="Custom","",INDEX(Scenarios!$B$4:$L$8,MATCH($B$5,Scenarios!$A$4:$A$8,0),10)) -> 0.082 | D17: =IF(ISNUMBER(C17),C17,B17) -> 0.082 | E17: % | F17: ESTIMATE | G17: Capstone physical engine · 27 Jul 2026
A18: DDR ex-HBM demand, 2028 | B18: =IF($B$5="Custom","",INDEX(Scenarios!$B$4:$L$8,MATCH($B$5,Scenarios!$A$4:$A$8,0),11)) -> 528.5 | D18: =IF(ISNUMBER(C18),C18,B18) -> 528.5 | E18: bn Gb | F18: ESTIMATE | G18: Capstone physical engine · 27 Jul 2026
A20: Constants and independent anchors
A21: Constant / anchor | D21: Value | E21: Unit | F21: Grounding | G21: Source / date
A22: 2027 DRAM wafer capacity | D22: 2176 | E22: k wpm | F22: ANCHOR | G22: Capstone · 27 Jul 2026; UBS ≈2,170k · 3 Jul 2026
A23: DDR bits per wafer, 2027 | D23: 22.72 | E23: kGb / wafer | F23: ANCHOR | G23: Capstone · 27 Jul 2026
A24: Monthly-to-annual conversion | D24: 0.012 | E24: ×12 / 1,000 | F24: HARD | G24: Dimensional conversion
A25: Prior-case incremental DRAM EUV demand | D25: 51 | E25: tools | F25: PARTIAL | G25: Bristlemoon · Jun 2026; comparator only | I25: Year | J25: DDR supply | K25: DDR demand | L25: Sufficiency
A26: Independent HBM wafers, 2027 | D26: 668 | E26: k wpm | F26: HARD | G26: SemiAnalysis · 6 Feb 2026 | I26: 2025 | J26: 293 | K26: 306.3 | L26: -0.043
A27: Modeled HBM wafers, 2027 | D27: 690 | E27: k wpm | F27: ANCHOR | G27: Capstone · 27 Jul 2026 | I27: 2026E | J27: 352.7 | K27: 358.3 | L27: -0.016
A28: Independent total DRAM capacity, 2027 | D28: 2170 | E28: k wpm | F28: PARTIAL | G28: UBS / Nicolas Gaudois · 3 Jul 2026 | I28: 2027E | J28: 405.2 | K28: 474.5 | L28: -0.146
I29: 2028E | J29: =D41 -> 396.64735 | K29: =D18 -> 528.5 | L29: =D43 -> -0.24948467
A30: Selected-case arithmetic
A31: Step | D31: Value | E31: Unit | F31: Grounding | G31: Formula / interpretation
A32: Low-NA memory residual | D32: =MAX(0,D8-D9-D10-D11) -> 40 | E32: tools | F32: ESTIMATE | G32: ASML − TSMC − Intel − other
A33: Planned gross wafer add | D33: =D12-D22 -> 304 | E33: k wpm | F33: ESTIMATE | G33: 2028 total − 2027 anchor
A34: Qualified gross wafer add | D34: =D33*D13 -> 304 | E34: k wpm | F34: ESTIMATE | G34: Gross add × qualification
A35: Effective 2028 DRAM wafers | D35: =D22+D34 -> 2480 | E35: k wpm | F35: ESTIMATE | G35: 2027 anchor + qualified add
A36: HBM bits produced | D36: =D14*D15 -> 109 | E36: bn Gb | F36: ESTIMATE | G36: Demand × served share
A37: Unmet HBM demand | D37: =MAX(0,D14-D36) -> 0 | E37: bn Gb | F37: ESTIMATE | G37: Demand − produced
A38: HBM wafers required | D38: =D36/(D16*D24) -> 1135.4167 | E38: k wpm | F38: ESTIMATE | G38: HBM bits ÷ (density × .012)
A39: DDR wafers remaining | D39: =MAX(0,D35-D38) -> 1344.5833 | E39: k wpm | F39: ESTIMATE | G39: Total − HBM wafers
A40: DDR bits per wafer | D40: =D23*(1+D17) -> 24.58304 | E40: kGb / wafer | F40: ESTIMATE | G40: 2027 density × (1 + node)
A41: DDR supply | D41: =D39*D40*D24 -> 396.64735 | E41: bn Gb | F41: ESTIMATE | G41: DDR wpm × density × .012
A42: DDR gap | D42: =D41-D18 -> -131.85265 | E42: bn Gb | F42: ESTIMATE | G42: Supply − demand
A43: DDR sufficiency | D43: =D42/D18 -> -0.24948467 | E43: % | F43: ESTIMATE | G43: Gap ÷ demand
...

Sheet Sensitivity
A1: Sensitivity around the selected case
A2: TSMC and Intel change Low-NA feasibility, not wafer capacity.
A3: Input | B3: Low assumption | C3: Low output | D3: Selected | E3: Selected output | F3: High assumption | G3: High output | H3: Output basis
A4: HBM demand | B4: 90 | C4: =MAX(0,(Model!$D$22+(Model!$D$12-Model!$D$22)*Model!$D$13)-((B4*Model!$D$15)/(Model!$D$16*Model!$D$24)))*(Model!$D$23*(1+Model!$D$17))*Model!$D$24/Model!$D$18-1 -> -0.13901217 | D4: =Model!$D$14 -> 109 | E4: =MAX(0,(Model!$D$22+(Model!$D$12-Model!$D$22)*Model!$D$13)-((D4*Model!$D$15)/(Model!$D$16*Model!$D$24)))*(Model!$D$23*(1+Model!$D$17))*Model!$D$24/Model!$D$18-1 -> -0.24948467 | F4: 120 | G4: =MAX(0,(Model!$D$22+(Model!$D$12-Model!$D$22)*Model!$D$13)-((F4*Model!$D$15)/(Model!$D$16*Model!$D$24)))*(Model!$D$23*(1+Model!$D$17))*Model!$D$24/Model!$D$18-1 -> -0.31344244 | H4: DDR sufficiency
A5: Total DRAM wafers | B5: 2300 | C5: =MAX(0,(Model!$D$22+(B5-Model!$D$22)*Model!$D$13)-((Model!$D$14*Model!$D$15)/(Model!$D$16*Model!$D$24)))*(Model!$D$23*(1+Model!$D$17))*Model!$D$24/Model!$D$18-1 -> -0.34995651 | D5: =Model!$D$12 -> 2480 | E5: =MAX(0,(Model!$D$22+(D5-Model!$D$22)*Model!$D$13)-((Model!$D$14*Model!$D$15)/(Model!$D$16*Model!$D$24)))*(Model!$D$23*(1+Model!$D$17))*Model!$D$24/Model!$D$18-1 -> -0.24948467 | F5: 2800 | G5: =MAX(0,(Model!$D$22+(F5-Model!$D$22)*Model!$D$13)-((Model!$D$14*Model!$D$15)/(Model!$D$16*Model!$D$24)))*(Model!$D$23*(1+Model!$D$17))*Model!$D$24/Model!$D$18-1 -> -0.070868072 | H5: DDR sufficiency
A6: Gross adds qualified | B6: 0.7 | C6: =MAX(0,(Model!$D$22+(Model!$D$12-Model!$D$22)*B6)-((Model!$D$14*Model!$D$15)/(Model!$D$16*Model!$D$24)))*(Model!$D$23*(1+Model!$D$17))*Model!$D$24/Model!$D$18-1 -> -0.3003904 | D6: =Model!$D$13 -> 1 | E6: =MAX(0,(Model!$D$22+(Model!$D$12-Model!$D$22)*D6)-((Model!$D$14*Model!$D$15)/(Model!$D$16*Model!$D$24)))*(Model!$D$23*(1+Model!$D$17))*Model!$D$24/Model!$D$18-1 -> -0.24948467 | F6: 1 | G6: =MAX(0,(Model!$D$22+(Model!$D$12-Model!$D$22)*F6)-((Model!$D$14*Model!$D$15)/(Model!$D$16*Model!$D$24)))*(Model!$D$23*(1+Model!$D$17))*Model!$D$24/Model!$D$18-1 -> -0.24948467 | H6: DDR sufficiency
A7: TSMC Low-NA allocation | B7: 45 | C7: =MAX(0,Model!$D$8-B7-Model!$D$10-Model!$D$11) -> 45 | D7: =Model!$D$9 -> 50 | E7: =Model!$D$32 -> 40 | F7: 55 | G7: =MAX(0,Model!$D$8-F7-Model!$D$10-Model!$D$11) -> 35 | H7: Memory tools residual
A8: Intel Low-NA allocation | B8: 8 | C8: =MAX(0,Model!$D$8-Model!$D$9-B8-Model!$D$11) -> 47 | D8: =Model!$D$10 -> 15 | E8: =Model!$D$32 -> 40 | F8: 20 | G8: =MAX(0,Model!$D$8-Model!$D$9-F8-Model!$D$11) -> 35 | H8: Memory tools residual
A9: Node uplift | B9: 0.05 | C9: =MAX(0,(Model!$D$22+(Model!$D$12-Model!$D$22)*Model!$D$13)-((Model!$D$14*Model!$D$15)/(Model!$D$16*Model!$D$24)))*(Model!$D$23*(1+B9))*Model!$D$24/Model!$D$18-1 -> -0.27168106 | D9: =Model!$D$17 -> 0.082 | E9: =MAX(0,(Model!$D$22+(Model!$D$12-Model!$D$22)*Model!$D$13)-((Model!$D$14*Model!$D$15)/(Model!$D$16*Model!$D$24)))*(Model!$D$23*(1+D9))*Model!$D$24/Model!$D$18-1 -> -0.24948467 | F9: 0.12 | G9: =MAX(0,(Model!$D$22+(Model!$D$12-Model!$D$22)*Model!$D$13)-((Model!$D$14*Model!$D$15)/(Model!$D$16*Model!$D$24)))*(Model!$D$23*(1+F9))*Model!$D$24/Model!$D$18-1 -> -0.22312646 | H9: DDR sufficiency
A10: HBM density | B10: 7 | C10: =MAX(0,(Model!$D$22+(Model!$D$12-Model!$D$22)*Model!$D$13)-((Model!$D$14*Model!$D$15)/(B10*Model!$D$24)))*(Model!$D$23*(1+Model!$D$17))*Model!$D$24/Model!$D$18-1 -> -0.34002229 | D10: =Model!$D$16 -> 8 | E10: =MAX(0,(Model!$D$22+(Model!$D$12-Model!$D$22)*Model!$D$13)-((Model!$D$14*Model!$D$15)/(D10*Model!$D$24)))*(Model!$D$23*(1+Model!$D$17))*Model!$D$24/Model!$D$18-1 -> -0.24948467 | F10: 10 | G10: =MAX(0,(Model!$D$22+(Model!$D$12-Model!$D$22)*Model!$D$13)-((Model!$D$14*Model!$D$15)/(F10*Model!$D$24)))*(Model!$D$23*(1+Model!$D$17))*Model!$D$24/Model!$D$18-1 -> -0.12273201 | H10: DDR sufficiency
A11: HBM served | B11: 0.6 | C11: =MAX(0,(Model!$D$22+(Model!$D$12-Model!$D$22)*Model!$D$13)-((Model!$D$14*B11)/(Model!$D$16*Model!$D$24)))*(Model!$D$23*(1+Model!$D$17))*Model!$D$24/Model!$D$18-1 -> 0.0040206592 | D11: =Model!$D$15 -> 1 | E11: =MAX(0,(Model!$D$22+(Model!$D$12-Model!$D$22)*Model!$D$13)-((Model!$D$14*D11)/(Model!$D$16*Model!$D$24)))*(Model!$D$23*(1+Model!$D$17))*Model!$D$24/Model!$D$18-1 -> -0.24948467 | F11: 1 | G11: =MAX(0,(Model!$D$22+(Model!$D$12-Model!$D$22)*Model!$D$13)-((Model!$D$14*F11)/(Model!$D$16*Model!$D$24)))*(Model!$D$23*(1+Model!$D$17))*Model!$D$24/Model!$D$18-1 -> -0.24948467 | H11: DDR sufficiency
A12: DDR demand | B12: 500 | C12: =MAX(0,(Model!$D$22+(Model!$D$12-Model!$D$22)*Model!$D$13)-((Model!$D$14*Model!$D$15)/(Model!$D$16*Model!$D$24)))*(Model!$D$23*(1+Model!$D$17))*Model!$D$24/B12-1 -> -0.2067053 | D12: =Model!$D$18 -> 528.5 | E12: =MAX(0,(Model!$D$22+(Model!$D$12-Model!$D$22)*Model!$D$13)-((Model!$D$14*Model!$D$15)/(Model!$D$16*Model!$D$24)))*(Model!$D$23*(1+Model!$D$17))*Model!$D$24/D12-1 -> -0.24948467 | F12: 560 | G12: =MAX(0,(Model!$D$22+(Model!$D$12-Model!$D$22)*Model!$D$13)-((Model!$D$14*Model!$D$15)/(Model!$D$16*Model!$D$24)))*(Model!$D$23*(1+Model!$D$17))*Model!$D$24/F12-1 -> -0.29170116 | H12: DDR sufficiency

Sheet Checks & Sources
A1: Guardrails, provenance and skeptic verdict
A2: Verdict: PARTIAL — directional, not precise; 2028 capacity, qualification and tool allocation remain unvalidated.
A4: Guardrail | B4: Model | C4: Independent | D4: Variance | E4: Basis | F4: Status | G4: Why it matters
A5: 2027 HBM wafer level | B5: =Model!$D$27 -> 690 | C5: =Model!$D$26 -> 668 | D5: =B5/C5-1 -> 0.032934132 | E5: k wpm stock | F5: PASS | G5: Independent SemiAnalysis level; <25% variance
A6: 2027 total DRAM capacity | B6: =Model!$D$22 -> 2176 | C6: =Model!$D$28 -> 2170 | D6: =B6/C6-1 -> 0.002764977 | E6: k wpm stock | F6: PASS | G6: Independent UBS vendor sum
A7: 2028 total DRAM capacity | B7: =Model!$D$35 -> 2480 | C7: n/a | D7: n/a | E7: k wpm stock | F7: UNVALIDATED | G7: No independent 2028 anchor
A8: Low-NA memory flow | B8: =Model!$D$32 -> 40 | C8: =Model!$D$25 -> 51 | D8: =B8/C8-1 -> -0.21568627 | E8: tools/year flow | F8: WATCH | G8: Prior case comparator, not validation
A9: HBM demand cross-source | B9: =Model!$D$14 -> 109 | C9: 78.3 | D9: =B9/C9-1 -> 0.39208174 | E9: bn Gb/year | F9: WATCH | G9: 109bn Bernstein vs 78.3bn Bristlemoon; prior-house 80bn is shown separately in Scenarios
A10: Low-NA / High-NA split | B10: Low-NA only | C10: n/a | D10: n/a | E10: tool-flow | F10: UNVALIDATED | G10: High-NA timing not converted
A11: Qualification timing | B11: =Model!$D$13 -> 1 | C11: n/a | D11: n/a | E11: share by YE | F11: UNVALIDATED | G11: No install/qualification curve
A14: Source ledger
A15: Datapoint | B15: Value | C15: Grounding | D15: Source | E15: Analyst | F15: Date | G15: Use
A16: ASML 2028 Low-NA plan | B16: 110 tools | C16: HARD | D16: ASML Q2 call | E16: Company | F16: 15 Jul 2026 | G16: Feasibility ceiling; realization PARTIAL
A17: TSMC 2027 EUV bookings | B17: 40–45 | C17: PARTIAL | D17: Redburn | E17: Conor O’Mara | F17: 23 Jun 2026 | G17: 2028 allocation 50 is ESTIMATE
A18: Intel equipment orders | B18: +30–40% | C18: PARTIAL | D18: KeyBanc via Semiecosystem | E18: John Vinh | F18: 24 Jul 2026 | G18: Not EUV-specific
A19: Prior 2028 allocation | B19: 112 total; TSMC45; Intel11; DRAM51 | C19: PARTIAL | D19: Bristlemoon EUV model | E19: Bristlemoon | F19: Jun 2026 | G19: Prior comparator
A20: HBM demand 2028 | B20: 78.3bn Gb | C20: PARTIAL | D20: Bristlemoon EUV model | E20: Bristlemoon | F20: Jun 2026 | G20: Lower case
A21: HBM demand 2028 | B21: ≈109bn Gb | C21: PARTIAL | D21: Bernstein via Capstone | E21: Bernstein | F21: 27 Jul 2026 | G21: Updated high-XPU case
A22: Total DRAM 2027 | B22: ≈2,170k wpm | C22: PARTIAL | D22: UBS Memory Semis Monthly | E22: Nicolas Gaudois | F22: 3 Jul 2026 | G22: Independent level
A23: HBM capacity 2027 | B23: 668k wpm | C23: HARD | D23: SemiAnalysis | E23: SemiAnalysis | F23: 6 Feb 2026 | G23: Independent level
A24: Capstone engine | B24: 2,176k/2,480k wpm; 528.5bn Gb DDR | C24: ESTIMATE | D24: Memory dashboard | E24: Capstone | F24: 27 Jul 2026 | G24: Core assumptions
