Workbook

Sheet Summary
A1: New Street Research “$4tn AI capex in 2030” (18-Sep-2026) vs Capstone — summary
A2: NSR (Pierre Ferragu, Antoine Chkaiban, Benjamin Harwood, Peter Vogel) raised its 2030 AI capex forecast from ~$3.1tn to $4.15tn. This workbook transcribes the note with live formulas (NSR_* sheets), lays the Capstone series beside it (House) and compares them line by line (Comparison). This page links to those cells.
A4: WHAT NSR SAYS
A5: • $4.15tn of AI infrastructure capex in 2030 (from $584bn in 2025, 48% CAGR): XPUs $1.70tn (41%), other equipment & buildings $1.02tn (24%), networking $465bn, DRAM & NAND $423bn, other server content $373bn, CPUs $168bn. Increase is volume-driven; ~275 GW of installed AI capacity in 2030 (from ~225 GW).
A6: • Memory share of AI infrastructure keeps rising even as prices normalise: HBM $560bn in 2030 (33% of XPU spend, GM ~76%), DRAM $241bn, NAND $182bn.
A7: • Hyperscalers: group capex $8.7tn cumulative 2026-30, FCF negative through 2029 (trough −$486bn in 2028), positive again in 2030; OCF $8.0tn vs consensus $6tn on a 24% revenue CAGR and 77% incremental OCF margin.
A8: • Funding: $16.5tn of datacenter capex 2026-30, >75% covered by hyperscaler / tier-2 / neocloud OCF and enterprise self-funding; ~$3.7tn (23%) needs external financing, mostly neoclouds with hyperscaler guarantees; industry leverage ~2.2x 2027 EBITDA.
A10: KEY READS — NSR vs Capstone
A11: 1. Level: NSR is above the house on total AI capex in every year — $584bn vs $396bn in 2025 (+47%), $1,132 vs $902 (2026), $2,190 vs $1,885 (2027), $3,330 vs $2,913 (2028, +14%). The gap narrows because the house grows faster in 2026-27 (+128% / +109% vs NSR +94% / +93%).
A12: 2. 2030: NSR $4.15tn vs the house's July-vintage extension $3.48tn (−16%). Re-based on the current CY28 ($2,913bn) the same growth path gives ~$3.9tn — within ~6% of NSR. The house has no modeled CY29-30 on the current base.
A13: 3. Mix: the house puts more into accelerators (48% → 40% of capex) than NSR (35% → 41%); NSR puts more into shell/buildings early (44% in 2025 vs 36%) and less later (27% vs 36% in 2028). Capex per GW converges on ~$42bn by 2028 (NSR $40-45bn; house $30.5 → $41.9bn).
A14: 4. Memory is the biggest dollar disagreement: HBM 2030 NSR $560bn vs house repriced $283bn (BofA $168bn) — the two agree in 2027 (~$190bn) and diverge after, as NSR keeps HBM compounding at 22-38% into 2029-30 where the house fades price. Ex-HBM DRAM+NAND agree within 6% (2027) and 4% (2030).
... A21: HEADLINE TABLE — 2028 and 2030 (linked to the Comparison sheet; blue Δ = Capstone above NSR, red = below)
A22: Metric | B22: Unit | C22: NSR 2028 | D22: Capstone 2028 | E22: Δ 2028 | F22: NSR 2030 | G22: Capstone 2030 | H22: Δ 2030 | I22: Read
A23: Total AI capex | B23: $bn | C23: =IF(Comparison!F6="","",Comparison!F6) -> 3330 | D23: =IF(Comparison!F7="","",Comparison!F7) -> 2913.1 | E23: =IF(Comparison!F8="","",Comparison!F8) -> -0.1251952 | F23: =IF(Comparison!H6="","",Comparison!H6) -> 4150 | G23: =IF(Comparison!H7="","",Comparison!H7) -> 3481.9 | H23: =IF(Comparison!H8="","",Comparison!H8) -> -0.16098795 | I23: Capstone 2030 is a July-vintage extension; re-based ~$3.9tn.
A24: XPUs / accelerators | B24: $bn | C24: =IF(Comparison!F32="","",Comparison!F32) -> 1252 | D24: =IF(Comparison!F33="","",Comparison!F33) -> 1157.4 | E24: =IF(Comparison!F34="","",Comparison!F34) -> -0.075559105 | F24: =IF(Comparison!H32="","",Comparison!H32) -> 1702 | G24: =IF(Comparison!H33="","",Comparison!H33) -> 1414.2 | H24: =IF(Comparison!H34="","",Comparison!H34) -> -0.16909518 | I24: House chips = designers' revenue incl. HBM.
A25: HBM (Semis MAP repriced) | B25: $bn | C25: =IF(Comparison!F73="","",Comparison!F73) -> 332 | D25: =IF(Comparison!F74="","",Comparison!F74) -> 224 | E25: =IF(Comparison!F75="","",Comparison!F75) -> -0.3253012 | F25: =IF(Comparison!H73="","",Comparison!H73) -> 560 | G25: =IF(Comparison!H74="","",Comparison!H74) -> 283.4 | H25: =IF(Comparison!H75="","",Comparison!H75) -> -0.49392857 | I25: The largest dollar gap; agree in 2027, diverge after.
A26: DRAM ex-HBM + NAND | B26: $bn | C26: =IF(Comparison!F81="","",Comparison!F81) -> 459 | D26: =IF(Comparison!F82="","",Comparison!F82) -> 345.8 | E26: =IF(Comparison!F83="","",Comparison!F83) -> -0.24662309 | F26: =IF(Comparison!H81="","",Comparison!H81) -> 423 | G26: =IF(Comparison!H82="","",Comparison!H82) -> 404.9 | H26: =IF(Comparison!H83="","",Comparison!H83) -> -0.042789598 | I26: Close in 2027 and 2030; house lower in 2028.
A27: Total memory (HBM + DRAM + NAND) | B27: $bn | C27: =IF(Comparison!F89="","",Comparison!F89) -> 791 | D27: =IF(Comparison!F90="","",Comparison!F90) -> 596.5 | E27: =IF(Comparison!F91="","",Comparison!F91) -> -0.24589128 | F27: =IF(Comparison!H89="","",Comparison!H89) -> 983 | G27: =IF(Comparison!H90="","",Comparison!H90) -> 737 | H27: =IF(Comparison!H91="","",Comparison!H91) -> -0.25025432 | I27: House TOTAL CSP memory bill vs NSR sum.
A28: Networking | B28: $bn | C28: =IF(Comparison!F52="","",Comparison!F52) -> 336 | D28: =IF(Comparison!F53="","",Comparison!F53) -> 450.7 | E28: =IF(Comparison!F54="","",Comparison!F54) -> 0.34136905 | F28: =IF(Comparison!H52="","",Comparison!H52) -> 465 | G28: =IF(Comparison!H53="","",Comparison!H53) -> 606.3 | H28: =IF(Comparison!H54="","",Comparison!H54) -> 0.30387097 | I28: Semis MAP line; Bottom_Up build is ~0.65x NSR.
A29: Hyperscaler capex (total) | B29: $bn | C29: =IF(Comparison!F123="","",Comparison!F123) -> 1975 | D29: =IF(Comparison!F124="","",Comparison!F124) -> 1463.3 | E29: =IF(Comparison!F125="","",Comparison!F125) -> -0.25908861 | I29: NSR basket not enumerated; house = big-4 calendar.
A30: Hyperscaler FCF | B30: $bn | C30: =IF(Comparison!F127="","",Comparison!F127) -> -486 | D30: =IF(Comparison!F128="","",Comparison!F128) -> -261.4 | E30: =IF(Comparison!F129="","",Comparison!F129) -> -0.46213992 | I30: House trough earlier and shallower.
A31: AI cloud revenue | B31: $bn | C31: =IF(Comparison!F136="","",Comparison!F136) -> 651 | D31: =IF(Comparison!F137="","",Comparison!F137) -> 627.1 | E31: =IF(Comparison!F138="","",Comparison!F138) -> -0.03671275 | F31: =IF(Comparison!H136="","",Comparison!H136) -> 1511 | G31: =IF(Comparison!H137="","",Comparison!H137) -> 1492 | H31: =IF(Comparison!H138="","",Comparison!H138) -> -0.012574454 | I31: Strongest convergence in the note.
A32: Installed AI GW (chip-content basis) | B32: GW | F32: =IF(Comparison!H98="","",Comparison!H98) -> 275 | G32: =IF(Comparison!H99="","",Comparison!H99) -> 298.7 | H32: =IF(Comparison!H100="","",Comparison!H100) -> 0.086181818 | I32: NSR basis unstated; house chip GW, gross of retirements.
A33: Installed AI GW (facility basis) | B33: GW | F33: =IF(Comparison!H102="","",Comparison!H102) -> 275 | G33: =IF(Comparison!H103="","",Comparison!H103) -> 241.7 | H33: =IF(Comparison!H104="","",Comparison!H104) -> -0.12109091 | I33: Bottom_Up physical facility GW.
A34: Capex per GW | B34: $bn/GW | C34: =IF(Comparison!F110="","",Comparison!F110) -> 42.5 | D34: =IF(Comparison!F111="","",Comparison!F111) -> 41.9 | E34: =IF(Comparison!F112="","",Comparison!F112) -> -0.014117647 | I34: Converging on ~$42bn by 2028.
A36: VENDOR MARKET SHARES ON THE NSR POOLS — 2028 and 2030 (linked to Share_XPU / Share_CPU / Share_Memory; implied $bn = NSR pool × share)
A37: Not additive across blocks: HBM dollars sit inside the XPU figures AND appear as vendor HBM revenue below (NSR p.5 puts HBM inside XPU spending) — summing NVIDIA/Broadcom with SK Hynix/Samsung/Micron double-counts $332bn in 2028 and $560bn in 2030. Capstone-mix shares are house forecasts (EST), not market prints; CY29-30 sit on the July base.
A38: Pool — vendor | C38: Share 2028 | D38: $bn 2028 | F38: Share 2030 | G38: $bn 2030 | I38: Share lens / basis
A39: XPU — NVIDIA | C39: =IF(Share_XPU!F20="","",Share_XPU!F20) -> 0.67732181 | D39: =IF(Share_XPU!F36="","",Share_XPU!F36) -> 848.00691 | F39: =IF(Share_XPU!H20="","",Share_XPU!H20) -> 0.63635721 | G39: =IF(Share_XPU!H36="","",Share_XPU!H36) -> 1083.08 | I39: Capstone designer mix (AI Model CY28; Semis MAP CY30 — the CY28→29 share step is a vintage splice). NSR itself has ~60% in 2030, BofA 68%.
A40: XPU — Broadcom (custom ASIC) | C40: =IF(Share_XPU!F21="","",Share_XPU!F21) -> 0.24587473 | D40: =IF(Share_XPU!F37="","",Share_XPU!F37) -> 307.83516 | F40: =IF(Share_XPU!H21="","",Share_XPU!H21) -> 0.27872446 | G40: =IF(Share_XPU!H37="","",Share_XPU!H37) -> 474.38903 | I40: Capstone mix; BofA 16% in 2030. On NSR's pool this implies more Broadcom revenue than NSR's own $230bn FY28 Broadcom datapoint — see Share_XPU guardrail.
A41: XPU — AMD | C41: =IF(Share_XPU!F22="","",Share_XPU!F22) -> 0.04475162 | D41: =IF(Share_XPU!F38="","",Share_XPU!F38) -> 56.029028 | F41: =IF(Share_XPU!H22="","",Share_XPU!H22) -> 0.048575267 | G41: =IF(Share_XPU!H38="","",Share_XPU!H38) -> 82.675104 | I41: Capstone mix; BofA ~7% in 2030.
A42: XPU — NVIDIA at NSR’s own 60% (2030 only) | C42: =IF(Share_XPU!F29="","",Share_XPU!F29) | D42: =IF(Share_XPU!F42="","",Share_XPU!F42) | F42: =IF(Share_XPU!H29="","",Share_XPU!H29) -> 0.6 | G42: =IF(Share_XPU!H42="","",Share_XPU!H42) -> 1021.2 | I42: NSR p.3: ~$1.0tn of NVIDIA XPU revenue in 2030.
A43: Server CPU — Intel | C43: =IF(Share_CPU!F47="","",Share_CPU!F47) -> 0.32902468 | D43: =IF(Share_CPU!F53="","",Share_CPU!F53) -> 38.495887 | F43: =IF(Share_CPU!H47="","",Share_CPU!H47) -> 0.3093679 | G43: =IF(Share_CPU!H53="","",Share_CPU!H53) -> 62.492316 | I43: Silicon anchor build applied to NSR's total CPU pool: Intel on BofA's printed path ($14.1bn CY25 → $46.3bn CY30E).
A44: Server CPU — AMD | C44: =IF(Share_CPU!F48="","",Share_CPU!F48) -> 0.28397963 | D44: =IF(Share_CPU!F54="","",Share_CPU!F54) -> 33.225617 | F44: =IF(Share_CPU!H48="","",Share_CPU!H48) -> 0.33409061 | G44: =IF(Share_CPU!H54="","",Share_CPU!H54) -> 67.486302 | I44: Segment prints to 2026, UBS 05-21 on its own TAM in 2030 (29% × $173bn ≈ $50bn); AMD's own target is >50% of $220bn.
A45: Server CPU — NVIDIA (Grace/Vera) | C45: =IF(Share_CPU!F49="","",Share_CPU!F49) -> 0.23893459 | D45: =IF(Share_CPU!F55="","",Share_CPU!F55) -> 27.955347 | F45: =IF(Share_CPU!H49="","",Share_CPU!H49) -> 0.15769077 | G45: =IF(Share_CPU!H55="","",Share_CPU!H55) -> 31.853535 | I45: CHIP basis: Bernstein units × $4k ASP (≈ Grace TTM >$5bn in 2025). Management's ‘$20bn demand / more than double in FY28’ is a systems-basis reading, kept as a scenario.
A46: Server CPU — captive Arm + Hygon + others | C46: =IF(Share_CPU!F50="","",Share_CPU!F50) -> 0.1480611 | D46: =IF(Share_CPU!F56="","",Share_CPU!F56) -> 17.323149 | F46: =IF(Share_CPU!H50="","",Share_CPU!H50) -> 0.19885073 | G46: =IF(Share_CPU!H56="","",Share_CPU!H56) -> 40.167847 | I46: Bernstein units × ~$1.2k EST (±$0.5k moves the line ±42%).
A47: HBM — SK Hynix | C47: =IF(Share_Memory!F18="","",Share_Memory!F18) -> 0.42 | D47: =IF(Share_Memory!F50="","",Share_Memory!F50) -> 139.44 | F47: =IF(Share_Memory!H18="","",Share_Memory!H18) -> 0.42 | G47: =IF(Share_Memory!H50="","",Share_Memory!H50) -> 235.2 | I47: JPM SALES-share path (60% → 42% by 2028) held at 2028; if JPM's −6pp/yr slope continues, 30% / $168bn in 2030 (Share_Memory scenario). Capstone Semis MAP has 47% in 2028.
A48: HBM — Samsung | C48: =IF(Share_Memory!F19="","",Share_Memory!F19) -> 0.38 | D48: =IF(Share_Memory!F51="","",Share_Memory!F51) -> 126.16 | F48: =IF(Share_Memory!H19="","",Share_Memory!H19) -> 0.38 | G48: =IF(Share_Memory!H51="","",Share_Memory!H51) -> 212.8 | I48: JPM 20% → 38% held; slope-continued 50% / $280bn in 2030. UBS's ‘41% in 2027’ is a BIT share. Capstone 28%.
A49: HBM — Micron | C49: =IF(Share_Memory!F20="","",Share_Memory!F20) -> 0.2 | D49: =IF(Share_Memory!F52="","",Share_Memory!F52) -> 66.4 | F49: =IF(Share_Memory!H20="","",Share_Memory!H20) -> 0.2 | G49: =IF(Share_Memory!H52="","",Share_Memory!H52) -> 112 | I49: JPM ~20% flat; Capstone 25%; UBS 20-21% (bits).
...

Sheet Comparison
A1: NSR (18-Sep-2026) vs Capstone — side by side, 2025-2030
A2: Each metric has three rows: NSR (linked from the NSR sheets) / Capstone (linked from House) / Δ = Capstone ÷ NSR − 1 (blue = Capstone above NSR, red = below). Capstone CY29-30 come from July-vintage extensions (stale base) or are blank. Read the basis note before quoting a delta.
A4: Metric | B4: Series | C4: 2025 | D4: 2026 | E4: 2027 | F4: 2028 | G4: 2029 | H4: 2030 | I4: Basis / how to read
A5: 1. THE HEADLINE — total AI capex, all buyers
A6: Total AI capex ($bn) | B6: NSR | C6: =IF(NSR_Capex!C12="","",NSR_Capex!C12) -> 584 | D6: =IF(NSR_Capex!D12="","",NSR_Capex!D12) -> 1132 | E6: =IF(NSR_Capex!E12="","",NSR_Capex!E12) -> 2190 | F6: =IF(NSR_Capex!F12="","",NSR_Capex!F12) -> 3330 | G6: =IF(NSR_Capex!G12="","",NSR_Capex!G12) -> 3810 | H6: =IF(NSR_Capex!H12="","",NSR_Capex!H12) -> 4150 | I6: NSR p.4 total (all buyers). Capstone CY25-28 = AI Model Capex Total (31-Aug, all players); CY29-30 = Semis MAP v11 scenario extension on the JULY base (CY28 2,588 vs current 2,913) — re-based on the current CY28 the CY29-30 house path would be ~$3.4tn / ~$3.9tn. Read: NSR is ABOVE the house in every year — +47% in 2025 ($584bn vs $396bn), narrowing to +14% in 2028 ($3,330bn vs $2,913bn) because the house grows faster in 2026-27. In 2030 NSR $4.15tn vs the stale house extension $3.48tn (−16%); on the re-based ~$3.9tn the gap is ~6%.
B7: Capstone | C7: =IF(House!E6="","",House!E6) -> 396.3 | D7: =IF(House!F6="","",House!F6) -> 901.6 | E7: =IF(House!G6="","",House!G6) -> 1885.4 | F7: =IF(House!H6="","",House!H6) -> 2913.1 | G7: =IF(House!I28="","",House!I28) -> 3054.3 | H7: =IF(House!J28="","",House!J28) -> 3481.9
B8: Δ Capstone vs NSR | C8: =IF(OR(C6="",C7=""),"",IFERROR(C7/C6-1,"")) -> -0.32140411 | D8: =IF(OR(D6="",D7=""),"",IFERROR(D7/D6-1,"")) -> -0.20353357 | E8: =IF(OR(E6="",E7=""),"",IFERROR(E7/E6-1,"")) -> -0.13908676 | F8: =IF(OR(F6="",F7=""),"",IFERROR(F7/F6-1,"")) -> -0.1251952 | G8: =IF(OR(G6="",G7=""),"",IFERROR(G7/G6-1,"")) -> -0.19834646 | H8: =IF(OR(H6="",H7=""),"",IFERROR(H7/H6-1,"")) -> -0.16098795
A10: Total AI capex — y/y growth | B10: NSR | C10: =IF(NSR_Capex!C22="","",NSR_Capex!C22) | D10: =IF(NSR_Capex!D22="","",NSR_Capex!D22) -> 0.93996569 | E10: =IF(NSR_Capex!E22="","",NSR_Capex!E22) -> 0.93899204 | F10: =IF(NSR_Capex!F22="","",NSR_Capex!F22) -> 0.51801186 | G10: =IF(NSR_Capex!G22="","",NSR_Capex!G22) -> 0.14328627 | H10: =IF(NSR_Capex!H22="","",NSR_Capex!H22) -> 0.089595376 | I10: House 2026 +128% / 2027 +109% / 2028 +54% vs NSR +94% / +93% / +52% / +14% / +9%. Same 2028 deceleration; house 2027 is the steeper year.
B11: Capstone | C11: =IF(House!E11="","",House!E11) -> 0.69431381 | D11: =IF(House!F11="","",House!F11) -> 1.2750442 | E11: =IF(House!G11="","",House!G11) -> 1.0911713 | F11: =IF(House!H11="","",House!H11) -> 0.54508327
B12: Δ Capstone vs NSR | C12: =IF(OR(C10="",C11=""),"",IFERROR(C11/C10-1,"")) | D12: =IF(OR(D10="",D11=""),"",IFERROR(D11/D10-1,"")) -> 0.35647946 | E12: =IF(OR(E10="",E11=""),"",IFERROR(E11/E10-1,"")) -> 0.16206656 | F12: =IF(OR(F10="",F11=""),"",IFERROR(F11/F10-1,"")) -> 0.052260224 | G12: =IF(OR(G10="",G11=""),"",IFERROR(G11/G10-1,"")) | H12: =IF(OR(H10="",H11=""),"",IFERROR(H11/H10-1,""))
A14: Cumulative AI capex ($bn) — NSR 2026-30 in the 2030 column; Capstone 2026-28 in the 2028 column | B14: NSR | H14: =IF(NSR_Capex!H36="","",NSR_Capex!H36) -> 14606 | I14: NSR 2026-30 cumulative $14.6tn AI (inside a $16.5tn total DC figure). House 2026-28 alone = $5.7tn on the current model (NSR 2026-28 = $6.65tn). No house cumulative to 2030 on the current base.
B15: Capstone | F15: =IF(House!H23="","",House!H23) -> 5700.1
B16: Δ Capstone vs NSR | C16: =IF(OR(C14="",C15=""),"",IFERROR(C15/C14-1,"")) | D16: =IF(OR(D14="",D15=""),"",IFERROR(D15/D14-1,"")) | E16: =IF(OR(E14="",E15=""),"",IFERROR(E15/E14-1,"")) | F16: =IF(OR(F14="",F15=""),"",IFERROR(F15/F14-1,"")) | G16: =IF(OR(G14="",G15=""),"",IFERROR(G15/G14-1,"")) | H16: =IF(OR(H14="",H15=""),"",IFERROR(H15/H14-1,""))
A18: 2. WHO SPENDS — hyperscalers vs the rest
A19: Hyperscaler capex, total incl. non-AI ($bn) | B19: NSR | C19: =IF(NSR_HyperPL!C33="","",NSR_HyperPL!C33) -> 415 | D19: =IF(NSR_HyperPL!D33="","",NSR_HyperPL!D33) -> 795 | E19: =IF(NSR_HyperPL!E33="","",NSR_HyperPL!E33) -> 1384 | F19: =IF(NSR_HyperPL!F33="","",NSR_HyperPL!F33) -> 1975 | G19: =IF(NSR_HyperPL!G33="","",NSR_HyperPL!G33) -> 2181 | H19: =IF(NSR_HyperPL!H33="","",NSR_HyperPL!H33) -> 2387 | I19: NSR p.7 group capex, basket not enumerated. Capstone = MSFT+AMZN+GOOG+META official models (calendar). NSR 2027 $1,384bn vs house big-4 $1,098bn: NSR is ~26% above on a basket that probably includes ORCL and possibly others.
B20: Capstone | C20: =IF(House!E20="","",House!E20) -> 410.1 | D20: =IF(House!F20="","",House!F20) -> 738.9 | E20: =IF(House!G20="","",House!G20) -> 1097.8 | F20: =IF(House!H20="","",House!H20) -> 1425.1
B21: Δ Capstone vs NSR | C21: =IF(OR(C19="",C20=""),"",IFERROR(C20/C19-1,"")) -> -0.011807229 | D21: =IF(OR(D19="",D20=""),"",IFERROR(D20/D19-1,"")) -> -0.070566038 | E21: =IF(OR(E19="",E20=""),"",IFERROR(E20/E19-1,"")) -> -0.20679191 | F21: =IF(OR(F19="",F20=""),"",IFERROR(F20/F19-1,"")) -> -0.27843038 | G21: =IF(OR(G19="",G20=""),"",IFERROR(G20/G19-1,"")) | H21: =IF(OR(H19="",H20=""),"",IFERROR(H20/H19-1,""))
A23: Hyperscaler AI capex ($bn) | B23: NSR | C23: =IF(NSR_HyperPL!C42="","",NSR_HyperPL!C42) -> 290 | D23: =IF(NSR_HyperPL!D42="","",NSR_HyperPL!D42) -> 653.75 | E23: =IF(NSR_HyperPL!E42="","",NSR_HyperPL!E42) -> 1224.3875 | F23: =IF(NSR_HyperPL!F42="","",NSR_HyperPL!F42) -> 1794.6379 | G23: =IF(NSR_HyperPL!G42="","",NSR_HyperPL!G42) -> 1977.1908 | H23: =IF(NSR_HyperPL!H42="","",NSR_HyperPL!H42) -> 2156.6956 | I23: NSR implied = group capex − non-AI ($125bn +13% p.a., NSR's own comment). Capstone = AI Model hyperscaler AI bottom-up (big-4). House is above NSR in 2025-26 (+16% / +4%) and below from 2027 (−8%) and 2028 (−21%); by 2028 both put ~all of the growth in AI.
B24: Capstone | C24: =IF(House!E15="","",House!E15) -> 336.4 | D24: =IF(House!F15="","",House!F15) -> 681.9 | E24: =IF(House!G15="","",House!G15) -> 1125.5 | F24: =IF(House!H15="","",House!H15) -> 1425.1
B25: Δ Capstone vs NSR | C25: =IF(OR(C23="",C24=""),"",IFERROR(C24/C23-1,"")) -> 0.16 | D25: =IF(OR(D23="",D24=""),"",IFERROR(D24/D23-1,"")) -> 0.043059273 | E25: =IF(OR(E23="",E24=""),"",IFERROR(E24/E23-1,"")) -> -0.080764872 | F25: =IF(OR(F23="",F24=""),"",IFERROR(F24/F23-1,"")) -> -0.20591222 | G25: =IF(OR(G23="",G24=""),"",IFERROR(G24/G23-1,"")) | H25: =IF(OR(H23="",H24=""),"",IFERROR(H24/H23-1,""))
A27: Non-hyperscaler share of AI capex | B27: NSR | H27: =IFERROR((NSR_Funding!B7+NSR_Funding!B8)/NSR_Funding!B10,"") -> 0.47878788 | I27: NSR: cumulative 2026-30, neocloud $6.5tn + enterprise/gov $1.4tn = 48% of $16.5tn (neocloud alone 39%). Capstone: other players (ORCL, CRWV, SpaceX, labs, sovereign) = 24% of 2026 → 40% of 2027 → 51% of 2028 AI capex. Both houses agree the non-hyperscaler half is where the funding question lives.
B28: Capstone | C28: =IF(House!E22="","",House!E22) -> 0.15089579 | D28: =IF(House!F22="","",House!F22) -> 0.24367791 | E28: =IF(House!G22="","",House!G22) -> 0.40304445 | F28: =IF(House!H22="","",House!H22) -> 0.51079606
B29: Δ Capstone vs NSR | C29: =IF(OR(C27="",C28=""),"",IFERROR(C28/C27-1,"")) | D29: =IF(OR(D27="",D28=""),"",IFERROR(D28/D27-1,"")) | E29: =IF(OR(E27="",E28=""),"",IFERROR(E28/E27-1,"")) | F29: =IF(OR(F27="",F28=""),"",IFERROR(F28/F27-1,"")) | G29: =IF(OR(G27="",G28=""),"",IFERROR(G28/G27-1,"")) | H29: =IF(OR(H27="",H28=""),"",IFERROR(H28/H27-1,""))
A31: 3. WHERE IT GOES — component mix
A32: XPUs / accelerators ($bn) | B32: NSR | C32: =IF(NSR_Capex!C5="","",NSR_Capex!C5) -> 205 | D32: =IF(NSR_Capex!D5="","",NSR_Capex!D5) -> 408 | E32: =IF(NSR_Capex!E5="","",NSR_Capex!E5) -> 782 | F32: =IF(NSR_Capex!F5="","",NSR_Capex!F5) -> 1252 | G32: =IF(NSR_Capex!G5="","",NSR_Capex!G5) -> 1517 | H32: =IF(NSR_Capex!H5="","",NSR_Capex!H5) -> 1702 | I32: NSR XPUs (incl. HBM) vs Capstone chips = designers' revenue incl. HBM (AI Model CY25-28; Semis MAP extension CY29-30). Capstone is only 2-8% below NSR on XPUs while it is 12-32% below on total capex — i.e. the house puts a LARGER share of each capex dollar into the accelerator than NSR does.
B33: Capstone | C33: =IF(House!E7="","",House!E7) -> 190.2 | D33: =IF(House!F7="","",House!F7) -> 399.9 | E33: =IF(House!G7="","",House!G7) -> 767 | F33: =IF(House!H7="","",House!H7) -> 1157.4 | G33: =IF(House!I31="","",House!I31) -> 1240.6 | H33: =IF(House!J31="","",House!J31) -> 1414.2
B34: Δ Capstone vs NSR | C34: =IF(OR(C32="",C33=""),"",IFERROR(C33/C32-1,"")) -> -0.072195122 | D34: =IF(OR(D32="",D33=""),"",IFERROR(D33/D32-1,"")) -> -0.019852941 | E34: =IF(OR(E32="",E33=""),"",IFERROR(E33/E32-1,"")) -> -0.019181586 | F34: =IF(OR(F32="",F33=""),"",IFERROR(F33/F32-1,"")) -> -0.075559105 | G34: =IF(OR(G32="",G33=""),"",IFERROR(G33/G32-1,"")) -> -0.18220171 | H34: =IF(OR(H32="",H33=""),"",IFERROR(H33/H32-1,"")) -> -0.16909518
A36: XPUs as % of total AI capex | B36: NSR | C36: =IF(NSR_Capex!C25="","",NSR_Capex!C25) -> 0.3516295 | D36: =IF(NSR_Capex!D25="","",NSR_Capex!D25) -> 0.36074271 | E36: =IF(NSR_Capex!E25="","",NSR_Capex!E25) -> 0.35658915 | F36: =IF(NSR_Capex!F25="","",NSR_Capex!F25) -> 0.37608892 | G36: =IF(NSR_Capex!G25="","",NSR_Capex!G25) -> 0.39858119 | H36: =IF(NSR_Capex!H25="","",NSR_Capex!H25) -> 0.41041717 | I36: NSR 35% → 38% (2028) → 41% (2030), rising. Capstone 48% → 40% (CY28), falling as the networking/CPU/memory bucket grows 16% → 25%. House share is higher every year but the trajectories cross — the sharpest structural disagreement in this comparison.
B37: Capstone | C37: =IF(House!E12="","",House!E12) -> 0.47993944 | D37: =IF(House!F12="","",House!F12) -> 0.44354481 | E37: =IF(House!G12="","",House!G12) -> 0.40681023 | F37: =IF(House!H12="","",House!H12) -> 0.39730871
B38: Δ Capstone vs NSR | C38: =IF(OR(C36="",C37=""),"",IFERROR(C37/C36-1,"")) -> 0.36490094 | D38: =IF(OR(D36="",D37=""),"",IFERROR(D37/D36-1,"")) -> 0.2295323 | E38: =IF(OR(E36="",E37=""),"",IFERROR(E37/E36-1,"")) -> 0.14083737 | F38: =IF(OR(F36="",F37=""),"",IFERROR(F37/F36-1,"")) -> 0.056422278 | G38: =IF(OR(G36="",G37=""),"",IFERROR(G37/G36-1,"")) | H38: =IF(OR(H36="",H37=""),"",IFERROR(H37/H36-1,""))
A40: NVDA share of accelerator value | B40: NSR | H40: =NSR_Datapoints!B21 -> 0.6 | I40: NSR: ~60% in 2030 (~$1.0tn NVDA of $1.7tn). Capstone: 68% CY28 (AI Model), 64% CY30 (Semis MAP). House is 4-8pp more NVDA-heavy at the end of the decade; BofA has 68% CY30.
B41: Capstone | C41: =IF(House!E70="","",House!E70) -> 0.83491062 | D41: =IF(House!F70="","",House!F70) -> 0.77969492 | E41: =IF(House!G70="","",House!G70) -> 0.75436767 | F41: =IF(House!H70="","",House!H70) -> 0.67738034 | G41: =IF(House!I35="","",House!I35) -> 0.64106078 | H41: =IF(House!J35="","",House!J35) -> 0.63640221
B42: Δ Capstone vs NSR | C42: =IF(OR(C40="",C41=""),"",IFERROR(C41/C40-1,"")) | D42: =IF(OR(D40="",D41=""),"",IFERROR(D41/D40-1,"")) | E42: =IF(OR(E40="",E41=""),"",IFERROR(E41/E40-1,"")) | F42: =IF(OR(F40="",F41=""),"",IFERROR(F41/F40-1,"")) | G42: =IF(OR(G40="",G41=""),"",IFERROR(G41/G40-1,"")) | H42: =IF(OR(H40="",H41=""),"",IFERROR(H41/H40-1,"")) -> 0.060670344
A44: CPUs — AI slice ($bn) | B44: NSR | C44: =IF(NSR_Capex!C6="","",NSR_Capex!C6) -> 6 | D44: =IF(NSR_Capex!D6="","",NSR_Capex!D6) -> 27 | E44: =IF(NSR_Capex!E6="","",NSR_Capex!E6) -> 56 | F44: =IF(NSR_Capex!F6="","",NSR_Capex!F6) -> 90 | G44: =IF(NSR_Capex!G6="","",NSR_Capex!G6) -> 129 | H44: =IF(NSR_Capex!H6="","",NSR_Capex!H6) -> 168 | I44: NSR p.4 CPUs (AI) 6 → 168. Capstone Semis MAP AI CPUs (head-node, BofA-mix on house capex) 15 → 171. Nearly identical 2030 level, but the house is 1.5-2.5x NSR in 2025-26 (NSR's $6bn 2025 looks too low against any head-node count).
B45: Capstone | C45: =IF(House!E38="","",House!E38) -> 15.2 | D45: =IF(House!F38="","",House!F38) -> 40.2 | E45: =IF(House!G38="","",House!G38) -> 79.2 | F45: =IF(House!H38="","",House!H38) -> 127.2 | G45: =IF(House!I38="","",House!I38) -> 150.1 | H45: =IF(House!J38="","",House!J38) -> 171.1
B46: Δ Capstone vs NSR | C46: =IF(OR(C44="",C45=""),"",IFERROR(C45/C44-1,"")) -> 1.5333333 | D46: =IF(OR(D44="",D45=""),"",IFERROR(D45/D44-1,"")) -> 0.48888889 | E46: =IF(OR(E44="",E45=""),"",IFERROR(E45/E44-1,"")) -> 0.41428571 | F46: =IF(OR(F44="",F45=""),"",IFERROR(F45/F44-1,"")) -> 0.41333333 | G46: =IF(OR(G44="",G45=""),"",IFERROR(G45/G44-1,"")) -> 0.16356589 | H46: =IF(OR(H44="",H45=""),"",IFERROR(H45/H44-1,"")) -> 0.018452381
A48: CPUs — total server-CPU market ($bn) | B48: NSR | C48: =IF(NSR_Memory!C25="","",NSR_Memory!C25) -> 25 | D48: =IF(NSR_Memory!D25="","",NSR_Memory!D25) -> 49 | E48: =IF(NSR_Memory!E25="","",NSR_Memory!E25) -> 80 | F48: =IF(NSR_Memory!F25="","",NSR_Memory!F25) -> 117 | G48: =IF(NSR_Memory!G25="","",NSR_Memory!G25) -> 159 | H48: =IF(NSR_Memory!H25="","",NSR_Memory!H25) -> 202 | I48: NSR p.5 CPUs spending 25 → 202. Capstone ledger: house build ~$55bn CY26 / $96bn CY27 / $137bn CY28, ~$180-200bn 2030 (CPU-silicon total incl. Vera + enterprise). House is above NSR in 2026-28 (front-loaded agentic 1:1), converges by 2030; AMD's $220bn 2030 is above both.
B49: Capstone | D49: =IF(House!F116="","",House!F116) -> 55 | E49: =IF(House!G116="","",House!G116) -> 96 | F49: =IF(House!H116="","",House!H116) -> 137 | H49: =IF(House!J116="","",House!J116) -> 190
B50: Δ Capstone vs NSR | C50: =IF(OR(C48="",C49=""),"",IFERROR(C49/C48-1,"")) | D50: =IF(OR(D48="",D49=""),"",IFERROR(D49/D48-1,"")) -> 0.12244898 | E50: =IF(OR(E48="",E49=""),"",IFERROR(E49/E48-1,"")) -> 0.2 | F50: =IF(OR(F48="",F49=""),"",IFERROR(F49/F48-1,"")) -> 0.17094017 | G50: =IF(OR(G48="",G49=""),"",IFERROR(G49/G48-1,"")) | H50: =IF(OR(H48="",H49=""),"",IFERROR(H49/H48-1,"")) -> -0.059405941
A52: Networking ($bn) | B52: NSR | C52: =IF(NSR_Capex!C9="","",NSR_Capex!C9) -> 40 | D52: =IF(NSR_Capex!D9="","",NSR_Capex!D9) -> 103 | E52: =IF(NSR_Capex!E9="","",NSR_Capex!E9) -> 211 | F52: =IF(NSR_Capex!F9="","",NSR_Capex!F9) -> 336 | G52: =IF(NSR_Capex!G9="","",NSR_Capex!G9) -> 405 | H52: =IF(NSR_Capex!H9="","",NSR_Capex!H9) -> 465 | I52: NSR networking 40 → 465. Capstone Semis MAP AI networking (BofA ratio × house accelerators) 57 → 606; Bottom_Up physical build is lower (56 → 306). NSR sits between the two house constructions; all three agree networking outgrows compute.
...

Sheet Share_XPU
A1: XPU / accelerators — vendor market share and implied revenue, 2025-2030 ($bn)
A2: Pool = NSR XPUs (p.4, HBM inside the package) and the Capstone chip pool. Shares = Capstone designer revenue ÷ Capstone pool (our model's mix, tagged EST because it is a house forecast), with NSR's and BofA's 2030 marks as the external alternatives. Implied revenue = NSR pool × share. NOT ADDITIVE with Share_Memory: the HBM dollars inside these XPU figures are the same dollars shown as vendor HBM revenue there. Tags: HARD = sourced figure; PARTIAL = sourced range, point is ours; EST = our assumption; SCENARIO = alternative reading; FORMULA = derived.
A4: Line | B4: Unit | C4: 2025 | D4: 2026 | E4: 2027 | F4: 2028 | G4: 2029 | H4: 2030 | I4: Tag | J4: Source
A5: A. Pools ($bn)
A6: NSR XPU spending (incl. HBM inside the package) | B6: $bn | C6: =IF(NSR_Capex!C5="","",NSR_Capex!C5) -> 205 | D6: =IF(NSR_Capex!D5="","",NSR_Capex!D5) -> 408 | E6: =IF(NSR_Capex!E5="","",NSR_Capex!E5) -> 782 | F6: =IF(NSR_Capex!F5="","",NSR_Capex!F5) -> 1252 | G6: =IF(NSR_Capex!G5="","",NSR_Capex!G5) -> 1517 | H6: =IF(NSR_Capex!H5="","",NSR_Capex!H5) -> 1702 | I6: LINK | J6: NSR p.4 (NSR_Capex)
A7: Capstone chip pool = designers' AI chip revenue (incl. HBM inside) | B7: $bn | C7: =IF(House!E7="","",House!E7) -> 190.2 | D7: =IF(House!F7="","",House!F7) -> 399.9 | E7: =IF(House!G7="","",House!G7) -> 767 | F7: =IF(House!H7="","",House!H7) -> 1157.4 | G7: =IF(House!I31="","",House!I31) -> 1240.6 | H7: =IF(House!J31="","",House!J31) -> 1414.2 | I7: LINK | J7: House!cx_chips CY25-28 (AI Model 31-Aug); House!sm_des CY29-30 (Semis MAP v11, July base). VINTAGE SPLICE: NVDA CY28 → CY29 grows only +1.4% across the join (Semis MAP's own CY28→29 is +17%), so the CY29-30 NVDA share step-down is an artifact, not a view
A9: B. Capstone vendor chip revenue ($bn) — the house mix (EST: house model output)
A10: NVIDIA (merchant GPU) | B10: $bn | C10: 158.8 | D10: 311.8 | E10: 578.6 | F10: 784 | G10: 795.3 | H10: 900 | I10: EST | J10: AI Model.xlsx (31-Aug-2026) → Resumo | Designers ‘Receita de Chip das Designers’ rows 34-45 (CY25-28); Semis MAP v11 → Designers TAM (CY29-30, July base). HOUSE MODEL OUTPUT — a forecast split, not a market print (hence EST)
A11: Broadcom (Google TPU + Meta MTIA + OpenAI Titan, custom ASIC) | B11: $bn | C11: 20.1 | D11: 60.4 | E11: 125.5 | F11: 284.6 | G11: 340.3 | H11: 394.2 | I11: EST | J11: same source. NOTE the house fork: the official AVGO model (Modelo Avgo pós 2Q26) has AI semis $251bn FY28 INCLUDING networking, below this XPU-only $284.6bn
A12: AMD (MI series) | B12: $bn | C12: 8 | D12: 20.7 | E12: 38.4 | F12: 51.8 | G12: 60.7 | H12: 68.7 | I12: EST | J12: same source
A13: Marvell (Trainium + other custom) | B13: $bn | C13: 2.9 | D13: 6.9 | E13: 9.3 | F13: 13.3 | G13: 15.9 | H13: 18.4 | I13: EST | J13: same source
A14: MediaTek (TPU co-design) | B14: $bn | C14: 0 | D14: 0.2 | E14: 12.3 | F14: 20.3 | G14: 24.2 | H14: 28.1 | I14: EST | J14: same source
A15: Alchip (incl. Microsoft Maia co-design) | B15: $bn | C15: 0.4 | D15: 0 | E15: 3 | F15: 3.5 | G15: 4.2 | H15: 4.9 | I15: EST | J15: same source — Semis MAP labels the row ‘Microsoft (Alchip)’; Maia is INSIDE Alchip, not additive (skeptic fix)
A16: Sum of vendor rows | B16: $bn | C16: =SUM(C10:C15) -> 190.2 | D16: =SUM(D10:D15) -> 400 | E16: =SUM(E10:E15) -> 767.1 | F16: =SUM(F10:F15) -> 1157.5 | G16: =SUM(G10:G15) -> 1240.6 | H16: =SUM(H10:H15) -> 1414.3 | I16: FORMULA
A17: Check: vendor rows − Capstone pool (should be ~0) | B17: $bn | C17: =IF(C7="","",C16-C7) -> 2.8421709e-14 | D17: =IF(D7="","",D16-D7) -> 0.1 | E17: =IF(E7="","",E16-E7) -> 0.1 | F17: =IF(F7="","",F16-F7) -> 0.1 | G17: =IF(G7="","",G16-G7) -> 2.2737368e-13 | H17: =IF(H7="","",H16-H7) -> 0.1 | I17: FORMULA | J17: AI Model total = NVDA + AVGO + AMD + MRVL + MTK + Alchip exactly
A19: C. Market share — Capstone mix (share of the Capstone pool)
A20: NVIDIA — share of accelerator value | B20: % | C20: =IF(OR(C10="",C16=""),"",IFERROR(C10/C16,"")) -> 0.83491062 | D20: =IF(OR(D10="",D16=""),"",IFERROR(D10/D16,"")) -> 0.7795 | E20: =IF(OR(E10="",E16=""),"",IFERROR(E10/E16,"")) -> 0.75426933 | F20: =IF(OR(F10="",F16=""),"",IFERROR(F10/F16,"")) -> 0.67732181 | G20: =IF(OR(G10="",G16=""),"",IFERROR(G10/G16,"")) -> 0.64106078 | H20: =IF(OR(H10="",H16=""),"",IFERROR(H10/H16,"")) -> 0.63635721 | I20: EST | J20: → vendor row / sum of vendor rows (house forecast split)
A21: Broadcom — share of accelerator value | B21: % | C21: =IF(OR(C11="",C16=""),"",IFERROR(C11/C16,"")) -> 0.10567823 | D21: =IF(OR(D11="",D16=""),"",IFERROR(D11/D16,"")) -> 0.151 | E21: =IF(OR(E11="",E16=""),"",IFERROR(E11/E16,"")) -> 0.16360318 | F21: =IF(OR(F11="",F16=""),"",IFERROR(F11/F16,"")) -> 0.24587473 | G21: =IF(OR(G11="",G16=""),"",IFERROR(G11/G16,"")) -> 0.27430276 | H21: =IF(OR(H11="",H16=""),"",IFERROR(H11/H16,"")) -> 0.27872446 | I21: EST | J21: → vendor row / sum of vendor rows (house forecast split)
A22: AMD — share of accelerator value | B22: % | C22: =IF(OR(C12="",C16=""),"",IFERROR(C12/C16,"")) -> 0.042060988 | D22: =IF(OR(D12="",D16=""),"",IFERROR(D12/D16,"")) -> 0.05175 | E22: =IF(OR(E12="",E16=""),"",IFERROR(E12/E16,"")) -> 0.050058662 | F22: =IF(OR(F12="",F16=""),"",IFERROR(F12/F16,"")) -> 0.04475162 | G22: =IF(OR(G12="",G16=""),"",IFERROR(G12/G16,"")) -> 0.048927938 | H22: =IF(OR(H12="",H16=""),"",IFERROR(H12/H16,"")) -> 0.048575267 | I22: EST | J22: → vendor row / sum of vendor rows (house forecast split)
A23: Marvell — share of accelerator value | B23: % | C23: =IF(OR(C13="",C16=""),"",IFERROR(C13/C16,"")) -> 0.015247108 | D23: =IF(OR(D13="",D16=""),"",IFERROR(D13/D16,"")) -> 0.01725 | E23: =IF(OR(E13="",E16=""),"",IFERROR(E13/E16,"")) -> 0.012123582 | F23: =IF(OR(F13="",F16=""),"",IFERROR(F13/F16,"")) -> 0.011490281 | G23: =IF(OR(G13="",G16=""),"",IFERROR(G13/G16,"")) -> 0.012816379 | H23: =IF(OR(H13="",H16=""),"",IFERROR(H13/H16,"")) -> 0.01300997 | I23: EST | J23: → vendor row / sum of vendor rows (house forecast split)
A24: MediaTek — share of accelerator value | B24: % | C24: =IF(OR(C14="",C16=""),"",IFERROR(C14/C16,"")) -> 0 | D24: =IF(OR(D14="",D16=""),"",IFERROR(D14/D16,"")) -> 0.0005 | E24: =IF(OR(E14="",E16=""),"",IFERROR(E14/E16,"")) -> 0.016034415 | F24: =IF(OR(F14="",F16=""),"",IFERROR(F14/F16,"")) -> 0.017537797 | G24: =IF(OR(G14="",G16=""),"",IFERROR(G14/G16,"")) -> 0.01950669 | H24: =IF(OR(H14="",H16=""),"",IFERROR(H14/H16,"")) -> 0.019868486 | I24: EST | J24: → vendor row / sum of vendor rows (house forecast split)
A25: Alchip (incl. Maia) — share of accelerator value | B25: % | C25: =IF(OR(C15="",C16=""),"",IFERROR(C15/C16,"")) -> 0.0021030494 | D25: =IF(OR(D15="",D16=""),"",IFERROR(D15/D16,"")) -> 0 | E25: =IF(OR(E15="",E16=""),"",IFERROR(E15/E16,"")) -> 0.003910833 | F25: =IF(OR(F15="",F16=""),"",IFERROR(F15/F16,"")) -> 0.0030237581 | G25: =IF(OR(G15="",G16=""),"",IFERROR(G15/G16,"")) -> 0.0033854586 | H25: =IF(OR(H15="",H16=""),"",IFERROR(H15/H16,"")) -> 0.0034646115 | I25: EST | J25: → vendor row / sum of vendor rows (house forecast split)
A26: Custom ASIC total (Broadcom + Marvell + MediaTek + Alchip) — share | B26: % | C26: =IF(C20="","",1-C20-C22) -> 0.12302839 | D26: =IF(D20="","",1-D20-D22) -> 0.16875 | E26: =IF(E20="","",1-E20-E22) -> 0.19567201 | F26: =IF(F20="","",1-F20-F22) -> 0.27792657 | G26: =IF(G20="","",1-G20-G22) -> 0.31001128 | H26: =IF(H20="","",1-H20-H22) -> 0.31506752 | I26: FORMULA | J26: → 1 − NVIDIA − AMD
A28: D. Third-party marks (share of accelerator value unless stated)
A29: NVIDIA — NSR (2030) | B29: % | H29: 0.6 | I29: HARD | J29: NSR p.3: “Nvidia at close to 60% of XPU value in 2030, implying ~$1.7tn of total XPU spending”
A30: NVIDIA — BofA AI 2030 (CY30) | B30: % | H30: 0.68 | I30: HARD | J30: BofA Arya “AI 2030” 2026-05-13 (themes/ai-tam-bofa.md §5): NVDA ~$800bn of $1.17tn accelerators CY30 (83% → 68%)
A31: Broadcom — BofA AI 2030 (CY30) | B31: % | H31: 0.16 | I31: HARD | J31: BofA: AVGO custom ASIC ~$182bn CY30 = 16% (8% → 16%)
A32: AMD — BofA AI 2030 (CY30) | B32: % | H32: 0.07 | I32: HARD | J32: BofA: AMD ~$80bn CY30 = ~5-7%
A33: Custom ASIC — JPM UNIT share (units, NOT value) | B33: % | D33: 0.42 | E33: 0.53 | I33: HARD | J33: JPM Sur ‘AI Capex 2.0’ 2026-06-16 (assumptions.md asic-vs-gpu-share): ASIC 42% of units 2026E → 53% 2027E. Unit share ≠ value share (ASIC ASP ~$9-19k vs NVDA $41-137k in our model)
A35: E. Implied vendor revenue on the NSR pool ($bn) = NSR XPU pool × Capstone share
A36: NVIDIA — implied on NSR pool | B36: $bn | C36: =IF(OR(C6="",C20=""),"",C6*C20) -> 171.15668 | D36: =IF(OR(D6="",D20=""),"",D6*D20) -> 318.036 | E36: =IF(OR(E6="",E20=""),"",E6*E20) -> 589.83861 | F36: =IF(OR(F6="",F20=""),"",F6*F20) -> 848.00691 | G36: =IF(OR(G6="",G20=""),"",G6*G20) -> 972.4892 | H36: =IF(OR(H6="",H20=""),"",H6*H20) -> 1083.08 | I36: FORMULA | J36: NSR pool × Capstone share
A37: Broadcom — implied on NSR pool | B37: $bn | C37: =IF(OR(C6="",C21=""),"",C6*C21) -> 21.664038 | D37: =IF(OR(D6="",D21=""),"",D6*D21) -> 61.608 | E37: =IF(OR(E6="",E21=""),"",E6*E21) -> 127.93769 | F37: =IF(OR(F6="",F21=""),"",F6*F21) -> 307.83516 | G37: =IF(OR(G6="",G21=""),"",G6*G21) -> 416.11728 | H37: =IF(OR(H6="",H21=""),"",H6*H21) -> 474.38903 | I37: FORMULA | J37: NSR pool × Capstone share
A38: AMD — implied on NSR pool | B38: $bn | C38: =IF(OR(C6="",C22=""),"",C6*C22) -> 8.6225026 | D38: =IF(OR(D6="",D22=""),"",D6*D22) -> 21.114 | E38: =IF(OR(E6="",E22=""),"",E6*E22) -> 39.145874 | F38: =IF(OR(F6="",F22=""),"",F6*F22) -> 56.029028 | G38: =IF(OR(G6="",G22=""),"",G6*G22) -> 74.223682 | H38: =IF(OR(H6="",H22=""),"",H6*H22) -> 82.675104 | I38: FORMULA | J38: NSR pool × Capstone share
A39: Marvell — implied on NSR pool | B39: $bn | C39: =IF(OR(C6="",C23=""),"",C6*C23) -> 3.1256572 | D39: =IF(OR(D6="",D23=""),"",D6*D23) -> 7.038 | E39: =IF(OR(E6="",E23=""),"",E6*E23) -> 9.4806414 | F39: =IF(OR(F6="",F23=""),"",F6*F23) -> 14.385832 | G39: =IF(OR(G6="",G23=""),"",G6*G23) -> 19.442447 | H39: =IF(OR(H6="",H23=""),"",H6*H23) -> 22.142968 | I39: FORMULA | J39: NSR pool × Capstone share
A40: MediaTek — implied on NSR pool | B40: $bn | C40: =IF(OR(C6="",C24=""),"",C6*C24) -> 0 | D40: =IF(OR(D6="",D24=""),"",D6*D24) -> 0.204 | E40: =IF(OR(E6="",E24=""),"",E6*E24) -> 12.538913 | F40: =IF(OR(F6="",F24=""),"",F6*F24) -> 21.957322 | G40: =IF(OR(G6="",G24=""),"",G6*G24) -> 29.591649 | H40: =IF(OR(H6="",H24=""),"",H6*H24) -> 33.816163 | I40: FORMULA | J40: NSR pool × Capstone share
A41: Alchip (incl. Maia) — implied on NSR pool | B41: $bn | C41: =IF(OR(C6="",C25=""),"",C6*C25) -> 0.43112513 | D41: =IF(OR(D6="",D25=""),"",D6*D25) -> 0 | E41: =IF(OR(E6="",E25=""),"",E6*E25) -> 3.0582714 | F41: =IF(OR(F6="",F25=""),"",F6*F25) -> 3.7857451 | G41: =IF(OR(G6="",G25=""),"",G6*G25) -> 5.1357408 | H41: =IF(OR(H6="",H25=""),"",H6*H25) -> 5.8967687 | I41: FORMULA | J41: NSR pool × Capstone share
A42: NVIDIA — implied on NSR pool at NSR's own 60% (2030) | B42: $bn | C42: =IF(OR(C6="",C29=""),"",C6*C29) | D42: =IF(OR(D6="",D29=""),"",D6*D29) | E42: =IF(OR(E6="",E29=""),"",E6*E29) | F42: =IF(OR(F6="",F29=""),"",F6*F29) | G42: =IF(OR(G6="",G29=""),"",G6*G29) | H42: =IF(OR(H6="",H29=""),"",H6*H29) -> 1021.2 | I42: FORMULA | J42: → $1,702bn × 60% ≈ $1.02tn, NSR's implied NVIDIA 2030 XPU revenue
A43: NVIDIA — implied on NSR pool at BofA's 68% (2030) | B43: $bn | C43: =IF(OR(C6="",C30=""),"",C6*C30) | D43: =IF(OR(D6="",D30=""),"",D6*D30) | E43: =IF(OR(E6="",E30=""),"",E6*E30) | F43: =IF(OR(F6="",F30=""),"",F6*F30) | G43: =IF(OR(G6="",G30=""),"",G6*G30) | H43: =IF(OR(H6="",H30=""),"",H6*H30) -> 1157.36 | I43: FORMULA
A44: Broadcom — implied on NSR pool at BofA's 16% (2030) | B44: $bn | C44: =IF(OR(C6="",C31=""),"",C6*C31) | D44: =IF(OR(D6="",D31=""),"",D6*D31) | E44: =IF(OR(E6="",E31=""),"",E6*E31) | F44: =IF(OR(F6="",F31=""),"",F6*F31) | G44: =IF(OR(G6="",G31=""),"",G6*G31) | H44: =IF(OR(H6="",H31=""),"",H6*H31) -> 272.32 | I44: FORMULA
A46: F. Guardrails — implied revenue vs what the companies / consensus actually print
...

Sheet Share_CPU
A1: Server CPUs — vendor market share and implied revenue, 2025-2030 ($bn)
A2: Two NSR pools (total server-CPU market p.5; AI-slice p.4) and three share lenses: (1) Capstone Semis MAP head-node value shares (EST, systems-value basis), (2) Bernstein unit shares (HARD units; unit ≠ value), (3) a street-anchored SILICON value build from reported / printed vendor figures (Intel: BofA's printed 08-12 path; AMD: segment prints + UBS 05-21 on its own TAM; NVIDIA: Bernstein units × $4k chip ASP, with management's systems-basis reading as a scenario). Lens 3 is load-bearing. Skeptic-revised 2026-09-18.
A4: Line | B4: Unit | C4: 2025 | D4: 2026 | E4: 2027 | F4: 2028 | G4: 2029 | H4: 2030 | I4: Tag | J4: Source
A5: A. Pools ($bn) and external TAM marks
A6: NSR total server-CPU market (p.5 ‘CPUs spending’) | B6: $bn | C6: =IF(NSR_Memory!C25="","",NSR_Memory!C25) -> 25 | D6: =IF(NSR_Memory!D25="","",NSR_Memory!D25) -> 49 | E6: =IF(NSR_Memory!E25="","",NSR_Memory!E25) -> 80 | F6: =IF(NSR_Memory!F25="","",NSR_Memory!F25) -> 117 | G6: =IF(NSR_Memory!G25="","",NSR_Memory!G25) -> 159 | H6: =IF(NSR_Memory!H25="","",NSR_Memory!H25) -> 202 | I6: LINK | J6: NSR p.5 (NSR_Memory)
A7: NSR AI-slice CPUs (p.4) | B7: $bn | C7: =IF(NSR_Capex!C6="","",NSR_Capex!C6) -> 6 | D7: =IF(NSR_Capex!D6="","",NSR_Capex!D6) -> 27 | E7: =IF(NSR_Capex!E6="","",NSR_Capex!E6) -> 56 | F7: =IF(NSR_Capex!F6="","",NSR_Capex!F6) -> 90 | G7: =IF(NSR_Capex!G6="","",NSR_Capex!G6) -> 129 | H7: =IF(NSR_Capex!H6="","",NSR_Capex!H6) -> 168 | I7: LINK | J7: NSR p.4 (NSR_Capex)
A8: Capstone AI head-node CPUs — Semis MAP BofA-mix line (uncalibrated) | B8: $bn | C8: =IF(House!E38="","",House!E38) -> 15.2 | D8: =IF(House!F38="","",House!F38) -> 40.2 | E8: =IF(House!G38="","",House!G38) -> 79.2 | F8: =IF(House!H38="","",House!H38) -> 127.2 | G8: =IF(House!I38="","",House!I38) -> 150.1 | H8: =IF(House!J38="","",House!J38) -> 171.1 | I8: LINK | J8: House!sm_cpu (Semis MAP v11 ‘AI DC TAM (BofA mix)’ AI CPUs = BofA ratio × house capex)
A9: Capstone AI head-node CPUs — Semis MAP Build | CPU CALIBRATED line | B9: $bn | C9: 9.3 | D9: 24.6 | E9: 48.4 | F9: 77.8 | G9: 91.8 | H9: 104.7 | I9: EST | J9: AI_Chip_Designers_TAM_v11.xlsx → Build | CPU row 3 (the sheet's own ‘capture-calibrated version’). On this line NSR's AI-slice CPU pool is ~60% ABOVE the house in 2030; on the uncalibrated line above they look aligned — the alignment is a series choice
A10: Capstone total server-CPU (ledger canon) | B10: $bn | C10: =IF(House!E116="","",House!E116) | D10: =IF(House!F116="","",House!F116) -> 55 | E10: =IF(House!G116="","",House!G116) -> 96 | F10: =IF(House!H116="","",House!H116) -> 137 | G10: =IF(House!I116="","",House!I116) | H10: =IF(House!J116="","",House!J116) -> 190 | I10: LINK | J10: House!lg_cpu (assumptions.md server-cpu-tam: ~$55bn CY26 / $96bn CY27 / $137bn CY28 / ~$190bn 2030)
A11: External TAM — BofA (2026-08-12): ~$35bn CY25 level → $210.6bn CY30E | B11: $bn | C11: 35 | H11: 210.6 | I11: HARD | J11: INTC.md rows ~409/553: BofA raised CY30E server-CPU TAM to $210.6bn (from ~$170bn on 07-13); Intel value share 40.4% → 22.0%
A12: External TAM — UBS ‘CPU TAM’ (2026-05-21): $31bn 2025 → $74bn 2027E → $173bn 2030E | B12: $bn | C12: 31 | E12: 74 | H12: 173 | I12: HARD | J12: AMD.md row ~212 / ARM.md: UBS unit shares Intel 60% → 29%, Arm 16% → 42%, AMD 24% → 29% (2025 → 2030); AMD value share 24% → 27% (2027E) → 29% (2030E)
A13: External TAM — Bernstein Rasgon (2026-06-16): $37bn 2025 → $137bn 2030 BASE ($223bn BULL) | B13: $bn | C13: 37 | H13: 137 | I13: HARD | J13: assumptions.md server-cpu-tam
A14: Company target — AMD Advancing AI (2026-07-23): $220bn 2030, AMD share >50% | B14: $bn | H14: 220 | I14: HARD | J14: assumptions.md server-cpu-tam; company event TAM, high bias
A16: B. Lens 1 — Capstone Semis MAP head-node value shares (AI servers only; systems-value basis)
A17: Intel (Xeon head-node) | B17: % | C17: 0.28 | D17: 0.22 | E17: 0.18 | F17: 0.15 | G17: =F17 -> 0.15 | H17: =F17 -> 0.15 | I17: EST | J17: AI_Chip_Designers_TAM_v11.xlsx → Build | CPU rows 7-10 (2026-07-16); CY29-30 held at CY28. Systems-value shares: NVIDIA's 38% carries Grace/Vera at superchip value, which is why lens 1 can exceed the silicon build in block D
A18: AMD (EPYC head-node) | B18: % | C18: 0.3 | D18: 0.26 | E18: 0.24 | F18: 0.22 | G18: =F18 -> 0.22 | H18: =F18 -> 0.22 | I18: EST | J18: same source
A19: NVIDIA (Grace / Vera inside GB200-GB300-VR200 superchips) | B19: % | C19: 0.25 | D19: 0.33 | E19: 0.36 | F19: 0.38 | G19: =F19 -> 0.38 | H19: =F19 -> 0.38 | I19: EST | J19: same source
A20: Captive Arm (Graviton / Axion / Cobalt / Maia-CPU) + others | B20: % | C20: 0.17 | D20: 0.19 | E20: 0.22 | F20: 0.25 | G20: =F20 -> 0.25 | H20: =F20 -> 0.25 | I20: EST | J20: same source
A21: Check: sum of shares | B21: % | C21: =SUM(C17:C20) -> 1 | D21: =SUM(D17:D20) -> 1 | E21: =SUM(E17:E20) -> 1 | F21: =SUM(F17:F20) -> 1 | G21: =SUM(G17:G20) -> 1 | H21: =SUM(H17:H20) -> 1 | I21: FORMULA
A23: C. Lens 2 — Bernstein server-CPU UNITS by vendor (mn units) → unit shares
A24: Intel (excl. Atom) | B24: mn | C24: 18.8 | D24: 21.6 | E24: 24.3 | F24: 26.5 | G24: 31.4 | H24: 38 | I24: HARD | J24: Bernstein · Qingyuan Lin, ‘Global memory interface chips’ model (P:\Felipe Monteiro\Memória\Bernstein on CPU.xlsx → PPT output rows 5-9; server CPU excl. IoT)
A25: AMD | B25: mn | C25: 7.2 | D25: 9.7 | E25: 12.7 | F25: 16.4 | G25: 21.1 | H25: 26.5 | I25: HARD | J25: same source (Bernstein PPT output)
A26: Hygon (China x86) | B26: mn | C26: 1.8 | D26: 2.2 | E26: 3.3 | F26: 5.7 | G26: 8.8 | H26: 11.8 | I26: HARD | J26: same source
A27: Arm — non-NVIDIA (Graviton / Axion / Cobalt / Ampere etc.) | B27: mn | C27: 2.7 | D27: 3.8 | E27: 5.3 | F27: 6.9 | G27: 9.2 | H27: 13 | I27: HARD | J27: same source
A28: Arm — NVIDIA (Grace / Vera) | B28: mn | C28: 1.2 | D28: 2.7 | E28: 6.1 | F28: 6.1 | G28: 6.1 | H28: 5.9 | I28: HARD | J28: same source — note Bernstein has NVIDIA units FLAT 2027-30
A29: Total server CPU units | B29: mn | C29: =SUM(C24:C28) -> 31.7 | D29: =SUM(D24:D28) -> 40 | E29: =SUM(E24:E28) -> 51.7 | F29: =SUM(F24:F28) -> 61.6 | G29: =SUM(G24:G28) -> 76.6 | H29: =SUM(H24:H28) -> 95.2 | I29: FORMULA | J29: Bernstein prints 31.8 / 40.0 / 51.6 mn for 2025-27; JPM proprietary model 26M (2025) → 68M (2028) for comparison
A30: Intel — UNIT share | B30: % | C30: =IF(OR(C24="",C29=""),"",IFERROR(C24/C29,"")) -> 0.59305994 | D30: =IF(OR(D24="",D29=""),"",IFERROR(D24/D29,"")) -> 0.54 | E30: =IF(OR(E24="",E29=""),"",IFERROR(E24/E29,"")) -> 0.47001934 | F30: =IF(OR(F24="",F29=""),"",IFERROR(F24/F29,"")) -> 0.43019481 | G30: =IF(OR(G24="",G29=""),"",IFERROR(G24/G29,"")) -> 0.40992167 | H30: =IF(OR(H24="",H29=""),"",IFERROR(H24/H29,"")) -> 0.39915966 | I30: FORMULA | J30: → units / total units (Bernstein). UBS 2026-05-21 unit shares for reference: Intel 60% → 29%, Arm 16% → 42%, AMD 24% → 29% (2025 → 2030)
A31: AMD — UNIT share | B31: % | C31: =IF(OR(C25="",C29=""),"",IFERROR(C25/C29,"")) -> 0.22712934 | D31: =IF(OR(D25="",D29=""),"",IFERROR(D25/D29,"")) -> 0.2425 | E31: =IF(OR(E25="",E29=""),"",IFERROR(E25/E29,"")) -> 0.24564797 | F31: =IF(OR(F25="",F29=""),"",IFERROR(F25/F29,"")) -> 0.26623377 | G31: =IF(OR(G25="",G29=""),"",IFERROR(G25/G29,"")) -> 0.27545692 | H31: =IF(OR(H25="",H29=""),"",IFERROR(H25/H29,"")) -> 0.27836134 | I31: FORMULA | J31: → units / total units
A32: Hygon — UNIT share | B32: % | C32: =IF(OR(C26="",C29=""),"",IFERROR(C26/C29,"")) -> 0.056782334 | D32: =IF(OR(D26="",D29=""),"",IFERROR(D26/D29,"")) -> 0.055 | E32: =IF(OR(E26="",E29=""),"",IFERROR(E26/E29,"")) -> 0.063829787 | F32: =IF(OR(F26="",F29=""),"",IFERROR(F26/F29,"")) -> 0.092532468 | G32: =IF(OR(G26="",G29=""),"",IFERROR(G26/G29,"")) -> 0.11488251 | H32: =IF(OR(H26="",H29=""),"",IFERROR(H26/H29,"")) -> 0.12394958 | I32: FORMULA | J32: → units / total units
A33: Arm non-NVIDIA — UNIT share | B33: % | C33: =IF(OR(C27="",C29=""),"",IFERROR(C27/C29,"")) -> 0.085173502 | D33: =IF(OR(D27="",D29=""),"",IFERROR(D27/D29,"")) -> 0.095 | E33: =IF(OR(E27="",E29=""),"",IFERROR(E27/E29,"")) -> 0.10251451 | F33: =IF(OR(F27="",F29=""),"",IFERROR(F27/F29,"")) -> 0.11201299 | G33: =IF(OR(G27="",G29=""),"",IFERROR(G27/G29,"")) -> 0.12010444 | H33: =IF(OR(H27="",H29=""),"",IFERROR(H27/H29,"")) -> 0.13655462 | I33: FORMULA | J33: → units / total units
A34: Arm NVIDIA — UNIT share | B34: % | C34: =IF(OR(C28="",C29=""),"",IFERROR(C28/C29,"")) -> 0.03785489 | D34: =IF(OR(D28="",D29=""),"",IFERROR(D28/D29,"")) -> 0.0675 | E34: =IF(OR(E28="",E29=""),"",IFERROR(E28/E29,"")) -> 0.11798839 | F34: =IF(OR(F28="",F29=""),"",IFERROR(F28/F29,"")) -> 0.099025974 | G34: =IF(OR(G28="",G29=""),"",IFERROR(G28/G29,"")) -> 0.079634465 | H34: =IF(OR(H28="",H29=""),"",IFERROR(H28/H29,"")) -> 0.06197479 | I34: FORMULA | J34: → units / total units
A36: D. Lens 3 — street-anchored SILICON value build ($bn of server-CPU revenue by vendor)
A37: Intel server CPU revenue — BofA printed path | B37: $bn | C37: 14.1 | D37: 20.8 | E37: 27.8 | F37: 33.6 | G37: 39.7 | H37: 46.3 | I37: HARD | J37: BofA (2026-08-12, INTC.md ~row 553): $14.1bn CY25 → $20.8bn CY26E → $27.8bn CY27E → $33.6bn CY28E → $46.3bn CY30E (value share 40.4% → 22.0% of a $210.6bn TAM). CY29 = midpoint EST. Cross-check: DCAI prints 1Q26 $5.1bn, 2Q26 $6.26bn (+59% y/y) → CY26 DCAI ≈ $24-25bn incl. ~$2bn custom ASIC
A38: AMD server CPU (EPYC) revenue | B38: $bn | C38: 10 | D38: 16.4 | E38: 22 | F38: 29 | G38: 38 | H38: 50 | I38: PARTIAL | J38: CY26 from segment prints: 2Q26 server CPU $3.63bn, 3Q26 guide $4.53bn (GS model, AMD.md ~row 465) → ≈ $16bn; CY25 ≈ $10bn (35-40% growth). CY30 = UBS 05-21 on ITS OWN TAM: 29% × $173bn ≈ $50bn (skeptic fix — the earlier $75bn crossed UBS's ‘~40% value share’ from a $60bn-TAM vintage onto a $190bn pool). 2027-29 EST path
A39: NVIDIA CPU chip ASP (Grace / Vera) | B39: $k | C39: 4 | D39: 4 | E39: 4 | F39: 4 | G39: 4 | H39: 4 | I39: PARTIAL | J39: Jefferies bottom-up: standalone Vera ‘at a $4k ASP’ (NVDA.md ~row 1211); BofA Core Wars: Vera $4-5k (assumptions.md server-cpu-tam). Cross-check: 1.2mn units × $4k = $4.8bn ≈ Grace TTM revenue ‘>$5bn’ (NVDA mgmt)
A40: NVIDIA CPU revenue — CHIP basis (Bernstein units × ASP) | B40: $bn | C40: =IF(OR(C28="",C39=""),"",C28*C39) -> 4.8 | D40: =IF(OR(D28="",D39=""),"",D28*D39) -> 10.8 | E40: =IF(OR(E28="",E39=""),"",E28*E39) -> 24.4 | F40: =IF(OR(F28="",F39=""),"",F28*F39) -> 24.4 | G40: =IF(OR(G28="",G39=""),"",G28*G39) -> 24.4 | H40: =IF(OR(H28="",H39=""),"",H28*H39) -> 23.6 | I40: FORMULA | J40: → Arm-NVIDIA units × chip ASP. This is the SILICON figure comparable to NSR's CPU pool
A41: NVIDIA CPU — SYSTEMS-basis reading (scenario, not used in the build) | B41: $bn | C41: 5 | D41: 20 | E41: 40 | I41: SCENARIO | J41: NVDA mgmt (Q2 FY27 call, AMD.md ~row 106): Grace TTM revenue ‘>$5bn’; ‘demand for approximately $20 billion in total server CPUs’ (DEMAND SEEN, not a revenue guide); ‘CPU revenue to more than double in fiscal 28’. Reading the doubling off $20bn gives ~$40bn FY28 (Jefferies/relayed ‘$40bn target’, NVDA.md ~row 1075); off the >$5bn Grace base it gives ~$10bn+ (AMD.md ~row 108). UBS Arcuri: the $20bn is systems + DRAM, ~$5bn / ~1mn units of Vera chip at $3-4k (ARM.md). Skeptic: the earlier build carried NVIDIA at ~2x the $4k chip ASP
A42: Captive Arm + Hygon + others — units (Bernstein, mn) | B42: mn | C42: =C27+C26 -> 4.5 | D42: =D27+D26 -> 6 | E42: =E27+E26 -> 8.6 | F42: =F27+F26 -> 12.6 | G42: =G27+G26 -> 18 | H42: =H27+H26 -> 24.8 | I42: FORMULA | J42: → Arm non-NVIDIA + Hygon units
A43: Captive Arm + Hygon — blended value per unit | B43: $k | C43: 1.2 | D43: 1.2 | E43: 1.2 | F43: 1.2 | G43: 1.2 | H43: 1.2 | I43: EST | J43: Cost-based captive silicon (Graviton/Axion) blended with merchant Hygon (likely $2-3k); no disclosed ASP. Sensitivity: ±$0.5k moves this line ±42%, the 2030 anchor sum ±8%
A44: Captive Arm + Hygon + others — implied revenue | B44: $bn | C44: =IF(OR(C42="",C43=""),"",C42*C43) -> 5.4 | D44: =IF(OR(D42="",D43=""),"",D42*D43) -> 7.2 | E44: =IF(OR(E42="",E43=""),"",E42*E43) -> 10.32 | F44: =IF(OR(F42="",F43=""),"",F42*F43) -> 15.12 | G44: =IF(OR(G42="",G43=""),"",G42*G43) -> 21.6 | H44: =IF(OR(H42="",H43=""),"",H42*H43) -> 29.76 | I44: FORMULA | J44: units × value per unit (EST)
...

Sheet Share_Memory
A1: Memory — vendor market share and implied revenue by pool (HBM / server DRAM / server NAND), 2025-2030 ($bn)
A2: Pools = NSR p.5 lines (HBM inside the XPU; DRAM and NAND as server content) with the Capstone equivalents. HBM shares: Capstone Semis MAP (EST) vs JPM SALES-share path (HARD end-points, interpolated/held EST, plus a slope-continued scenario) vs UBS BIT share (HARD, 2025-27). Server-DRAM shares: total-DRAM bit-supply mix from the Capstone memory bible (PARTIAL proxy). Server-NAND shares: TrendForce 2Q26 enterprise-SSD revenue share (HARD), held flat. NOT ADDITIVE with Share_XPU: HBM dollars sit inside the XPU pool too. Skeptic-revised 2026-09-18.
A4: Line | B4: Unit | C4: 2025 | D4: 2026 | E4: 2027 | F4: 2028 | G4: 2029 | H4: 2030 | I4: Tag | J4: Source
A5: A. Pools ($bn)
A6: HBM — NSR | B6: $bn | C6: =IF(NSR_Memory!C13="","",NSR_Memory!C13) -> 34 | D6: =IF(NSR_Memory!D13="","",NSR_Memory!D13) -> 82 | E6: =IF(NSR_Memory!E13="","",NSR_Memory!E13) -> 189 | F6: =IF(NSR_Memory!F13="","",NSR_Memory!F13) -> 332 | G6: =IF(NSR_Memory!G13="","",NSR_Memory!G13) -> 457 | H6: =IF(NSR_Memory!H13="","",NSR_Memory!H13) -> 560 | I6: LINK | J6: NSR p.5
A7: HBM — Capstone Semis MAP repriced (bits × $/GB) | B7: $bn | C7: =IF(House!E41="","",House!E41) -> 35 | D7: =IF(House!F41="","",House!F41) -> 77.4 | E7: =IF(House!G41="","",House!G41) -> 193.8 | F7: =IF(House!H41="","",House!H41) -> 224 | G7: =IF(House!I41="","",House!I41) -> 255.4 | H7: =IF(House!J41="","",House!J41) -> 283.4 | I7: LINK | J7: House!sm_hbm_rep
A8: HBM — Capstone AI Model HBM Model | B8: $bn | C8: =IF(House!E85="","",House!E85) -> 27 | D8: =IF(House!F85="","",House!F85) -> 63.7 | E8: =IF(House!G85="","",House!G85) -> 127.8 | F8: =IF(House!H85="","",House!H85) -> 281.5 | G8: =IF(House!I85="","",House!I85) | H8: =IF(House!J85="","",House!J85) | I8: LINK | J8: House!am_hbm (CY25-28)
A9: Server DRAM (ex-HBM) — NSR | B9: $bn | C9: =IF(NSR_Memory!C30="","",NSR_Memory!C30) -> 17 | D9: =IF(NSR_Memory!D30="","",NSR_Memory!D30) -> 100 | E9: =IF(NSR_Memory!E30="","",NSR_Memory!E30) -> 211 | F9: =IF(NSR_Memory!F30="","",NSR_Memory!F30) -> 273 | G9: =IF(NSR_Memory!G30="","",NSR_Memory!G30) -> 250 | H9: =IF(NSR_Memory!H30="","",NSR_Memory!H30) -> 241 | I9: LINK | J9: NSR p.5
A10: Fleet DDR5 — Capstone Semis MAP | B10: $bn | C10: =IF(House!E42="","",House!E42) -> 19.5 | D10: =IF(House!F42="","",House!F42) -> 91.3 | E10: =IF(House!G42="","",House!G42) -> 134.4 | F10: =IF(House!H42="","",House!H42) -> 141.8 | G10: =IF(House!I42="","",House!I42) -> 148.2 | H10: =IF(House!J42="","",House!J42) -> 164.9 | I10: LINK | J10: House!sm_ddr
A11: Server NAND — NSR | B11: $bn | C11: =IF(NSR_Memory!C35="","",NSR_Memory!C35) -> 9 | D11: =IF(NSR_Memory!D35="","",NSR_Memory!D35) -> 60 | E11: =IF(NSR_Memory!E35="","",NSR_Memory!E35) -> 127 | F11: =IF(NSR_Memory!F35="","",NSR_Memory!F35) -> 186 | G11: =IF(NSR_Memory!G35="","",NSR_Memory!G35) -> 181 | H11: =IF(NSR_Memory!H35="","",NSR_Memory!H35) -> 182 | I11: LINK | J11: NSR p.5
A12: DC NAND — Capstone Semis MAP | B12: $bn | C12: =IF(House!E43="","",House!E43) -> 22.8 | D12: =IF(House!F43="","",House!F43) -> 119.7 | E12: =IF(House!G43="","",House!G43) -> 182.4 | F12: =IF(House!H43="","",House!H43) -> 204 | G12: =IF(House!I43="","",House!I43) -> 222 | H12: =IF(House!J43="","",House!J43) -> 240 | I12: LINK | J12: House!sm_nand
A14: B. HBM share — three lenses (value unless stated) + slope scenario
A15: SK Hynix — Capstone Semis MAP | B15: % | C15: 0.6 | D15: 0.57 | E15: 0.5 | F15: 0.47 | G15: =F15 -> 0.47 | H15: =F15 -> 0.47 | I15: EST | J15: AI_Chip_Designers_TAM_v11.xlsx → Build | HBM rows 7-9 (2026-07-16). CALIBRATION (corrected): the map is calibrated to the canonical $35bn CY25 HBM TAM (capture 0.621), NOT to SK Hynix's revenue — its implied SK Hynix CY25 is ~$21bn vs an unverified street ~$28bn, an open tension the map flags in its own row 31. CY29-30 held. No ‘others’ plug (CXMT HBM3E not modelled)
A16: Samsung — Capstone Semis MAP | B16: % | C16: 0.17 | D16: 0.18 | E16: 0.25 | F16: 0.28 | G16: =F16 -> 0.28 | H16: =F16 -> 0.28 | I16: EST | J16: same source
A17: Micron — Capstone Semis MAP | B17: % | C17: 0.23 | D17: 0.25 | E17: 0.25 | F17: 0.25 | G17: =F17 -> 0.25 | H17: =F17 -> 0.25 | I17: EST | J17: same source
A18: SK Hynix — JPM sales-share path (2028 held) | B18: % | C18: 0.6 | D18: 0.54 | E18: 0.48 | F18: 0.42 | G18: =F18 -> 0.42 | H18: =F18 -> 0.42 | I18: HARD+EST | J18: JPM · Kwon ‘Global Memory TAM and S&D update’ 2026-08-09/10 (MU.md ~row 615): HBM share BY SALES SK Hynix 60% → 42%, Samsung 20% → 38% (2025 and 2028 printed = HARD), Micron 20/20/21/20 (all four years printed). 2026-27 for SK Hynix/Samsung are straight-line EST (Samsung 2027 back-solved to 31% so the set sums to 100%); CY29-30 HELD at 2028 = EST choice (see slope scenario below)
A19: Samsung — JPM sales-share path (2028 held) | B19: % | C19: 0.2 | D19: 0.26 | E19: 0.31 | F19: 0.38 | G19: =F19 -> 0.38 | H19: =F19 -> 0.38 | I19: HARD+EST | J19: same source
A20: Micron — JPM sales-share path (2028 held) | B20: % | C20: 0.2 | D20: 0.2 | E20: 0.21 | F20: 0.2 | G20: =F20 -> 0.2 | H20: =F20 -> 0.2 | I20: HARD+EST | J20: same source (2025-28 all printed)
A21: SK Hynix — JPM slope CONTINUED (−6pp/yr into 2029-30) | B21: % | G21: 0.36 | H21: 0.3 | I21: SCENARIO | J21: Skeptic: freezing at 2028 stops JPM's −6pp/yr trend exactly at the last printed point; continuing it two more years is an equally defensible reading
A22: Samsung — JPM slope CONTINUED (+6pp/yr into 2029-30) | B22: % | G22: 0.44 | H22: 0.5 | I22: SCENARIO | J22: as above; Micron held at 20%
A23: SK Hynix — UBS (BIT share, not sales share) | B23: % | C23: 0.59 | D23: 0.48 | E23: 0.39 | I23: HARD | J23: UBS Gaudois memory model 2026-07-03 via Memória Capstone dashboard (hbm_ubs = UBS Fig 3 bit supply × Fig 8 share, bn Gb). BIT/volume share: Samsung bins below SK Hynix, so its sales share is lower than its bit share. SKHYNIX.md ‘UBS 2026 HBM share 56/22/22’ is UBS's Dec-2025 overview — an older vintage of the same house, not a conflict
A24: Samsung — UBS (BIT share) | B24: % | C24: 0.2 | D24: 0.3 | E24: 0.41 | I24: HARD | J24: same source. Samsung mgmt: ‘30-40% in 2H26 on HBM4, mid-to-high 30s in 2027’ (hbm-memory theme ~row 915) — a company target, share basis unstated
A25: Micron — UBS (BIT share) | B25: % | C25: 0.21 | D25: 0.21 | E25: 0.2 | I25: HARD | J25: same source; Micron target ‘HBM share = DRAM share’ (~20-25%)
A27: C. Server-DRAM share — total-DRAM bit-supply mix (incl. HBM, all end-markets; server tilt not applied)
A28: Samsung — DRAM bit supply | B28: bn Gb | C28: 120.1 | D28: 146.6 | E28: 173.9 | F28: 213.3 | I28: PARTIAL | J28: Memória Capstone dashboard_data.json seg.sup_dram (bn Gb; sources TrendForce/Bernstein), 2025-28; CY29-30 held (CXMT's bit share is RISING ~1.3pp/yr, so the hold understates CXMT bits and overstates the big three). Wells Fargo (MU.md ~row 702): CXMT ~8% DRAM REVENUE share, ~10% capacity share 1Q26, DDR4/LPDDR4-heavy — bit share overstates CXMT's SERVER relevance
A29: SK Hynix — DRAM bit supply | B29: bn Gb | C29: 93.1 | D29: 117 | E29: 137.3 | F29: 171.1 | I29: PARTIAL | J29: same source (memory bible seg.sup_dram)
A30: Micron — DRAM bit supply | B30: bn Gb | C30: 73.6 | D30: 91 | E30: 107.1 | F30: 135.6 | I30: PARTIAL | J30: same source
A31: CXMT — DRAM bit supply | B31: bn Gb | C31: 22 | D31: 28.4 | E31: 39 | F31: 64 | I31: PARTIAL | J31: same source
A32: Nanya + others — DRAM bit supply | B32: bn Gb | C32: 5.8 | D32: 6.2 | E32: 7 | F32: 9.5 | I32: PARTIAL | J32: same source; residual to the printed total 314.6 / 389.2 / 464.3 / 593.5
A33: Total DRAM bits | B33: bn Gb | C33: =SUM(C28:C32) -> 314.6 | D33: =SUM(D28:D32) -> 389.2 | E33: =SUM(E28:E32) -> 464.3 | F33: =SUM(F28:F32) -> 593.5 | I33: FORMULA
A34: Samsung — DRAM bit share (2029-30 held) | B34: % | C34: =IF(OR(C28="",C33=""),"",C28/C33) -> 0.38175461 | D34: =IF(OR(D28="",D33=""),"",D28/D33) -> 0.37667009 | E34: =IF(OR(E28="",E33=""),"",E28/E33) -> 0.37454232 | F34: =IF(OR(F28="",F33=""),"",F28/F33) -> 0.35939343 | G34: =F34 -> 0.35939343 | H34: =F34 -> 0.35939343 | I34: PARTIAL | J34: bit share as proxy for server-DRAM value share
A35: SK Hynix — DRAM bit share (2029-30 held) | B35: % | C35: =IF(OR(C29="",C33=""),"",C29/C33) -> 0.29593134 | D35: =IF(OR(D29="",D33=""),"",D29/D33) -> 0.30061665 | E35: =IF(OR(E29="",E33=""),"",E29/E33) -> 0.29571398 | F35: =IF(OR(F29="",F33=""),"",F29/F33) -> 0.28828981 | G35: =F35 -> 0.28828981 | H35: =F35 -> 0.28828981 | I35: PARTIAL | J35: bit share as proxy for server-DRAM value share
A36: Micron — DRAM bit share (2029-30 held) | B36: % | C36: =IF(OR(C30="",C33=""),"",C30/C33) -> 0.23394787 | D36: =IF(OR(D30="",D33=""),"",D30/D33) -> 0.23381295 | E36: =IF(OR(E30="",E33=""),"",E30/E33) -> 0.23066983 | F36: =IF(OR(F30="",F33=""),"",F30/F33) -> 0.22847515 | G36: =F36 -> 0.22847515 | H36: =F36 -> 0.22847515 | I36: PARTIAL | J36: bit share as proxy for server-DRAM value share
