Workbook

Sheet README
A1: UBS server CPU x DRAM note (26-Oct-2026) — data + DRAM-CPU link
A3: Source | B3: UBS Global Research (Timothy Arcuri, Seth Cho), 'US Semiconductors: $210B Server CPU TAM By C2030; Gated By Memory Supply', 26-Oct-2026. Page refs are to the PDF (39 pp; disclosures from p.28).
A4: Ratings in note | B4: AMD Buy (CBE) US$516.79; ARM Buy US$210.33; INTC Neutral US$86.96 (PT cut $103 -> $100, SOTP); MU Buy US$877.55 — prices 23-Oct-2026 (p.29). UBS: 'we continue to believe MU is the best way to play server CPU demand'.
A5: What the note says | B5: C2030 server-CPU TAM raised ~$175B -> ~$208B (37MM AI CPUs + 30MM traditional = 67MM units, ~77EB DRAM). 'Unconstrained' demand = ~150MM CPUs / $548B / 282EB DRAM, but memory supply caps it; CPU:GPU attach stays ~0.83:1 in C2030.
A6: Colour code | B6: Blue text = number as printed in the note (or a cross-check source) · Black = formula · Green = link to another sheet · Yellow fill = key lever on the link sheet. Tags on the link sheet: HARD (green) printed in a source, PARTIAL/ANCHOR (blue) range sourced or calibration anchor, ESTIMATE (amber) house assumption, DERIVED (white) arithmetic.
A7: Units | B7: EB = exabytes (1 EB = 1e18 bytes = 1,000,000 TB). 1MM CPUs x 1 TB/CPU = 1 EB, so 'EB per MM units' = 'TB per CPU'. 1Gb-equivalent: 1 EB = 8,000 million Gb (8bn Gb).
A8: Sheet map | B8: DRAM_CPU_Link = the relationship model (start here) · Report_Tieouts = internal arithmetic checks of every table (also validates the transcription) · Cross_Check = independent server-DRAM / CPU anchors (Bernstein, UBS memory team, JPM, Mizuho) · Fig* sheets = one per figure, as printed.
A9: Chart data | B9: Figs 9, 12, 17, 18, 20, 21 carry printed data labels -> transcribed. Figs 25-31 (Mercury/UBSe unit + mix history, 1Q19/1Q21-2Q26; Fig 27 1Q08-2Q26) are unlabeled stacked/area charts: values were extracted from the PDF's vector geometry and cross-checked by pixel measurement (+/-0.01MM, +/-0.05pp; labels +/-0.5pp). Fig 27 quarter mapping confirmed by wiki anchors (Intel x86 revenue share 55.4% 2Q26; AMD 41.3% 4Q25, 39.4% 1Q25). Fig 26 shares match Fig 25 units within 0.11pp.
A10: Model basis | B10: DRAM_CPU_Link runs C2030E on UBS's UNROUNDED standalone count: Fig 11's 0.33 attach x 44MM = 14.5MM (printed '~15'), which at 29EB gives 2.0TB/CPU and reproduces the printed $208B TAM, $160B AI-CPU $, $4,378 ASP and 0.83 attach exactly. Reviewed by an independent skeptic pass (transcription verified against 300-dpi renders; calibration claim downgraded to an identity; scenarios added).
A11: Not tabulated | B11: Fig 13/14 (AMD+ARM and INTC+NVDA management quotes — text exhibits), Fig 22 (ex-server desktop/notebook/gaming roadmap Gantt). Fig 23 server roadmap transcribed with approximate quarters read off the Gantt bars.
A12: Transcription | B12: All tables are images in the PDF (no text layer). Read from 300+ dpi renders; every arithmetic identity in the note is re-computed on Report_Tieouts — rows that do not tie are either rounding (|diff| <= rounding of the printed figure) or a flagged inconsistency in the note itself.

Sheet Summary
A1: DRAM <-> server CPU: what the UBS note implies (C2030E unless stated)
A2: Every number below is a live link into DRAM_CPU_Link / Report_Tieouts / Cross_Check — change a yellow lever there and this page moves.
A4: Relationship | B4: Value | C4: Unit | D4: Read-across
A5: 1. DRAM per CPU shipped (UBS C2030E base, Fig 8 implied)
A6: traditional CPU | B6: =DRAM_CPU_Link!D13 -> 0.5 | C6: TB | D6: 0.5TB in every year — Fig 5 / p.6 / Fig 15 say ~1TB by C2030E
A7: AI head-node CPU | B7: =DRAM_CPU_Link!D14 -> 1.5 | C7: TB | D7: 1.0TB today -> 1.5TB (low end of Fig 5)
A8: AI standalone CPU | B8: =DRAM_CPU_Link!D15 -> 1.9972452 | C8: TB | D8: 29EB / 14.5MM; 4x a traditional CPU (low end of Fig 5's 2-3TB)
A9: blended, C2025 | B9: =DRAM_CPU_Link!B16 -> 0.60869565 | C9: TB | D9: on UBS's 23MM base (~0.4-0.47TB on the ~30MM in Fig 25 / Bernstein)
A10: blended, C2030E | B10: =DRAM_CPU_Link!D16 -> 1.1492537 | C10: TB | D10: mix shift alone ~doubles DRAM per new CPU
A11: 2. The identity
A12: DRAM for CPUs C2030E = 30MM x 0.5 + 22MM x 1.5 + 14.5MM x 2.0 | B12: =DRAM_CPU_Link!D22 -> 77 | C12: EB | D12: Equals Fig 7 supply (69EB server + 7EB CXL). UBS sized the base so CPU DRAM = its supply estimate (an identity, not proof that memory set the count)
A13: unconstrained need, 147MM CPUs on UBS's TB/CPU | B13: =DRAM_CPU_Link!F22 -> 238 | C13: EB | D13: printed 282EB is on 169MM CPUs, inconsistent with Fig 4 / the text (147-150MM); at Fig 5 midpoints ~306EB (~4x). Supply covers ~1/4-1/3
A14: 3. Exchange rates at the margin (C2030E)
A15: AI standalone CPUs per +1EB of DRAM | B15: =DRAM_CPU_Link!B45 -> 0.50068966 | C15: MM
A16: CPU TAM per +1EB of DRAM (standalone) | B16: =DRAM_CPU_Link!B46 -> 2.1144124 | C16: $B | D16: vs $3.0B (head-node) / $3.2B (traditional): standalone is the least TAM-dense use of DRAM
A17: 1MM AI CPUs as % of C2030E server DRAM | B17: =DRAM_CPU_Link!B47 -> 0.028945582 | C17: %
A18: -0.1TB de-spec on all AI CPUs -> extra CPU TAM | B18: =DRAM_CPU_Link!B52 -> 7.7218341 | C18: $B
A19: 4. What the ~$208B needs (scenarios, CPU TAM $B)
A20: UBS base | B20: =DRAM_CPU_Link!G112 -> 208.05796 | C20: $B | D20: every class at/below the LOW END of Fig 5, and the HIGHER (99EB) of UBS's two supply bases
A21: supply on Fig 6 vendor-capacity basis (66EB) | B21: =DRAM_CPU_Link!G113 -> 184.79942 | C21: $B
A22: traditional CPUs at Fig 5's ~1TB | B22: =DRAM_CPU_Link!G115 -> 176.34177 | C22: $B
A23: all classes at Fig 5 midpoints | B23: =DRAM_CPU_Link!G120 -> 161.0982 | C23: $B
A24: head nodes at Vera's post-cut 768GB | B24: =DRAM_CPU_Link!G117 -> 242.10846 | C24: $B | D24: de-spec is the upside lever: memory per CPU, not CPU demand, sets the unit count
A25: 5. Dollars and watts
A26: DRAM $ per standalone AI CPU / its $4.2K ASP (at $12K/TB) | B26: =DRAM_CPU_Link!D63 -> 5.6753356 | C26: x | D26: 4.7-5.7x across $10-12K/TB: memory is the bigger dollar pool (UBS: MU is the best way to play CPU demand)
A27: C2030E DRAM bill for CPUs at $10K/TB (Fig 15's implied price) | B27: =DRAM_CPU_Link!C67 -> 770 | C27: $B | D27: $385B at $5K/TB to $1.6T at UBS's 2027E DDR ASP — vs a ~$208B CPU TAM
A28: DRAM per GW of CPU+DIMM power — traditional / AI (Fig 15 spec) | B28: =DRAM_CPU_Link!B78 -> 2.7027027 | C28: EB/GW | D28: 2.70 vs 2.90 on Fig 15's illustrative 1TB/2TB spec; 1.35 vs 2.90 on Fig 8's 0.5TB
A29: CPU-side DRAM per accelerator, C2030E | B29: =DRAM_CPU_Link!D24 -> 1.4090909 | C29: TB/GPU | D29: 1.8-4.9x the GPU's own HBM, depending on generation (Feynman 768GB -> VR200 288GB)
A30: 6. Checks
A31: Report tie-outs | B31: =Report_Tieouts!C97 -> 78 OK / 12 FLAG | D31: FLAGs = inconsistencies inside the note itself (transcription re-read for each)

Sheet DRAM_CPU_Link
A1: DRAM <-> server CPU: the relationship in UBS's 26-Oct-2026 framework (live model)
A2: Identity: DRAM for CPUs (EB) = SUM over CPU types [ units (MM) x DRAM per CPU (TB) ]. Supply-gated: standalone AI CPUs = (DRAM available for CPUs - traditional EB - head-node EB) / TB per standalone CPU. Blue = UBS as printed (linked from Fig sheets in green), yellow = levers you can change.
A4: A. Units and DRAM intensity, as printed (Fig 8 / Fig 10-11)
A5: Line | B5: C2025 | C5: C2027E | D5: C2030E Base | E5: C2030E Unconstr. (as printed) | F5: C2030E Unconstr. (corrected) | G5: Tag | H5: Source / note
A6: Traditional CPUs (MM) | B6: =Fig08_09_DRAM_Demand!B5 -> 20 | C6: =Fig08_09_DRAM_Demand!D5 -> 26 | D6: =Fig08_09_DRAM_Demand!F5 -> 30 | E6: =Fig08_09_DRAM_Demand!H5 -> 30 | F6: =E6 -> 30 | G6: HARD | H6: Fig 8 (p.7); corrected column = Fig 4
A7: AI head-node CPUs (MM) | B7: =Fig08_09_DRAM_Demand!B6 -> 3 | C7: =Fig08_09_DRAM_Demand!D6 -> 11 | D7: =Fig08_09_DRAM_Demand!F6 -> 22 | E7: =Fig08_09_DRAM_Demand!H6 -> 22 | F7: =E7 -> 22 | G7: HARD | H7: Fig 8 (p.7); corrected column = Fig 4
A8: AI standalone CPUs (MM) | B8: =Fig08_09_DRAM_Demand!B7 -> 0 | C8: =Fig08_09_DRAM_Demand!D7 -> 5 | D8: =Fig10_12_TAM!D34*D10 -> 14.52 | E8: =Fig08_09_DRAM_Demand!H7 -> 117 | F8: =Fig04_Unconstrained!D9 -> 95 | G8: HARD | H8: C2030E base = Fig 11 attach 0.33 x 44 = 14.5MM (printed '~15'): the unrounded value reproduces $208B TAM, $160B AI $, $4,378 ASP, 0.83 attach and 29EB at 2.0TB. Unconstrained: Fig 8 prints 117 (equal to Fig 4's total AI CPUs 22+95; mechanism not provable); corrected column uses Fig 4's 95
A9: Total CPUs (MM) | B9: =SUM(B6:B8) -> 23 | C9: =SUM(C6:C8) -> 42 | D9: =SUM(D6:D8) -> 66.52 | E9: =SUM(E6:E8) -> 169 | F9: =SUM(F6:F8) -> 147 | G9: DERIVED | H9: Printed: 23 / 41 / 67 / 169; Fig 4 + text: ~147-150MM unconstrained
A10: Accelerators (MM) | B10: =Fig10_12_TAM!B11 -> 9 | C10: =Fig10_12_TAM!C11 -> 29 | D10: =Fig10_12_TAM!D11 -> 44 | E10: =Fig10_12_TAM!D11 -> 44 | F10: =Fig10_12_TAM!D11 -> 44 | G10: HARD | H10: Fig 10 / Fig 4 (~44MM in C2030, ex-China)
A12: DRAM per CPU (TB) — implied by Fig 8 (EB / MM units)
A13: TB per traditional CPU | B13: =Fig08_09_DRAM_Demand!C12 -> 0.5 | C13: =Fig08_09_DRAM_Demand!E12 -> 0.46153846 | D13: =Fig08_09_DRAM_Demand!G12 -> 0.5 | E13: =Fig08_09_DRAM_Demand!I12 -> 0.5 | F13: =E13 -> 0.5 | G13: HARD | H13: Implied 0.5TB in every year incl. C2030E (also in the unconstrained column) — while Fig 5, the p.6 text and Fig 15/16 all use ~1.0TB by C2030E (see section D/G2)
A14: TB per head-node CPU | B14: =Fig08_09_DRAM_Demand!C13 -> 1 | C14: =Fig08_09_DRAM_Demand!E13 -> 1 | D14: =Fig08_09_DRAM_Demand!G13 -> 1.5 | E14: =Fig08_09_DRAM_Demand!I13 -> 1.5 | F14: =E14 -> 1.5 | G14: HARD | H14: 1.0 / 1.0 / 1.5TB — at the LOW END of Fig 5's ~1-1.5TB (25/27) and ~1.5-2TB (30E) ranges
A15: TB per standalone CPU | B15: =Fig08_09_DRAM_Demand!C14 | C15: =Fig08_09_DRAM_Demand!E14 -> 1.4 | D15: =Fig08_09_DRAM_Demand!G7/D8 -> 1.9972452 | E15: =Fig08_09_DRAM_Demand!I14 -> 2 | F15: =E15 -> 2 | G15: HARD | H15: 1.4 (2027E, below Fig 5's 1.5-2) / 2.0 (C2030E = 29EB / 14.5MM; unconstrained 234/117 = 2.0) — LOW END of Fig 5's ~2-3TB
A16: Blended TB per CPU shipped (all CPUs) | B16: =Fig08_09_DRAM_Demand!C9/Fig08_09_DRAM_Demand!B8 -> 0.60869565 | C16: =Fig08_09_DRAM_Demand!E9/Fig08_09_DRAM_Demand!D8 -> 0.70731707 | D16: =Fig08_09_DRAM_Demand!G9/Fig08_09_DRAM_Demand!F8 -> 1.1492537 | E16: =Fig08_09_DRAM_Demand!I9/Fig08_09_DRAM_Demand!H8 -> 1.6686391 | F16: =F22/F9 -> 1.6190476 | G16: DERIVED | H16: Printed EB / printed units: 0.6 -> 0.7 -> 1.15TB per CPU shipped — mix alone roughly doubles DRAM per new CPU by C2030E (a flow, not the installed fleet)
A17: Blended TB per AI CPU (head-node + standalone) | B17: =IFERROR((B20+B21)/(B7+B8),"") -> 1 | C17: =IFERROR((C20+C21)/(C7+C8),"") -> 1.125 | D17: =IFERROR((D20+D21)/(D7+D8),"") -> 1.6976999 | E17: =IFERROR((E20+E21)/(E7+E8),"") -> 1.9208633 | F17: =IFERROR((F20+F21)/(F7+F8),"") -> 1.9059829 | G17: DERIVED | H17: C2030E base ~1.70TB vs Fig 5's 'Blended AI CPU ~2-2.5TB' — below UBS's own stated range
A18: B. DRAM demand identity (EB = MM x TB) — recomputed
A19: Traditional EB | B19: =IF(B13="",0,B6*B13) -> 10 | C19: =IF(C13="",0,C6*C13) -> 12 | D19: =IF(D13="",0,D6*D13) -> 15 | E19: =IF(E13="",0,E6*E13) -> 15 | F19: =IF(F13="",0,F6*F13) -> 15 | G19: DERIVED
A20: Head-node EB | B20: =IF(B14="",0,B7*B14) -> 3 | C20: =IF(C14="",0,C7*C14) -> 11 | D20: =IF(D14="",0,D7*D14) -> 33 | E20: =IF(E14="",0,E7*E14) -> 33 | F20: =IF(F14="",0,F7*F14) -> 33 | G20: DERIVED
A21: Standalone EB | B21: =IF(B15="",0,B8*B15) -> 0 | C21: =IF(C15="",0,C8*C15) -> 7 | D21: =IF(D15="",0,D8*D15) -> 29 | E21: =IF(E15="",0,E8*E15) -> 234 | F21: =IF(F15="",0,F8*F15) -> 190 | G21: DERIVED
A22: Total DRAM for CPUs (EB) | B22: =SUM(B19:B21) -> 13 | C22: =SUM(C19:C21) -> 30 | D22: =SUM(D19:D21) -> 77 | E22: =SUM(E19:E21) -> 282 | F22: =SUM(F19:F21) -> 238 | G22: DERIVED | H22: Printed: 14 / 29 / 77 / 282 EB. Corrected unconstrained (147MM, Fig 4) = ~238EB on UBS's own TB/CPU = 3.1x base (not 3.5-3.7x); at Fig 5 midpoints the same 147MM need ~306EB (~4x, the figure title)
A23: Printed implied DRAM (EB) | B23: =Fig08_09_DRAM_Demand!C9 -> 14 | C23: =Fig08_09_DRAM_Demand!E9 -> 29 | D23: =Fig08_09_DRAM_Demand!G9 -> 77 | E23: =Fig08_09_DRAM_Demand!I9 -> 282 | G23: HARD | H23: Fig 8
A24: Head-node + standalone DRAM per accelerator (TB/GPU) | B24: =(B20+B21)/B10 -> 0.33333333 | C24: =(C20+C21)/C10 -> 0.62068966 | D24: =(D20+D21)/D10 -> 1.4090909 | E24: =(E20+E21)/E10 -> 6.0681818 | F24: =(F20+F21)/F10 -> 5.0681818 | G24: DERIVED | H24: Conventional DRAM pulled by AI CPUs per accelerator: 0.33 -> 0.62 -> 1.41TB (base). vs HBM per GPU: VR200 288GB / VR300 384-512GB / Feynman 768GB (Cross_Check) -> ~1.8-4.9x depending on GPU generation. The 44MM accelerators include TPU/Trainium
A26: C. Supply gate (Fig 6-7): how many CPUs the DRAM supply can carry
A27: Line | B27: C2025 | C27: C2027E | D27: C2030E Base | E27: C2030E Unconstr. (as printed) | F27: C2030E Unconstr. (corrected) | G27: Tag | H27: Source / note
A28: Server DRAM available (EB) | B28: =Fig06_07_DRAM_Supply!B19 -> 11 | C28: =Fig06_07_DRAM_Supply!C19 -> 27 | D28: =Fig06_07_DRAM_Supply!D19 -> 69 | E28: =Fig06_07_DRAM_Supply!D19 -> 69 | F28: =Fig06_07_DRAM_Supply!D19 -> 69 | G28: HARD | H28: Fig 7: non-HBM total on 'MU share' basis (36/54/99) minus non-server (26/27/30)
A29: Old DDR reuse via CXL (EB) | B29: 0 | C29: =Fig06_07_DRAM_Supply!C20 -> 2 | D29: =Fig06_07_DRAM_Supply!D20 -> 7 | E29: =Fig06_07_DRAM_Supply!D20 -> 7 | F29: =Fig06_07_DRAM_Supply!D20 -> 7 | G29: HARD | H29: Fig 7 (7EB = 10% of 2030 server DRAM vs text's +6-8%)
A30: DRAM available for CPUs (EB) — lever | B30: =Fig06_07_DRAM_Supply!B21 -> 11 | C30: =Fig06_07_DRAM_Supply!C21 -> 29 | D30: =Fig06_07_DRAM_Supply!D21 -> 77 | E30: =Fig06_07_DRAM_Supply!D21 -> 77 | F30: =Fig06_07_DRAM_Supply!D21 -> 77 | G30: HARD | H30: Fig 7 bottom line 11 / 29 / 77 (server + CXL = 11 / 29 / 76 — rounding). Overwrite to test other supply
A31: Coverage: DRAM available / DRAM demanded | B31: =B30/B22 -> 0.84615385 | C31: =C30/C22 -> 0.96666667 | D31: =D30/D22 -> 1 | E31: =E30/E22 -> 0.27304965 | F31: =F30/F22 -> 0.32352941 | G31: DERIVED | H31: C2025 85%: the note's own 2025 numbers disagree (Fig 8 demand 14EB vs Fig 7 supply 11EB; inventory not modelled). C2030E base = 100% by construction; unconstrained ~27% (printed) / ~32% (corrected) covered
A32: Standalone CPUs that fit = (avail - trad EB - head EB) / TB per standalone | C32: =MAX(0,(C30-C19-C20)/C15) -> 4.2857143 | D32: =MAX(0,(D30-D19-D20)/D15) -> 14.52 | E32: =MAX(0,(E30-E19-E20)/E15) -> 14.5 | F32: =MAX(0,(F30-F19-F20)/F15) -> 14.5 | G32: DERIVED | H32: IDENTITY, not a calibration: Fig 8's C2030E column sums to Fig 7's 77EB, so this returns UBS's 14.5MM by construction. It shows UBS sized the base so CPU DRAM = its supply estimate; it cannot show whether memory or demand set the count (the 0.33 standalone attach is unchanged from UBS's pre-memory framework). Use it as the flex tool
A33: Memory-gated total CPUs (MM) | C33: =C6+C7+C32 -> 41.285714 | D33: =D6+D7+D32 -> 66.52 | E33: =E6+E7+E32 -> 66.5 | F33: =F6+F7+F32 -> 66.5 | G33: DERIVED
A34: Memory-gated CPU:GPU attach (AI CPUs / accelerators) | C34: =(C7+C32)/C10 -> 0.5270936 | D34: =(D7+D32)/D10 -> 0.83 | E34: =(E7+E32)/E10 -> 0.82954545 | F34: =(F7+F32)/F10 -> 0.82954545 | G34: DERIVED | H34: UBS: 0.83:1 in C2030 'unchanged from our prior estimate' — practitioners want 3-4:1
A35: ASP traditional ($) | B35: =Fig10_12_TAM!B8 -> 1200 | C35: =Fig10_12_TAM!C8 -> 1348 | D35: =Fig10_12_TAM!D8 -> 1606 | E35: =Fig10_12_TAM!D8 -> 1606 | F35: =Fig10_12_TAM!D8 -> 1606 | G35: HARD | H35: Fig 10
A36: ASP head-node ($) | B36: =Fig10_12_TAM!B32 -> 2430 | C36: =Fig10_12_TAM!C32 -> 3160 | D36: =Fig10_12_TAM!D32 -> 4480 | E36: =Fig10_12_TAM!D32 -> 4480 | F36: =Fig10_12_TAM!D32 -> 4480 | G36: HARD | H36: Fig 11
A37: ASP standalone ($) | B37: 0 | C37: =Fig10_12_TAM!C35 -> 2850 | D37: =Fig10_12_TAM!D35 -> 4223 | E37: =Fig10_12_TAM!D35 -> 4223 | F37: =Fig10_12_TAM!D35 -> 4223 | G37: HARD | H37: Fig 11 (no standalone in 2025)
A38: Memory-gated CPU TAM ($B) | C38: =(C6*C35+C7*C36+C32*C37)/1000 -> 82.022286 | D38: =(D6*D35+D7*D36+D32*D37)/1000 -> 208.05796 | E38: =(E6*E35+E7*E36+E32*E37)/1000 -> 207.9735 | F38: =(F6*F35+F7*F36+F32*F37)/1000 -> 207.9735 | G38: DERIVED | H38: C2030E base reproduces $208.0B on the unrounded 14.5MM; C2027E $82B vs printed $83B (rounded 2027 inputs). Unconstrained columns are capped by the same 77EB
A40: D. Rules of thumb (C2030E base) — the DRAM<->CPU exchange rates
A41: Rule | B41: Value | C41: Unit | G41: Tag | H41: How it is computed / caveat
A42: DRAM per 1MM standalone AI CPUs | B42: =D15 -> 1.9972452 | C42: EB | G42: DERIVED | H42: TB per standalone CPU (1MM x 1TB = 1EB)
A43: DRAM per 1MM head-node CPUs | B43: =D14 -> 1.5 | C43: EB | G43: DERIVED
A44: DRAM per 1MM traditional CPUs | B44: =D13 -> 0.5 | C44: EB | G44: DERIVED
...

Sheet Cross_Check
A1: Cross-check: independent anchors for server DRAM and DRAM-per-CPU
A2: Independent of the CPU note: other houses' / other UBS teams' server-DRAM models on P:\Felipe Monteiro\Memória and wiki-logged spec marks. Read the basis column before comparing.
A3: Source: UBS Global Research (Timothy Arcuri, Seth Cho), 'US Semiconductors: $210B Server CPU TAM By C2030; Gated By Memory Supply', 26-Oct-2026
A5: Series | B5: 2023 | C5: 2024 | D5: 2025 | E5: 2026E | F5: 2027E | G5: 2028E | H5: 2030E | I5: Unit | J5: Source / basis
A6: 1. Server DRAM (ex-HBM), EB
A7: UBS CPU note — Fig 7 server DRAM | D7: =Fig06_07_DRAM_Supply!B19 -> 11 | F7: =Fig06_07_DRAM_Supply!C19 -> 27 | H7: =Fig06_07_DRAM_Supply!D19 -> 69 | I7: EB | J7: UBS (Arcuri) 26-Oct-26, Fig 7 (ex-CXL)
A8: UBS CPU note — Fig 8 implied DRAM for CPUs | D8: =Fig08_09_DRAM_Demand!C9 -> 14 | F8: =Fig08_09_DRAM_Demand!E9 -> 29 | H8: =Fig08_09_DRAM_Demand!G9 -> 77 | I8: EB | J8: UBS (Arcuri) 26-Oct-26, Fig 8 (base case, incl. CXL reuse)
A9: Bernstein S&D — server (non-HBM) DRAM demand | B9: 64199.926 | C9: 75305.64 | D9: 96496.206 | E9: 142810.46 | F9: 185467.94 | G9: 223952.54 | I9: M Gb | J9: Bernstein 'S&D' tab row 142, model 'Updated on Jun, 2026' (P:\...\Memória\Bernstein SxD.xlsx)
A10: = EB | B10: =B9/8000 -> 8.0249908 | C10: =C9/8000 -> 9.413205 | D10: =D9/8000 -> 12.062026 | E10: =E9/8000 -> 17.851307 | F10: =F9/8000 -> 23.183493 | G10: =G9/8000 -> 27.994068 | I10: EB | J10: 1 EB = 8,000 M Gb
A11: UBS memory team — server DRAM demand | B11: 59038.759 | C11: 75088.562 | D11: 118057.13 | E11: 179619.94 | F11: 312207.3 | I11: M Gb | J11: UBS Global DRAM NAND model (client file 3-Jul-26; Gaudois/Arcuri memory team), 'DRAM Demand' row 188
A12: = EB | B12: =B11*128/1000000 -> 7.5569612 | C12: =C11*128/1000000 -> 9.6113359 | D12: =D11*128/1000000 -> 15.111312 | E12: =E11*128/1000000 -> 22.991352 | F12: =F11*128/1000000 -> 39.962534 | I12: EB | J12: The UBS model builds its Gb as units x MB x 8/1024, so EB = M Gb x 128/1e6 (= units x content); /8000 would understate by 2.4%. Bernstein/UBS-memory rows are END-DEMAND (unconstrained); the CPU note's Fig 7 is a supply allocation
A14: 2. Server CPU / server units
A15: UBS CPU note — bottom-up CPU units | D15: =Fig10_12_TAM!B22 -> 23 | F15: =Fig10_12_TAM!C22 -> 41 | H15: =Fig10_12_TAM!D22 -> 67 | I15: MM CPUs | J15: UBS Fig 10 (Mercury-based x86+ARM; text: ~23MM CPUs shipped C2025)
A16: Bernstein — server CPUs using DIMM package | B16: 22.81086 | C16: 24.098935 | D16: 30.57085 | E16: 37.281171 | F16: 45.536678 | G16: 55.425041 | I16: MM CPUs | J16: Bernstein China Semis 'Global Memory Interface Chips' model, row 14 (file dated 13-Jul-26 on P:); incl. Hygon + non-NVDA ARM
A17: JPM — server CPU units | D17: 26 | G17: 68 | I17: MM CPUs | J17: JPM proprietary server-CPU model (Hung/Hariharan) 12-Jul-26, via wiki assumptions.md server-cpu-tam; 38% CAGR, agentic 155% CAGR
A18: UBS note Fig 25 (Mercury/UBSe) x86+ARM units — sum of 4 quarters | B18: =SUMPRODUCT((RIGHT(Fig25_CPU_Units_digitized!$A$6:$A$35,2)="23")*Fig25_CPU_Units_digitized!$E$6:$E$35) -> 24.503 | C18: =SUMPRODUCT((RIGHT(Fig25_CPU_Units_digitized!$A$6:$A$35,2)="24")*Fig25_CPU_Units_digitized!$E$6:$E$35) -> 24.204 | D18: =SUMPRODUCT((RIGHT(Fig25_CPU_Units_digitized!$A$6:$A$35,2)="25")*Fig25_CPU_Units_digitized!$E$6:$E$35) -> 29.894 | I18: MM CPUs | J18: Same note, p.18 chart (vector geometry, +/-0.01MM/qtr): 2025 = Intel 18.6 + AMD 7.2 + ARM 4.1 = ~29.9MM — vs the 23MM base of its own TAM table; matches Bernstein's 30.6MM
A19: Bernstein S&D — server SYSTEM units | B19: 12.818458 | C19: 13.074828 | D19: 14.05544 | E19: 16.023201 | F19: 17.785753 | G19: 18.675041 | I19: MM servers | J19: Bernstein S&D row 138 (servers, not CPUs)
A20: UBS memory team — server units | B20: 14.086865 | C20: 16.02536 | D20: 20.078 | E20: 23.8741 | F20: 27.84415 | I20: MM servers | J20: UBS DRAM model 'DRAM Demand' row 24 (Gartner actuals)
A22: 3. DRAM intensity
A23: UBS CPU note — blended TB per CPU | D23: =DRAM_CPU_Link!B16 -> 0.60869565 | F23: =DRAM_CPU_Link!C16 -> 0.70731707 | H23: =DRAM_CPU_Link!D16 -> 1.1492537 | I23: TB/CPU | J23: Fig 8 EB / Fig 8 units
A24: Bernstein — TB per CPU (S&D EB / CPU-model units) | B24: =B10/B16 -> 0.35180572 | C24: =C10/C16 -> 0.39060669 | D24: =D10/D16 -> 0.39455971 | E24: =E10/E16 -> 0.47882904 | F24: =F10/F16 -> 0.50911691 | G24: =G10/G16 -> 0.50507978 | I24: TB/CPU | J24: Two Bernstein files (different teams/dates) combined — basis: all DIMM-socket CPUs incl. China
A25: Bernstein S&D — GB per server system | B25: 626.0496 | C25: 719.94869 | D25: 858.17491 | E25: 1114.0912 | F25: 1303.4867 | G25: 1499.0097 | I25: GB/server | J25: Bernstein S&D row 140
A26: UBS memory team — GB per server | B26: 536.45443 | C26: 599.75788 | D26: 752.63035 | E26: 963.02488 | F26: 1435.2219 | I26: GB/server | J26: UBS DRAM model row 117 (MB/server / 1000)
A27: Bernstein — DIMMs per CPU | B27: 7.8858252 | C27: 8.9237201 | D27: 8.9798091 | E27: 9.5418592 | F27: 10.347981 | G27: 11.664184 | I27: DIMMs/CPU | J27: Bernstein memory-interface model row 45 (12/16-channel mix rising; GP slots 50% / AI 70% occupied)
A28: implied GB per DIMM | B28: =B24*1000/B27 -> 44.612416 | C28: =C24*1000/C27 -> 43.771732 | D28: =D24*1000/D27 -> 43.938541 | E28: =E24*1000/E27 -> 50.181944 | F28: =F24*1000/F27 -> 49.199638 | G28: =G24*1000/G27 -> 43.301768 | I28: GB/DIMM | J28: vs UBS Fig 15: 1TB/8 DIMMs = 125GB (trad), 2TB/16 = 125GB (AI)
A30: 4. Spec-level anchors (per CPU / per GPU)
A31: Anchor | B31: Value | C31: Unit | D31: Source (as logged on the wiki)
A32: NVDA Grace LPDDR per CPU | B32: 0.5 | C32: TB | D32: Mizuho (DELL note) 2026-06-03 — '~500GB Grace' (NVDA.md)
A33: NVDA Vera SOCAMM per CPU — original spec | B33: 1.5 | C33: TB | D33: Mizuho 2026-06-03; DAMNANG 2026-04-25 (independent author) — 1.5TB LPDDR5X
A34: NVDA Vera SOCAMM per CPU — after supply-driven cut | B34: 0.768 | C34: TB | D34: JPM (Harlan Sur) 2026-08-24; JPM memory (Jay Kwon) 2026-08-09 — 'cut 50%, to 768GB per CPU from 1.5TB', 'driven almost exclusively by supply tightness'
A35: Vera CPU-only rack: 256 CPUs ~400TB | B35: 1.5625 | C35: TB/CPU | D35: Mizuho 2026-06-03 (~7.9k CPU-only racks 2026E -> ~3EB DRAM)
A36: HBM per GPU — VR200 (Rubin) | B36: 0.288 | C36: TB | D36: Mizuho (Vijay Rakesh) 2026-08-16 — 288GB HBM4 flat GB300 -> VR200
A37: HBM per GPU — VR300 initial / later | B37: 0.384 | C37: TB | D37: UBS (Gaudois/Arcuri) Memory Semis Monthly 2026-08-07 — 384GB HBM4, then 512GB HBM4E (vs prior 768GB)
A38: HBM per GPU — VR300 HBM4E | B38: 0.512 | C38: TB | D38: UBS 2026-08-07
A39: UBS C2030E head-node DRAM per CPU (this note) | B39: =DRAM_CPU_Link!D14 -> 1.5 | C39: TB | D39: UBS Fig 8 implied (33EB / 22MM)
A40: UBS C2030E CPU-side DRAM per accelerator (this note) | B40: =DRAM_CPU_Link!D24 -> 1.4090909 | C40: TB/GPU | D40: DRAM_CPU_Link section B

Sheet Report_Tieouts
A1: Report tie-outs: every arithmetic identity in the note, recomputed
A2: OK = ties within the stated tolerance (rounding of printed figures). FLAG = does not tie — an inconsistency in the note itself (the transcription was re-read for each FLAG).
A3: Source: UBS Global Research (Timothy Arcuri, Seth Cho), 'US Semiconductors: $210B Server CPU TAM By C2030; Gated By Memory Supply', 26-Oct-2026
A5: # | B5: Figure | C5: Check | D5: Printed | E5: Recomputed | F5: Tolerance | G5: Status | H5: Comment
A6: 1 | B6: Fig 6 | C6: Vendor capacities sum to total (2025) | D6: =Fig06_07_DRAM_Supply!B10 -> 36 | E6: =Fig06_07_DRAM_Supply!B11 -> 36 | F6: 1 | G6: =IF(ABS(E6-D6)<=F6,"OK","FLAG") -> OK | H6: rounding
A7: 2 | B7: Fig 6 | C7: Vendor capacities sum to total (2027E) | D7: =Fig06_07_DRAM_Supply!C10 -> 55 | E7: =Fig06_07_DRAM_Supply!C11 -> 54 | F7: 1 | G7: =IF(ABS(E7-D7)<=F7,"OK","FLAG") -> OK | H7: rounding
A8: 3 | B8: Fig 6 | C8: Vendor capacities sum to total (2030E) | D8: =Fig06_07_DRAM_Supply!D10 -> 89 | E8: =Fig06_07_DRAM_Supply!D11 -> 89 | F8: 1 | G8: =IF(ABS(E8-D8)<=F8,"OK","FLAG") -> OK | H8: rounding
A9: 4 | B9: Fig 7 | C9: Server DRAM = MU-share total - non-server (2025) | D9: =Fig06_07_DRAM_Supply!B19 -> 11 | E9: =Fig06_07_DRAM_Supply!B22 -> 10 | F9: 1 | G9: =IF(ABS(E9-D9)<=F9,"OK","FLAG") -> OK
A10: 5 | B10: Fig 7 | C10: Server DRAM = MU-share total - non-server (2027E) | D10: =Fig06_07_DRAM_Supply!C19 -> 27 | E10: =Fig06_07_DRAM_Supply!C22 -> 27 | F10: 1 | G10: =IF(ABS(E10-D10)<=F10,"OK","FLAG") -> OK
A11: 6 | B11: Fig 7 | C11: Server DRAM = MU-share total - non-server (2030E) | D11: =Fig06_07_DRAM_Supply!D19 -> 69 | E11: =Fig06_07_DRAM_Supply!D22 -> 69 | F11: 1 | G11: =IF(ABS(E11-D11)<=F11,"OK","FLAG") -> OK
A12: 7 | B12: Fig 7 | C12: Server DRAM on Fig 6 vendor-capacity basis (2030E) | D12: =Fig06_07_DRAM_Supply!D19 -> 69 | E12: =Fig06_07_DRAM_Supply!D23 -> 59 | F12: 1 | G12: =IF(ABS(E12-D12)<=F12,"OK","FLAG") -> FLAG | H12: 69EB uses the 99EB 'MU share' total; on the 89EB vendor-sum total it is 59EB (66EB incl. CXL) — a 10EB basis gap inside the note
A13: 8 | B13: Fig 6 vs 7 | C13: Micron capacity (Fig 6) vs MU DRAM ex-HBM (Fig 7), 2030E | D13: =Fig06_07_DRAM_Supply!D8 -> 26 | E13: =Fig06_07_DRAM_Supply!D15 -> 23 | F13: 1 | G13: =IF(ABS(E13-D13)<=F13,"OK","FLAG") -> FLAG | H13: 26EB vs 23EB for the same vendor/year
A14: 9 | B14: Fig 7 | C14: DRAM for CPUs = server + CXL (2027E) | D14: =Fig06_07_DRAM_Supply!C21 -> 29 | E14: =Fig06_07_DRAM_Supply!C19+Fig06_07_DRAM_Supply!C20 -> 29 | F14: 1 | G14: =IF(ABS(E14-D14)<=F14,"OK","FLAG") -> OK
A15: 10 | B15: Fig 7 | C15: DRAM for CPUs = server + CXL (2030E) | D15: =Fig06_07_DRAM_Supply!D21 -> 77 | E15: =Fig06_07_DRAM_Supply!D19+Fig06_07_DRAM_Supply!D20 -> 76 | F15: 1 | G15: =IF(ABS(E15-D15)<=F15,"OK","FLAG") -> OK
A16: 11 | B16: Fig 7 vs text | C16: CXL reuse as % of DRAM for CPUs, 2030E (p.2: 'high-single digits') | D16: =0.08 -> 0.08 | E16: =Fig06_07_DRAM_Supply!D20/Fig06_07_DRAM_Supply!D21 -> 0.090909091 | F16: 0.02 | G16: =IF(ABS(E16-D16)<=F16,"OK","FLAG") -> OK | H16: 7/77 = 9.1% fits 'high-single digits'; META math 25% x 25-33% = 6.25-8.25% of fleet memory (p.7 '+6-8%'); 7/69 = 10% of server DRAM — a note, not an error
A17: 12 | B17: Fig 7 vs 8 | C17: C2025 DRAM for CPUs: Fig 7 vs Fig 8 | D17: =Fig06_07_DRAM_Supply!B21 -> 11 | E17: =Fig08_09_DRAM_Demand!C9 -> 14 | F17: 1 | G17: =IF(ABS(E17-D17)<=F17,"OK","FLAG") -> FLAG | H17: 11EB (supply view) vs 14EB (demand view) for the same year
A18: 13 | B18: Fig 8 | C18: DRAM rows sum to total (2025) | D18: =Fig08_09_DRAM_Demand!C9 -> 14 | E18: =Fig08_09_DRAM_Demand!C10 -> 13 | F18: 1 | G18: =IF(ABS(E18-D18)<=F18,"OK","FLAG") -> OK | H18: rounding
A19: 14 | B19: Fig 8 | C19: DRAM rows sum to total (2027E) | D19: =Fig08_09_DRAM_Demand!E9 -> 29 | E19: =Fig08_09_DRAM_Demand!E10 -> 30 | F19: 1 | G19: =IF(ABS(E19-D19)<=F19,"OK","FLAG") -> OK | H19: rounding
A20: 15 | B20: Fig 8 | C20: DRAM rows sum to total (2030E base) | D20: =Fig08_09_DRAM_Demand!G9 -> 77 | E20: =Fig08_09_DRAM_Demand!G10 -> 77 | F20: 1 | G20: =IF(ABS(E20-D20)<=F20,"OK","FLAG") -> OK | H20: rounding
A21: 16 | B21: Fig 8 | C21: DRAM rows sum to total (2030E unconstr.) | D21: =Fig08_09_DRAM_Demand!I9 -> 282 | E21: =Fig08_09_DRAM_Demand!I10 -> 282 | F21: 1 | G21: =IF(ABS(E21-D21)<=F21,"OK","FLAG") -> OK | H21: rounding
A22: 17 | B22: Fig 8 | C22: CPU rows sum to total (2025) | D22: =Fig08_09_DRAM_Demand!B8 -> 23 | E22: =Fig08_09_DRAM_Demand!B10 -> 23 | F22: 1 | G22: =IF(ABS(E22-D22)<=F22,"OK","FLAG") -> OK
A23: 18 | B23: Fig 8 | C23: CPU rows sum to total (2027E) | D23: =Fig08_09_DRAM_Demand!D8 -> 41 | E23: =Fig08_09_DRAM_Demand!D10 -> 42 | F23: 1 | G23: =IF(ABS(E23-D23)<=F23,"OK","FLAG") -> OK
A24: 19 | B24: Fig 8 | C24: CPU rows sum to total (2030E base) | D24: =Fig08_09_DRAM_Demand!F8 -> 67 | E24: =Fig08_09_DRAM_Demand!F10 -> 67 | F24: 1 | G24: =IF(ABS(E24-D24)<=F24,"OK","FLAG") -> OK
A25: 20 | B25: Fig 8 | C25: CPU rows sum to total (2030E unconstr.) | D25: =Fig08_09_DRAM_Demand!H8 -> 169 | E25: =Fig08_09_DRAM_Demand!H10 -> 169 | F25: 1 | G25: =IF(ABS(E25-D25)<=F25,"OK","FLAG") -> OK
A26: 21 | B26: Fig 8 vs 4 | C26: Unconstrained total CPUs: Fig 8 vs Fig 4 | D26: =Fig08_09_DRAM_Demand!H8 -> 169 | E26: =Fig04_Unconstrained!D16 -> 147 | F26: 2 | G26: =IF(ABS(E26-D26)<=F26,"OK","FLAG") -> FLAG | H26: Fig 8's standalone row carries 117 (= Fig 4's total AI CPUs, 22 head + 95 standalone): 169MM vs 147MM in Fig 4, '~150MM' on p.6, '~120MM AI before ~30MM traditional' on p.1, and Fig 9's $548B. Head nodes appear counted twice (mechanism not provable: 3x44-15 also = 117)
A27: 22 | B27: Fig 8 vs 4 | C27: Unconstrained DRAM: printed vs 147MM on Fig 8's own TB/CPU | D27: =Fig08_09_DRAM_Demand!I9 -> 282 | E27: =DRAM_CPU_Link!F22 -> 238 | F27: 2 | G27: =IF(ABS(E27-D27)<=F27,"OK","FLAG") -> FLAG | H27: 282EB -> ~238EB on UBS's content (3.1x the base, not 3.5-3.7x)
A28: 23 | B28: Fig 8 vs 5 | C28: C2030E traditional TB/CPU: Fig 8 implied vs Fig 5 stated ~1.0TB | D28: =Fig05_DRAM_per_CPU!N5 -> 1 | E28: =Fig08_09_DRAM_Demand!G12 -> 0.5 | F28: 0.1 | G28: =IF(ABS(E28-D28)<=F28,"OK","FLAG") -> FLAG | H28: The 77EB base case holds traditional CPUs at 0.5TB; at Fig 5's ~1.0TB the base case needs +15EB (DRAM_CPU_Link section D)
A29: 24 | B29: Fig 8 vs 5 | C29: C2030E head-node TB/CPU inside Fig 5 range (1.5-2TB, mid) | D29: =Fig05_DRAM_per_CPU!N6 -> 1.75 | E29: =Fig08_09_DRAM_Demand!G13 -> 1.5 | F29: 0.25 | G29: =IF(ABS(E29-D29)<=F29,"OK","FLAG") -> OK | H29: at the low end of the range
A30: 25 | B30: Fig 8 vs 5 | C30: C2030E standalone TB/CPU inside Fig 5 range (2-3TB, mid) | D30: =Fig05_DRAM_per_CPU!N7 -> 2.5 | E30: =Fig08_09_DRAM_Demand!G14 -> 1.9333333 | F30: 0.6 | G30: =IF(ABS(E30-D30)<=F30,"OK","FLAG") -> OK | H30: 29/15 = 1.93 on the rounded print; 29/14.5 = 2.0TB on the unrounded count = LOW END of the 2-3TB range
A31: 26 | B31: Fig 8 vs 5 | C31: C2030E blended AI CPU TB vs Fig 5 'Blended AI CPU ~2-2.5TB' (low end) | D31: =Fig05_DRAM_per_CPU!J8 -> 2 | E31: =DRAM_CPU_Link!D17 -> 1.6976999 | F31: 0.05 | G31: =IF(ABS(E31-D31)<=F31,"OK","FLAG") -> FLAG | H31: 62EB / 36.5MM = 1.70TB — below the low end of UBS's own stated range
A32: 27 | B32: Fig 8 vs 5 | C32: Corrected unconstrained (147MM) DRAM at Fig 5 C2030E midpoints vs title '~4x' | D32: =4*Fig08_09_DRAM_Demand!G9 -> 308 | E32: =Fig08_09_DRAM_Demand!F5*Fig05_DRAM_per_CPU!N5+Fig08_09_DRAM_Demand!F6*Fig05_DRAM_per_CPU!N6+Fig04_Unconstrained!D9*Fig05_DRAM_per_CPU!N7 -> 306 | F32: 20 | G32: =IF(ABS(E32-D32)<=F32,"OK","FLAG") -> OK | H32: 30x1.0 + 22x1.75 + 95x2.5 = ~306EB = 4.0x the 77EB base — the title's '~4x' holds on Fig 5 content even on the 147MM count; 238EB (3.1x) is the fix on Fig 8's own TB/CPU
A33: 28 | B33: Text | C33: Unconstrained DRAM multiple vs base (text: '3.5x') | D33: =3.5 -> 3.5 | E33: =Fig08_09_DRAM_Demand!I9/Fig08_09_DRAM_Demand!G9 -> 3.6623377 | F33: 0.2 | G33: =IF(ABS(E33-D33)<=F33,"OK","FLAG") -> OK | H33: 282/77 = 3.66x
A34: 29 | B34: Fig 4 | C34: Head node + standalone = AI CPUs (2027E) | D34: =Fig04_Unconstrained!C12 -> 30 | E34: =Fig04_Unconstrained!C6+Fig04_Unconstrained!C9 -> 31 | F34: 1 | G34: =IF(ABS(E34-D34)<=F34,"OK","FLAG") -> OK | H34: rounding
A35: 30 | B35: Fig 4 | C35: AI CPU $B = units x ASP (2027E) | D35: =Fig04_Unconstrained!C14 -> 90 | E35: =Fig04_Unconstrained!C12*Fig04_Unconstrained!C13/1000 -> 88.71 | F35: 3 | G35: =IF(ABS(E35-D35)<=F35,"OK","FLAG") -> OK
A36: 31 | B36: Fig 4 | C36: AI ASP = unit-weighted head/standalone ASP (2027E) | D36: =Fig04_Unconstrained!C13 -> 2957 | E36: =(Fig04_Unconstrained!C6*Fig04_Unconstrained!C8+Fig04_Unconstrained!C9*Fig04_Unconstrained!C11)/(Fig04_Unconstrained!C6+Fig04_Unconstrained!C9) -> 2960 | F36: 15 | G36: =IF(ABS(E36-D36)<=F36,"OK","FLAG") -> OK
A37: 32 | B37: Fig 4 | C37: Total TAM = AI $ + traditional $ (2027E) | D37: =Fig04_Unconstrained!C17 -> 125 | E37: =Fig04_Unconstrained!C14+Fig10_12_TAM!C9 -> 125 | F37: 1 | G37: =IF(ABS(E37-D37)<=F37,"OK","FLAG") -> OK
A38: 33 | B38: Fig 4 | C38: Total CPUs = AI + traditional (2027E) | D38: =Fig04_Unconstrained!C16 -> 56 | E38: =Fig04_Unconstrained!C12+Fig10_12_TAM!C7 -> 56 | F38: 1 | G38: =IF(ABS(E38-D38)<=F38,"OK","FLAG") -> OK
A39: 34 | B39: Fig 4 | C39: CPU-to-GPU attach = AI CPUs / accelerators (2027E) | D39: =Fig04_Unconstrained!C15 -> 1.05 | E39: =Fig04_Unconstrained!C12/Fig04_Unconstrained!C5 -> 1.0344828 | F39: 0.03 | G39: =IF(ABS(E39-D39)<=F39,"OK","FLAG") -> OK
A40: 35 | B40: Fig 4 | C40: Head node + standalone = AI CPUs (2030E) | D40: =Fig04_Unconstrained!D12 -> 117 | E40: =Fig04_Unconstrained!D6+Fig04_Unconstrained!D9 -> 117 | F40: 1 | G40: =IF(ABS(E40-D40)<=F40,"OK","FLAG") -> OK | H40: rounding
A41: 36 | B41: Fig 4 | C41: AI CPU $B = units x ASP (2030E) | D41: =Fig04_Unconstrained!D14 -> 500 | E41: =Fig04_Unconstrained!D12*Fig04_Unconstrained!D13/1000 -> 499.707 | F41: 3 | G41: =IF(ABS(E41-D41)<=F41,"OK","FLAG") -> OK
...

Sheet Fig01_Workloads
A1: Figure 1: CPU requirements vary by different workloads (p.3)
A2: UBS layering of Dell white paper 'Characterizing CPU Demand for Agentic AI: Three Agentic Workloads on the Dell PowerEdge R7725' (14-Sep-26); R7725 = 2x AMD Turin 64-core CPUs
A3: Source: UBS Global Research (Timothy Arcuri, Seth Cho), 'US Semiconductors: $210B Server CPU TAM By C2030; Gated By Memory Supply', 26-Oct-2026 — Fig 1
A5: Workload tested | B5: What the agent does | C5: Workload CPU requirements | D5: CPU quota per agent (cores) | E5: Sustained agents on 2x AMD 64-core Turin | F5: Measured CPU:GPU demand (x:1) | G5: % of consumer agentic workload (UBSe) | H5: Measured CPU cores:GPU (x:1) | I5: Check: cores/GPU = CPU:GPU x 128 cores
A6: Workload 1: pypi-server | B6: Writes a Python package and serves it from a local package index | C6: Light CPU: mostly model/code generation with short tool calls | D6: 1 | E6: 512 | F6: 1 | G6: 0.65 | H6: 128 | I6: =F6*128 -> 128
A7: Workload 2: sqlite-with-gcov | B7: Compiles SQLite with code-coverage instrumentation and fixes build errors | C7: Bursty CPU: compiler runs substantially between model reasoning turns | D7: 1 | E7: 238 | F7: 7 | G7: 0.3 | H7: 896 | I7: =F7*128 -> 896
A8: Workload 3: mcmc-sampling-stan | B8: Writes a statistical model, compiles it, then runs computationally heavy sampling | C8: Heavy CPU/HPC: sustained multi-core numerical computation | D8: 4 | E8: 60 | F8: 18 | G8: 0.05 | H8: 2304 | I8: =F8*128 -> 2304 | J8: printed '<5%' — 5% used as upper bound
A9: Blended CPU ratio (printed) | E9: CPU:GPU | F9: 4 | G9: printed 4:1
E10: CPU cores:GPU | H10: 421
A11: Recompute: mix-weighted (workload 3 at 5%) | F11: =SUMPRODUCT(F6:F8,G6:G8) -> 3.65 | H11: =SUMPRODUCT(H6:H8,G6:G8) -> 467.2
A12: Recompute: workload 3 weight that reproduces 421:1 | F12: =F6*G6+F7*G7+F8*G12 -> 3.2890625 | G12: =(H10-H6*G6-H7*G7)/H8 -> 0.029947917 | H12: =H6*G6+H7*G7+H8*G12 -> 421
A13: Each row has cores:GPU = 128 x CPU:GPU (2 x 64-core Turin), so the printed blended 421 cores:GPU implies 421/128 = 3.29:1 whatever the weights (a ~3% weight on workload 3 reproduces it). The table's '4:1' is the outlier; the text's '~3:1' / 'we use 3:1' agree with 421.
A15: Note text (p.3-4): layering this over Dell -> ~3:1 CPU:GPU on the current CPU generation, ~400 cores:1 GPU; core counts double every ~3-4 yrs (~500 cores/CPU by decade-end) but accelerator perf rises too -> UBS uses 3:1 in its demand estimate. Prior framework: ~0.33 standalone + ~0.5 head-node = ~0.85 CPUs/GPU.

Sheet Fig02_03_Muse
A1: Figures 2-3: META Muse CPU sizing (p.4-5)
A2: Muse ~2.5MM DAUs weeks after release; UBS: Muse is a demand signal, not a needle mover (~1MM units even at 1B users with 5-10% provisioning vs ~23MM CPUs shipped C2025)
A3: Source: UBS Global Research (Timothy Arcuri, Seth Cho), 'US Semiconductors: $210B Server CPU TAM By C2030; Gated By Memory Supply', 26-Oct-2026 — Figs 2, 3
A5: Figure 2: META Muse Sensitivity Table
A6: Scenario input | B6: Base Case | C6: High Engagement | D6: Notes (as printed)
A7: Daily Active Users (DAU) | B7: 3000000 | C7: 3000000 | D7: UBSe (printed '3MM')
A8: Peak Concurrent Sandboxes (% of DAU) | B8: 0.25 | C8: 0.5 | D8: UBSe
A9: vCPUs per Sandbox | B9: 2 | C9: 2 | D9: META
A10: Oversubscription | B10: 4 | C10: 1 | D10: Conservative vs. Firecracker/DeepSeek
A11: Cores per CPU | B11: 126 | C11: 126 | D11: AMD EPYC 9D25 (126 cores/252 threads)
A12: Math | B12: Base (recomputed) | C12: High (recomputed) | D12: Printed base | E12: Printed high | F12: Math (as printed)
A13: Concurrent Sandboxes | B13: =B7*B8 -> 750000 | C13: =C7*C8 -> 1500000 | D13: 1MM | E13: 2MM | F13: DAU x Concurrency
A14: vCPUs Demanded | B14: =B13*B9 -> 1500000 | C14: =C13*C9 -> 3000000 | D14: 2MM | E14: 3MM | F14: Sandboxes x vCPUs per Sandbox
A15: Cores Needed | B15: =B14/B10 -> 375000 | C15: =C14/C10 -> 3000000 | D15: 375K | E15: 3MM | F15: vCPUs / Oversubscription
A16: CPU Units (EPYC chips) | B16: =B15/B11 -> 2976.1905 | C16: =C15/C11 -> 23809.524 | D16: 2.98K | E16: 23.81K | F16: Cores needed / Cores per CPU
A17: Printed 'Concurrent Sandboxes 1MM / vCPUs 2MM' are rounded from 0.75MM / 1.5MM; the cores and CPU-unit lines use the unrounded values.
A19: # of CPU units — concurrency x oversubscription (printed)
A20: Concurrency | B20: 1x | C20: 2x | D20: 4x | E20: 8x | F20: Check 1x (recomputed) | G20: Max |printed - recomputed| in row
A21: 0.1 | B21: 4762 | C21: 2381 | D21: 1190 | E21: 595 | F21: =$B$7*A21*$B$9/1/$B$11 -> 4761.9048 | G21: =MAX(ABS(B21-$B$7*A21*$B$9/1/$B$11),ABS(C21-$B$7*A21*$B$9/2/$B$11),ABS(D21-$B$7*A21*$B$9/4/$B$11),ABS(E21-$B$7*A21*$B$9/8/$B$11)) -> 0.47619048
A22: 0.25 | B22: 11905 | C22: 5952 | D22: 2976 | E22: 1488 | F22: =$B$7*A22*$B$9/1/$B$11 -> 11904.762 | G22: =MAX(ABS(B22-$B$7*A22*$B$9/1/$B$11),ABS(C22-$B$7*A22*$B$9/2/$B$11),ABS(D22-$B$7*A22*$B$9/4/$B$11),ABS(E22-$B$7*A22*$B$9/8/$B$11)) -> 0.38095238
A23: 0.5 | B23: 23810 | C23: 11905 | D23: 5952 | E23: 2976 | F23: =$B$7*A23*$B$9/1/$B$11 -> 23809.524 | G23: =MAX(ABS(B23-$B$7*A23*$B$9/1/$B$11),ABS(C23-$B$7*A23*$B$9/2/$B$11),ABS(D23-$B$7*A23*$B$9/4/$B$11),ABS(E23-$B$7*A23*$B$9/8/$B$11)) -> 0.47619048
A24: 1 | B24: 47619 | C24: 23810 | D24: 11905 | E24: 5952 | F24: =$B$7*A24*$B$9/1/$B$11 -> 47619.048 | G24: =MAX(ABS(B24-$B$7*A24*$B$9/1/$B$11),ABS(C24-$B$7*A24*$B$9/2/$B$11),ABS(D24-$B$7*A24*$B$9/4/$B$11),ABS(E24-$B$7*A24*$B$9/8/$B$11)) -> 0.47619048
A26: Figure 3: Assuming 5-10% Target Utilization (thread-based sizing)
A27: Line | B27: Base Case | C27: High Engagement | D27: Base recomputed | E27: High recomputed | F27: Notes (as printed)
A28: Daily Active Users (DAUs) | B28: 3000000 | C28: 3000000 | F28: Unique users who open Muse on a given day
A29: (x) vCPUs per Sandbox | B29: 2 | C29: 2 | F29: Virtual CPUs allocated to each user's virtual machine (VM)
A30: Total Capacity Needed (Threads) | B30: 6000000 | C30: 6000000 | D30: =B28*B29 -> 6000000 | E30: =C28*C29 -> 6000000 | F30: Hardware needed if every DAU ran at once on dedicated hardware at one thread per vCPU
A31: (x) Peak Concurrent Sandboxes (% of DAUs) | B31: 0.2 | C31: 0.3 | F31: UBSe share of DAU with a live sandbox (a running VM, whether active or idle) during peak hours
A32: Concurrent sandboxes | B32: 600000 | C32: 900000 | D32: =B28*B31 -> 600000 | E32: =C28*C31 -> 900000 | F32: # of VMs alive at peak
A33: (/) Target Utilization | B33: 0.7 | C33: 0.65 | F33: UBSe how fully the provisioned capacity runs at peak, remainder = headroom
A34: Sandboxes Provisioned | B34: 857143 | C34: 1384615 | D34: =B32/B33 -> 857142.86 | E34: =C32/C33 -> 1384615.4 | F34: Sandbox slots built, including headroom
A35: vCPUs Provisioned | B35: 1714286 | C35: 2769231 | D35: =D34*B29 -> 1714285.7 | E35: =E34*C29 -> 2769230.8 | F35: vCPUs across all provisioned slots
A36: (/) Oversubscription | B36: 3 | C36: 3 | F36: UBSe vCPUs sharing one physical hardware thread (benchmarked vs DeepSeek and AWS)
A37: Threads Provisioned | B37: 571429 | C37: 923077 | D37: =D35/B36 -> 571428.57 | E37: =E35/C36 -> 923076.92 | F37: Physical hardware threads needed after sharing
A38: Hardware Deployed (% of total capacity) | B38: 0.1 | C38: 0.15 | D38: =D37/D30 -> 0.095238095 | E38: =E37/E30 -> 0.15384615 | F38: UBSe: heavily oversubscribed cloud workloads deploy 5-10% of dedicated-equivalent hardware in base case
A39: (/) Usable Threads per CPU | B39: 240 | C39: 230 | F39: Hardware threads available for sandboxes after host OS and hypervisor take their share
A40: # of CPUs being used | B40: 2382 | C40: 4012 | D40: =D37/B39 -> 2380.9524 | E40: =E37/C39 -> 4013.3779 | F40: # of CPUs required
A41: Printed 2,382 / 4,012 vs recomputed 2,381 / 4,013 (rounding in the note). Text: ~2,382 CPUs for 3MM DAUs base, ~4,012 high; deployed hardware = 10-15% of dedicated capacity.

Sheet Fig04_Unconstrained
A1: Figure 4: Unconstrained Estimates Suggest a $500B+ CPU TAM by C2030 (p.6)
A2: Source: UBS Global Research (Timothy Arcuri, Seth Cho), 'US Semiconductors: $210B Server CPU TAM By C2030; Gated By Memory Supply', 26-Oct-2026 — Fig 4 (UBS estimates)
A4: Unconstrained Demand Ests | B4: 2025 | C4: 2027E | D4: 2030E | E4: Comment
A5: Accelerators (NVDA, AMD, TPU, Trn), MM | B5: 9 | C5: 29 | D5: 44 | E5: Assumes units stay the same but TDP/performance increases; printed '~44'
A6: Head node CPU, MM | B6: 3 | C6: 11 | D6: 22 | E6: UBSe based announced systems; printed '~22'
A7: Head Node CPU-to-GPU attach rate | B7: 0.29 | C7: 0.36 | D7: 0.5
A8: Head Node ASP ($) | B8: 2430 | C8: 3160 | D8: 4480 | E8: Higher ASP given higher portion of NVDA CPUs
A9: Standalone (outside of rack), MM | B9: 0 | C9: 20 | D9: 95 | E9: Additional CPU units outside of rack; printed '~20' / '~95'
A10: Standalone CPU-to-GPU attach rate | C10: 0.69 | D10: 2.16 | E10: 3CPU:1GPU target ratio ex-head nodes and 50% of trad CPUs for tool calls
A11: Standalone CPU ASP ($) | C11: 2850 | D11: 4223 | E11: Assumes higher share of x86 even over time for multithread
A12: AI CPU Market (Bottom-up Ests), MM | B12: 3 | C12: 30 | D12: 117
A13: AI CPU ASP ($) | B13: 2430 | C13: 2957 | D13: 4271 | E13: Higher core counts and clock speeds increasing ASPs (row printed 'AI CPU ASP, K' but values are $)
A14: AI CPU Market (Bottom-up Ests), $B | B14: 7 | C14: 90 | D14: 500
A15: CPU-to-GPU Attach | B15: 0.29 | C15: 1.05 | D15: 2.66
A16: Implied Total CPUs (AI + Traditional), MM | B16: 23 | C16: 56 | D16: 147
A17: Implied Total CPU TAM, $B | B17: 31 | C17: 125 | D17: 548
A18: Implied DRAM Memory, EB | E18: Row printed blank in Fig 4 — the DRAM figure (282EB) is in Fig 8

Sheet Fig05_DRAM_per_CPU
A1: Figure 5: Memory Demand For Agentic Workloads is 3-4x Higher vs Traditional CPUs (p.6)
A2: Source: UBS Global Research (Timothy Arcuri, Seth Cho), 'US Semiconductors: $210B Server CPU TAM By C2030; Gated By Memory Supply', 26-Oct-2026 — Fig 5 (UBS Research)
A4: DRAM / CPU (TB) — as printed | B4: C2025/26 | C4: C2026/27 | D4: C2030E | E4: Growth | F4: low 25/26 | G4: high 25/26 | H4: low 26/27 | I4: high 26/27 | J4: low 30E | K4: high 30E | L4: mid 25/26 | M4: mid 26/27 | N4: mid 30E
A5: Traditional CPU | B5: ~0.25-0.5TB | C5: ~0.5-0.75TB | D5: ~1.0TB | E5: ~1.5-2x | F5: 0.25 | G5: 0.5 | H5: 0.5 | I5: 0.75 | J5: 1 | K5: 1 | L5: =AVERAGE(F5,G5) -> 0.375 | M5: =AVERAGE(H5,I5) -> 0.625 | N5: =AVERAGE(J5,K5) -> 1
A6: AI head-node CPU | B6: ~1-1.5TB | C6: ~1-1.5TB | D6: ~1.5-2TB | E6: ~1.5x | F6: 1 | G6: 1.5 | H6: 1 | I6: 1.5 | J6: 1.5 | K6: 2 | L6: =AVERAGE(F6,G6) -> 1.25 | M6: =AVERAGE(H6,I6) -> 1.25 | N6: =AVERAGE(J6,K6) -> 1.75
A7: AI standalone / agentic CPU | B7: ~1.5-2TB | C7: ~1.5-2TB | D7: ~2-3TB | E7: ~1.5x | F7: 1.5 | G7: 2 | H7: 1.5 | I7: 2 | J7: 2 | K7: 3 | L7: =AVERAGE(F7,G7) -> 1.75 | M7: =AVERAGE(H7,I7) -> 1.75 | N7: =AVERAGE(J7,K7) -> 2.5
A8: Blended AI CPU | B8: ~1.5TB | C8: ~1.5TB | D8: ~2-2.5TB | E8: ~1.5x | F8: 1.5 | G8: 1.5 | H8: 1.5 | I8: 1.5 | J8: 2 | K8: 2.5 | L8: =AVERAGE(F8,G8) -> 1.5 | M8: =AVERAGE(H8,I8) -> 1.5 | N8: =AVERAGE(J8,K8) -> 2.25
A10: Text (p.6): traditional ~0.5TB today -> ~1TB by end of decade; AI head-node already >1.5TB -> ~2TB; AI standalone may reach ~3TB over the next few generations. Low/high/mid columns are the printed ranges split into numbers for the link sheet.

Sheet Fig06_07_DRAM_Supply
A1: Figures 6-7: UBSe DRAM capacity by vendor and ex-HBM DRAM available for CPUs (p.6-7)
A2: Source: UBS Global Research (Timothy Arcuri, Seth Cho), 'US Semiconductors: $210B Server CPU TAM By C2030; Gated By Memory Supply', 26-Oct-2026 — Figs 6, 7 (UBS Research)
A4: Figure 6: UBSe DRAM Capacity by Vendor (EB)
A5: EB | B5: C2025 | C5: C2027E | D5: C2030E | E5: Note
A6: Samsung | B6: 14 | C6: 19 | D6: 31
A7: SK Hynix | B7: 10 | C7: 16 | D7: 22
A8: Micron | B8: 9 | C8: 13 | D8: 26
A9: CXMT | B9: 3 | C9: 6 | D9: 10
A10: Total | B10: 36 | C10: 55 | D10: 89 | E10: printed total
A11: Sum of vendors (recomputed) | B11: =SUM(B6:B9) -> 36 | C11: =SUM(C6:C9) -> 54 | D11: =SUM(D6:D9) -> 89
A13: Figure 7: Our Current Base Case Memory Model Suggests 77EB for Server DRAM in C2030
A14: ex-HBM DRAM Market (EB) | B14: C2025 | C14: C2027E | D14: C2030E | E14: Note
A15: MU DRAM ex-HBM | B15: 9 | C15: 13 | D15: 23
A16: Total Mkt (MU share, UBS Ests) | B16: 36 | C16: 54 | D16: 99 | E16: MU ex-HBM / assumed MU share
A17: Total non-HBM DRAM Mkt | B17: 36 | C17: 55 | D17: 89 | E17: equals Fig 6 total
A18: Non-Server DRAM | B18: 26 | C18: 27 | D18: 30
A19: Server DRAM Memory | B19: 11 | C19: 27 | D19: 69
A20: Old DDR Reuse via CXL (UBS Ests) | C20: 2 | D20: 7
A21: Total DRAM Memory for CPUs, EB | B21: 11 | C21: 29 | D21: 77
A22: Server DRAM = MU-share total - non-server (recomputed) | B22: =B16-B18 -> 10 | C22: =C16-C18 -> 27 | D22: =D16-D18 -> 69
A23: Server DRAM = vendor total - non-server (recomputed) | B23: =B17-B18 -> 10 | C23: =C17-C18 -> 28 | D23: =D17-D18 -> 59
A24: Implied MU share of non-HBM DRAM (MU / MU-share total) | B24: =B15/B16 -> 0.25 | C24: =C15/C16 -> 0.24074074 | D24: =D15/D16 -> 0.23232323
A25: CXL reuse as % of server DRAM | C25: =C20/C19 -> 0.074074074 | D25: =D20/D19 -> 0.10144928
A27: Text (p.7): META at AI Infra Summit showed a 1TB server using a 3:1 mix of DDR5 RDIMMs and CXL-attached DDR4; usable in 25-33% of 4 META CPU-workload fleets -> UBS: +6-8% memory capacity via reuse of older RDIMMs (experts: high-single-digit %).

Sheet Fig08_09_DRAM_Demand
A1: Figure 8: The 3:1 CPU:GPU Attach Ratio Results in DRAM Demand ~4x Above UBS Estimates (p.7)
A2: Source: UBS Global Research (Timothy Arcuri, Seth Cho), 'US Semiconductors: $210B Server CPU TAM By C2030; Gated By Memory Supply', 26-Oct-2026 — Figs 8, 9 (UBS estimates)
A4: DRAM / CPU | B4: C2025 CPU, MM | C4: C2025 DRAM, EB | D4: C2027E CPU, MM | E4: C2027E DRAM, EB | F4: C2030E Base CPU, MM | G4: C2030E Base DRAM, EB | H4: C2030E Unconstr. CPU, MM | I4: C2030E Unconstr. DRAM, EB
A5: Traditional CPU | B5: 20 | C5: 10 | D5: 26 | E5: 12 | F5: 30 | G5: 15 | H5: 30 | I5: 15
A6: AI head-node CPU | B6: 3 | C6: 3 | D6: 11 | E6: 11 | F6: 22 | G6: 33 | H6: 22 | I6: 33
A7: AI standalone / agentic CPU | B7: 0 | C7: 0 | D7: 5 | E7: 7 | F7: 15 | G7: 29 | H7: 117 | I7: 234
A8: Total CPU, MM | B8: 23 | D8: 41 | F8: 67 | H8: 169
A9: Implied DRAM, EB | C9: 14 | E9: 29 | G9: 77 | I9: 282
A10: Sum of rows (recomputed) | B10: =SUM(B5:B7) -> 23 | C10: =SUM(C5:C7) -> 13 | D10: =SUM(D5:D7) -> 42 | E10: =SUM(E5:E7) -> 30 | F10: =SUM(F5:F7) -> 67 | G10: =SUM(G5:G7) -> 77 | H10: =SUM(H5:H7) -> 169 | I10: =SUM(I5:I7) -> 282
A11: Implied TB per CPU (DRAM EB / CPU MM)
A12: Traditional CPU | C12: =IF(B5=0,"",C5/B5) -> 0.5 | E12: =IF(D5=0,"",E5/D5) -> 0.46153846 | G12: =IF(F5=0,"",G5/F5) -> 0.5 | I12: =IF(H5=0,"",I5/H5) -> 0.5
A13: AI head-node CPU | C13: =IF(B6=0,"",C6/B6) -> 1 | E13: =IF(D6=0,"",E6/D6) -> 1 | G13: =IF(F6=0,"",G6/F6) -> 1.5 | I13: =IF(H6=0,"",I6/H6) -> 1.5
A14: AI standalone / agentic CPU | C14: =IF(B7=0,"",C7/B7) | E14: =IF(D7=0,"",E7/D7) -> 1.4 | G14: =IF(F7=0,"",G7/F7) -> 1.9333333 | I14: =IF(H7=0,"",I7/H7) -> 2
A15: Blended (total EB / total CPUs) | C15: =C9/B8 -> 0.60869565 | E15: =E9/D8 -> 0.70731707 | G15: =G9/F8 -> 1.1492537 | I15: =I9/H8 -> 1.6686391
A17: Note: the Unconstrained column puts 117MM in the standalone row — 117MM is Fig 4's TOTAL AI CPU count (22 head-node + 95 standalone), giving 169MM CPUs vs Fig 4's 147MM and the text's '~150MM' (3 x 44 - 15 also equals 117, so the mechanism is not provable). On UBS's own TB/CPU, 147MM CPUs need ~238EB — see Report_Tieouts / DRAM_CPU_Link.
A19: Figure 9: Bottom Up TAM Difference (data labels as printed; legend says 'MM units' but values match the $B TAMs of Figs 4/10)
A20: Series | B20: 2025 | C20: 2027E | D20: 2030E | E20: Note
A21: UBS CPU TAM ($B; legend printed 'MM units') | B21: 31 | C21: 83 | D21: 208 | E21: equals Fig 10 bottom-up TAM
A22: Demand CPU TAM ($B; legend printed 'MM units') | B22: 31 | C22: 125 | D22: 548 | E22: equals Fig 4 unconstrained TAM

Sheet Fig10_12_TAM
A1: Figures 10-12: Updated ~$210B C2030 CPU TAM framework (p.8)
A2: Source: UBS Global Research (Timothy Arcuri, Seth Cho), 'US Semiconductors: $210B Server CPU TAM By C2030; Gated By Memory Supply', 26-Oct-2026 — Figs 10, 11, 12 (UBS estimates; Fig 12 also Mercury Research)
A4: Figure 10: Our Estimates Suggest a ~$210B TAM by C2030
A5: Estimate | B5: 2025 | C5: 2027E | D5: 2030E | E5: Comment
A6: Traditional CPU Market
A7: Traditional CPU Market, MM | B7: 20 | C7: 26 | D7: 30 | E7: Grows from 2025 at 8% CAGR like C2005-2020
A8: Traditional CPU ASP ($) | B8: 1200 | C8: 1348 | D8: 1606 | E8: Grows from 2025 at 1.5x 4% CAGR like C2005-2020 (row printed 'ASP, K' but values are $)
A9: Traditional Market, $B | B9: 24 | C9: 35 | D9: 48 | E9: Implied by units and ASPs
A10: AI CPU (Bottom-Up)
A11: AI Accelerator Units (Bottom-Up), MM | B11: 9 | C11: 29 | D11: 44 | E11: Largest programs (NVDA, AMD, TPU, Trn), ex-China
A12: AI CPU Market (Bottom-Up Ests), MM | B12: 3 | C12: 16 | D12: 37
A13: Head Node | B13: 3 | C13: 11 | D13: 22 | E13: UBSe based announced systems; printed '~22'
A14: Standalone | B14: 0 | C14: 5 | D14: 15 | E14: Additional CPU units outside of rack
A15: AI CPU ASP ($) | B15: 2430 | C15: 3058 | D15: 4378 | E15: Higher core count and clock speed increasing ASPs
A16: AI CPU Market (Bottom-up Ests), $B | B16: 7 | C16: 48 | D16: 160
A17: AI CPU (Top-Down)
A18: AI CPU Market (Top-Down Ests), MM | D18: 80 | E18: TAM based on 3-4T AI Spend, and 1-to-1 CPU/GPU attach
A19: AI CPU ASP ($) top-down | D19: 3000 | E19: UBS ASP ests
A20: AI CPU Market, $B top-down | D20: 240 | E20: Implied by units and ASPs
A21: Total Market
A22: Bottom-up Units, MM | B22: 23 | C22: 41 | D22: 67 | E22: Traditional CPU + AI CPU Bottom-up Ests
A23: Bottom-up TAM, $B | B23: 31 | C23: 83 | D23: 208
A24: Top-Down CPU Market, MM | D24: 110 | E24: Traditional CPU + AI CPU Top-Down Ests
A25: Top-Down CPU Market, $B | D25: 288
A27: Figure 11: AI CPU Bottom-Up TAM Estimate
A28: AI CPU Bottom-Up TAM Estimate | B28: 2025 | C28: 2027E | D28: 2030E | E28: Comment
A29: Accelerators (NVDA, AMD, TPU, Trn) | B29: 9 | C29: 29 | D29: 44 | E29: Assumes units stay the same but TDP/performance increases
A30: Head Node CPUs, MM | B30: 3 | C30: 11 | D30: 22 | E30: UBSe based announced systems
A31: Head Node CPU per GPU attach rate | B31: 0.29 | C31: 0.36 | D31: 0.5
A32: Head Node ASP ($) | B32: 2430 | C32: 3160 | D32: 4480 | E32: Higher ASP given higher portion of NVDA CPUs
A33: Standalone (outside of rack), MM | B33: 0 | C33: 5 | D33: 15 | E33: Additional CPU units outside of rack; printed '~15'
A34: Standalone CPU per GPU attach rate | C34: 0.18 | D34: 0.33
A35: Standalone CPU ASP ($) | C35: 2850 | D35: 4223 | E35: Assumes higher share of x86 even over time for multithread
A36: AI CPU Market (Bottom-up Ests), MM | B36: 3 | C36: 16 | D36: 37
A37: AI CPU ASP ($) | B37: 2430 | C37: 3058 | D37: 4378 | E37: Higher core count and clock speed increasing ASPs
A38: AI CPU Market (Bottom-up Ests), $B | B38: 7 | C38: 48 | D38: 160
A39: CPU per GPU attach | B39: 0.29 | C39: 0.54 | D39: 0.83
A41: Figure 12: CPU Market To Reach ~$210B By C2030E ($B; stacked bar — totals printed, segments = Fig 10/11 units x ASP)
A42: Segment ($B) | B42: 2025 | C42: 2027E | D42: 2030E | E42: Basis
A43: Traditional servers | B43: =B9 -> 24 | C43: =C9 -> 35 | D43: =D9 -> 48 | E43: Fig 10 traditional $B
...

Sheet Fig15_18_Power
A1: Figures 15-18: CPUs per GW and CPU power / compute capacity deployed (p.11-12)
A2: Source: UBS Global Research (Timothy Arcuri, Seth Cho), 'US Semiconductors: $210B Server CPU TAM By C2030; Gated By Memory Supply', 26-Oct-2026 — Figs 15-18 (UBS Research)
A4: Figure 15: ~2.7MM traditional CPUs per GW, only ~1.4MM AI CPUs
A5: CPUs per GW | B5: Traditional CPU | C5: AI CPU | D5: Trad recomputed | E5: AI recomputed | F5: Note
A6: CPU TDP (W) | B6: 250 | C6: 450
A7: Approx DRAM / CPU (TB) | B7: 1 | C7: 2
A8: DRAM/DIMM (W) | B8: 15 | C8: 15
A9: # of DIMMs populated | B9: 8 | C9: 16
A10: Total TDP per CPU (W) | B10: 370 | C10: 690 | D10: =B6+B8*B9 -> 370 | E10: =C6+C8*C9 -> 690
A11: # of CPUs per GW | B11: 2702703 | C11: 1449275 | D11: =1000000000/D10 -> 2702702.7 | E11: =1000000000/E10 -> 1449275.4
A12: CPU ASP ($) | B12: 1500 | C12: 3500
A13: CPU+DIMMs Capex per GW, $B | B13: 17.6 | C13: 34.1 | D13: =D14+D15 -> 36.486486 | E13: =E14+E15 -> 39.855072 | F13: Text: CPU+memory capex/GW ~$34B (AI) vs ~$18B (traditional), memory the vast majority of the increase.
A14: CPU Capex ($B/GW) | B14: 4.1 | C14: 5.1 | D14: =D11*B12/1000000000 -> 4.0540541 | E14: =E11*C12/1000000000 -> 5.0724638
A15: Memory Capex ($B/GW; printed '$12K/1TB') | B15: 13.5 | C15: 29 | D15: =D11*B7*B16/1000000000 -> 32.432432 | E15: =E11*C7*C16/1000000000 -> 34.782609 | F15: Printed memory capex does NOT tie to the table's own 1TB x $12K/TB (recomputed cols: $32.4B / $34.8B). It ties EXACTLY at $10K/TB with traditional at 0.5TB (Fig 8's basis) and AI at 2TB: $5.0K / $20.0K of memory per CPU.
A16: Memory price assumption ($ per TB, printed '$12K/1TB') | B16: 12000 | C16: 12000
A18: Figure 16: ~21GW of power required for new CPUs in C2030
A19: CPU Power, GW | B19: 2025 | C19: 2027E | D19: 2030E | E19: Note
A20: Traditional CPUs, MM | B20: 20 | C20: 26 | D20: 30
A21: W per CPU + DIMMs (trad) | B21: 370 | C21: 370 | D21: 370
A22: Traditional Implied GW | B22: 8 | C22: 10 | D22: 11
A23: AI Head node Implied GW | E23: printed 'captured in GW racks'
A24: AI Standalone CPUs, MM | B24: 0 | C24: 5 | D24: 15
A25: W per CPU + DIMMs (AI) | B25: 690 | C25: 690 | D25: 690
A26: AI Standalone Implied GW | B26: 0 | C26: 4 | D26: 10
A27: Total CPUs, Implied GW | B27: 8 | C27: 13 | D27: 21
A28: Trad GW recomputed | B28: =B20*B21/1000 -> 7.4 | C28: =C20*C21/1000 -> 9.62 | D28: =D20*D21/1000 -> 11.1
A29: Standalone GW recomputed | B29: =B24*B25/1000 -> 0 | C29: =C24*C25/1000 -> 3.45 | D29: =D24*D25/1000 -> 10.35
A31: Figures 17-18: GW of annual compute / data-center capacity deployed (stacked bars; totals printed, CPU slice = Fig 16)
A32: GW | B32: 2025 | C32: 2027E | D32: 2030E | E32: Note
A33: Fig 17 annual compute capacity deployed (GPU+ASIC+CPU), GW | B33: 19 | C33: 62 | D33: 126 | E33: printed totals
A34: of which CPU (Fig 16), GW | B34: 8 | C34: 13 | D34: 21 | E34: Fig 16 total CPUs implied GW
A35: Fig 18 annual DC capacity deployed at PUE 1.12, GW | B35: 21 | C35: 70 | D35: 141 | E35: printed totals
A36: Fig 17 x 1.12 (recomputed) | B36: =B33*1.12 -> 21.28 | C36: =C33*1.12 -> 69.44 | D36: =D33*1.12 -> 141.12
A37: CPU share of compute GW | B37: =B34/B33 -> 0.42105263 | C37: =C34/C33 -> 0.20967742 | D37: =D34/D33 -> 0.16666667
A39: GPU/ASIC split of Figs 17-18 is unlabeled in the chart (2030E roughly GPU ~60GW / ASIC ~45GW / CPU ~21GW by eye) — not tabulated. Text: CPU-driven infrastructure ~20% of 2030 annual compute capacity deployed; Fig 18 assumes PUE 1.12.

Sheet Fig19_21_Share
A1: Figures 19-21: C2030E server-CPU revenue split and unit shares (p.13-14)
A2: Source: UBS Global Research (Timothy Arcuri, Seth Cho), 'US Semiconductors: $210B Server CPU TAM By C2030; Gated By Memory Supply', 26-Oct-2026 — Figs 19, 20, 21 (UBS estimates / UBS Research)
A4: Figure 19: UBSe Server CPU Market Breakdown C2030E
A5: (Revenues $B) | B5: C2030E | C5: % (printed) | D5: % (recomputed)
A6: AMD Server | B6: 62 | C6: 0.3 | D6: =B6/B12 -> 0.29807692
A7: INTC Server | B7: 44 | C7: 0.21 | D7: =B7/B12 -> 0.21153846
A8: ARM Server | B8: 102 | C8: 0.49 | D8: =B8/B12 -> 0.49038462
A9: of which ARM AGI | B9: 15 | C9: 0.07 | D9: =B9/B12 -> 0.072115385
A10: of which NVDA | B10: 53 | C10: 0.25 | D10: =B10/B12 -> 0.25480769
A11: of which Other | B11: 35 | C11: 0.17 | D11: =B11/B12 -> 0.16826923
A12: Total Server CPU | B12: 208 | C12: 1 | D12: =B12/B12 -> 1
A13: Sum AMD+INTC+ARM | B13: =B6+B7+B8 -> 208
A14: Sum ARM sub-rows | B14: =SUM(B9:B11) -> 103
A16: Figures 20-21: unit shares (pie labels)
A17: Unit share | B17: C2025 traditional CPU (Fig 20) | C17: UBSe C2030 total CPU (Fig 21) | D17: C2030 revenue share (Fig 19) | E17: Implied C2030 ASP ($) = rev / (share x 67MM)
A18: INTC | B18: 0.6 | C18: 0.28 | D18: =D7 -> 0.21153846 | E18: =B7*1000/(C18*Fig10_12_TAM!D22) -> 2345.4158
A19: AMD | B19: 0.24 | C19: 0.34 | D19: =D6 -> 0.29807692 | E19: =B6*1000/(C19*Fig10_12_TAM!D22) -> 2721.6857
A20: ARM | B20: 0.16 | C20: 0.38 | D20: =D8 -> 0.49038462 | E20: =B8*1000/(C20*Fig10_12_TAM!D22) -> 4006.2844
A22: Implied ASP column uses Fig 10's 67MM C2030 units: ARM-based revenue includes NVDA Grace/Vera and ARM AGI chips (full-chip $), not royalties. Text: AMD/INTC monetize ~$3-4K per CPU vs ARM IP economics ~$100+/CPU.

Sheet Fig23_Server_Roadmap
A1: Figure 23: Server CPU Roadmap (p.16) — approximate timing read off the Gantt bars
A2: Source: UBS Global Research (Timothy Arcuri, Seth Cho), 'US Semiconductors: $210B Server CPU TAM By C2030; Gated By Memory Supply', 26-Oct-2026 — Fig 23 (Company reports, UBS research)
A4: Vendor | B4: Generation / platform | C4: Microarchitecture | D4: Product family | E4: Process | F4: Bar start (approx) | G4: Bar end (approx)
A5: AMD | B5: 1st Gen | C5: Zen | D5: Naples | E5: 14nm | F5: 2017 | G5: 2019 Q2
A6: AMD | B6: 2nd Gen | C6: Zen2 | D6: General Purpose, Rome | E6: 7nm, 14nm | F6: 2019 Q3 | G6: 2021 Q1
A7: AMD | B7: 3rd Gen | C7: Zen3, 3D V-Cache | D7: General Purpose, Milan; Technical, Milan-X | E7: 7nm | F7: 2021 Q1 | G7: 2022 Q3
A8: AMD | B8: 4th Gen | C8: Zen4/4C, 3D V-Cache | D8: General Purpose, Genoa; Cloud Native - Bergamo; Technical - Genoa-X; Telco - Siena | E8: 5nm | F8: 2022 Q4 | G8: 2024 Q3
A9: AMD | B9: 5th Gen | C9: Zen5/5c | D9: Turin | E9: TSMC 3nm | F9: 2024 Q4 | G9: 2026 Q2
A10: AMD | B10: 6th Gen | C10: Zen6/6c | D10: Venice (26) and Verano (27) | E10: TSMC 2nm | F10: 2026 Q3 | G10: 2028 Q2
A11: AMD | B11: 7th Gen | C11: Zen 7/7c | D11: Florence | E11: Next Gen Process Node | F11: 2028 Q3 | G11: 2029+
A12: INTC | B12: 1st Gen (Purley) | C12: - | D12: Skylake-SP | E12: 14nm+ | F12: 2017 | G12: 2019 Q1
A13: INTC | B13: 1st Gen (Purley) | C13: - | D13: Cascade Lake-SP | E13: 14nm++ | F13: 2019 Q2 | G13: 2020 Q1
A14: INTC | B14: 2nd Gen (Purley) | C14: - | D14: Cooper Lake; Cascade Lake R | E14: 14nm++ | F14: 2020 | G14: 2020
A15: INTC | B15: 3rd Gen (Whitley) | C15: - | D15: Ice Lake-SP | E15: 10nm+ | F15: 2021 | G15: 2022
