Workbook

Sheet RESUMO
A1: MEMÓRIA — RESUMO CAPSTONE · DRAM ex-HBM · HBM · NAND | G1: gerado 2026-07-09
A2: Cenário ASP 27E/28E → | C2: House | D2: dropdown muda ASPs 27E/28E e o P&L (banda F). Fontes: coluna I + comentários nas células. Números em bn Gb salvo indicação.
A3: linha | B3: unid. | C3: CY23 | D3: CY24 | E3: CY25 | F3: CY26E | G3: CY27E | H3: CY28E | I3: fonte
A4: A · O CICLO EM 6 LINHAS
A5: Receita DRAM (indústria) | B5: $bn | C5: 56.177077 | D5: 92.395742 | E5: 150.894 | F5: 691.595 | G5: 1248.138 | H5: =ROUND(528.5/8*INDEX(_dados!$D$2:$D$4,MATCH($C$2,_dados!$A$2:$A$4,0))*8,0)+258.7 | I5: UBS 03-jul-26 · 28E engine+build
A6: Receita NAND (indústria) | B6: $bn | C6: ··· | D6: ··· | E6: 65.317 | F6: 300.248 | G6: 515.12 | H6: — | I6: UBS 03-jul-26
A7: Suficiência DRAM (S/D−1) | B7: % | C7: -0.0036 | D7: -0.0233 | E7: -0.0235 | F7: -0.0813 | G7: -0.012 | H7: ≈0 eng. | I7: UBS · engine 28E
A8: ASP DRAM blended | B8: $/Gb | C8: 0.25756 | D8: 0.36345 | E8: 0.47978252 | F8: 1.7786382 | G8: =INDEX(_dados!$B$2:$B$4,MATCH($C$2,_dados!$A$2:$A$4,0)) | H8: =INDEX(_dados!$D$2:$D$4,MATCH($C$2,_dados!$A$2:$A$4,0)) | I8: UBS · 27/28E = cenário
A9: Marcação a mercado (spot vs modelo) | B9: DDR5 spot 22.47 (jul) vs contract 12.25 (jun) — meses e bases distintos, spot ~80% acima · RDIMM 64GB 20.47 (jun) · NAND 512Gb 0.384 contract / 0.322 spot — série e unidades = aba de preços da bíblia (TrendForce); direção valida o 26E | I9: bíblia px (TrendForce/spot)
A10: Demanda HBM | B10: bn Gb | C10: 2.2 | D10: 5.6 | E10: 13.4 | F10: 28.4 | G10: 45.6 | H10: 80 | I10: build Capstone 40+ SKUs
A11: WFE total | B11: $bn | C11: 95.76 | D11: 100.34 | E11: 109.62 | F11: 158.4 | G11: 214.9 | H11: 260 | I11: UBS · ledger wfe-tam
A12: B · DEMANDA POR APLICAÇÃO (bn Gb)
A13: DRAM ex-HBM — Servidor DDR | B13: bn Gb | C13: 56.355 | D13: 65.224 | E13: 100.602 | F13: 146.482 | G13: 253.56 | H13: — | I13: UBS Fig.30-39
A14: Mobile | B14: bn Gb | C14: 62.954287 | D14: 74.63466 | E14: 86.263485 | F14: 85.74261 | G14: 92.148047 | H14: — | I14: UBS
A15: PC | B15: bn Gb | C15: 21.91033 | D15: 23.090512 | E15: 27.75809 | F15: 26.489642 | G15: 27.806007 | H15: — | I15: UBS
A16: Graphics + consumer + outros | B16: bn Gb | C16: 79.778585 | D16: 87.121582 | E16: 98.086844 | F16: 108.48115 | G16: 111.01416 | H16: — | I16: UBS (agregado)
A17: DRAM ex-HBM — total | B17: bn Gb | C17: 220.9982 | D17: 250.07075 | E17: 312.71042 | F17: 367.19541 | G17: 484.52821 | H17: 528.5 | I17: UBS · 28E engine
A18: HBM — NVIDIA | B18: bn Gb | C18: 1.65312 | D18: 3.870488 | E18: 9.43032 | F18: 17.18208 | G18: 17.6832 | H18: 30.2464 | I18: build (SKUs)
A19: Google TPU + AMD + AWS + outros | B19: bn Gb | C19: 0.56227828 | D19: 1.7138122 | E19: 3.9760883 | F19: 11.196975 | G19: 27.9392 | H19: 49.7632 | I19: build (agregado)
A20: HBM — total | B20: bn Gb | C20: 2.2 | D20: 5.6 | E20: 13.4 | F20: 28.4 | G20: 45.6 | H20: 80 | I20: build
A21: NAND — Mobile | B21: bn GB | C21: 215.36718 | D21: 245.34244 | E21: 286.5909 | F21: 292.58646 | G21: 316.88347 | H21: — | I21: UBS
A22: eSSD (servidores) | B22: bn GB | C22: 142.33054 | D22: 177.36585 | E22: 257.32064 | F22: 402.12783 | G22: 591.19527 | H22: — | I22: UBS
A23: SSD client + storage + outros | B23: bn GB | C23: 307.23106 | D23: 317.98989 | E23: 345.98534 | F23: 392.45069 | G23: 471.40198 | H23: — | I23: UBS (agregado)
A24: Embedded + cartões + tablet | B24: bn GB | C24: 149.92963 | D24: 175.80578 | E24: 190.72433 | F24: 209.29109 | G24: 215.7509 | H24: — | I24: UBS (agregado)
A25: NAND — total | B25: bn GB | C25: 814.85841 | D25: 916.50396 | E25: 1080.6212 | F25: 1296.4561 | G25: 1595.2316 | H25: — | I25: UBS
A26: B2 · SMARTPHONE — DESTRUIÇÃO DE DEMANDA (células amarelas: edite p/ sensibilizar)
A27: Units smartphone (base UBS — já com corte) | B27: M | C27: 1152 | D27: 1217 | E27: 1249 | F27: 1124 | G27: 1146 | H27: 1160 | I27: UBS via engine Capstone (handset)
A28: DRAM GB/unidade (base UBS — conteúdo desacelera) | B28: GB | C28: 6.8 | D28: 7.7 | E28: 8.1 | F28: 8.9 | G28: 9.4 | H28: 10.2 | I28: UBS
A29: Units contrafactual (sem aperto de preço) | B29: M | C29: 1152 | D29: 1217 | E29: 1249 | F29: 1249 | G29: 1249 | H29: 1249 | I29: EST: flat @ 1.249M pós-25
A30: GB/unidade contrafactual (tendência +10,5%/ano) | B30: GB | C30: 6.8 | D30: 7.7 | E30: 8.1 | F30: 9 | G30: 9.9 | H30: 10.9 | I30: EST: CAGR 22-25 real mantido
A31: Demanda DRAM destruída (contrafactual − base) | B31: bn Gb | C31: =(C29*C30-C27*C28)*8/1000 | D31: =(D29*D30-D27*D28)*8/1000 | E31: =(E29*E30-E27*E28)*8/1000 | F31: =(F29*F30-F27*F28)*8/1000 | G31: =(G29*G30-G27*G28)*8/1000 | H31: =(H29*H30-H27*H28)*8/1000 | I31: fórmula (viva)
A32: Suficiência DRAM sem a destruição (contrafactual) | B32: % | C32: — | D32: — | E32: — | F32: =-0.0813-F31/386.7 | G32: =-0.012-G31/520.1 | H32: — | I32: aprox.: suff − destruição ÷ demanda
A33: leitura | B33: a elasticidade já trabalhou: sem o corte de units+conteúdo o déficit 27E seria ~3× maior (−3,7% vs −1,2%). NAND análogo (238→253 GB/unit) não modelado aqui. | I33: Capstone
A34: C · OFERTA POR EMPRESA (bn Gb produção)
A35: DRAM — Samsung | B35: bn Gb | C35: 96.098088 | D35: 109.60591 | E35: 120.25075 | F35: 146.50516 | G35: 173.74904 | H35: — | I35: UBS
A36: DRAM — SK Hynix | B36: bn Gb | C36: 63.921644 | D36: 74.848909 | E36: 93.014352 | F36: 116.90085 | G36: 137.40942 | H36: — | I36: UBS
A37: DRAM — Micron | B37: bn Gb | C37: 47.452596 | D37: 60.413008 | E37: 73.604791 | F37: 90.902261 | G37: 107.16543 | H37: — | I37: UBS
A38: DRAM — CXMT | B38: bn Gb | C38: 2.0880205 | D38: 11.046041 | E38: 22.161558 | F38: 28.320604 | G38: 38.765855 | H38: — | I38: UBS
A39: Nanya + outros | B39: bn Gb | C39: 3.7808058 | D39: 3.8135743 | E39: 5.4731144 | F39: 6.2055794 | G39: 6.7246891 | H39: — | I39: UBS (agregado)
A40: DRAM — total oferta | B40: bn Gb | C40: 213.34115 | D40: 259.72744 | E40: 314.50457 | F40: 388.83446 | G40: 463.81444 | H40: — | I40: UBS
...

Sheet _dados
A1: cenário | B1: DDR 27E $/Gb | C1: NAND 27E $/GB | D1: DDR 28E $/Gb | E1: NAND 28E $/GB
A2: House | B2: 2.375 | C2: 0.33 | D2: 1.625 | E2: 0.28
A3: UBS base | B3: 2.67 | C3: 0.365 | D3: 2.25 | E3: 0.37
A4: Soft landing | B4: 1.6875 | C4: 0.28 | D4: 1.25 | E4: 0.28
A6: vendor | B6: dram MGb | C6: nand MGB | D6: gm | E6: opex $M | F6: tax | G6: fx | H6: shares M | I6: px | J6: eps27 cons
A7: MU | B7: 107165.43 | C7: 188920.01 | D7: 0.86 | E7: 3500 | F7: 0.15 | G7: 1 | H7: 1120 | I7: 878.84 | J7: 187.56
A8: SKHYNIX | B8: 137409.42 | C8: 233675.4 | D8: 0.84 | E8: 4000 | F8: 0.15 | G8: 1380 | H8: 728 | I8: 1272000 | J8: 488486.58
A9: SAMSUNG | B9: 173749.04 | C9: 405813.32 | D9: 0.84 | E9: 3000 | F9: 0.15 | G9: 1380 | H9: 5969 | I9: 215500 | J9: 74718.08
A10: KIOXIA | B10: 0 | C10: 211106.58 | D10: 0.84 | E10: 3000 | F10: 0.15 | G10: 150 | H10: 540 | I10: 13375 | J10: 4797.53
A11: SNDK | B11: 0 | C11: 162973.94 | D11: 0.84 | E11: 3000 | F11: 0.15 | G11: 1 | H11: 145 | I11: 1299.3 | J11: 241.9
